package alphaitems.worldgen;

import java.util.Random;

import net.minecraft.block.Block;
import net.minecraft.world.World;
import net.minecraft.world.gen.feature.WorldGenerator;
import alphaitems.blocks.Blocks;
import alphaitems.treasures.Treasures;

public class WorldGenUndergroundBase extends WorldGenerator
{
	protected int[] GetValidSpawnBlocks() {
		return new int[] { Block.dirt.blockID, Block.grass.blockID,
				Blocks.betterGrass.blockID, Block.snow.blockID,
				Block.stone.blockID, Blocks.redRock.blockID };
	}
	
	public boolean LocationIsValidSpawn(World world, int i, int j, int k) {
		int distanceToAir = 0;
		int checkID = world.getBlockId(i, j, k);
		
		while (checkID != 0) {
			distanceToAir++;
			checkID = world.getBlockId(i, j + distanceToAir, k);
		}
		
		if (distanceToAir > 3) {
			return false;
		}
		j += distanceToAir - 1;
		
		int blockID = world.getBlockId(i, j, k);
		int blockIDAbove = world.getBlockId(i, j + 1, k);
		int blockIDBelow = world.getBlockId(i, j - 1, k);
		for (int x : GetValidSpawnBlocks()) {
			if (blockIDAbove != 0) {
				return false;
			}
			if (blockID == x) {
				return true;
			} else if (blockID == Block.snow.blockID && blockIDBelow == x) {
				return true;
			}
		}
		return false;
	}
	
	public WorldGenUndergroundBase() {
	}
	
	@Override
	public boolean generate(World world, Random rand, int i, int j, int k) {
		// check that each corner is one of the valid spawn blocks
		if (!LocationIsValidSpawn(world, i, j, k))
		{
			return false;
		}
		
		world.setBlock(i + 0, j + 0, k + 0, Blocks.redCobble.blockID);
		world.setBlock(i + 0, j + 0, k + 1, Blocks.redCobble.blockID);
		world.setBlock(i + 0, j + 0, k + 2, Blocks.redCobble.blockID);
		world.setBlock(i + 0, j + 0, k + 3, Blocks.redCobble.blockID);
		world.setBlock(i + 0, j + 0, k + 4, Blocks.redCobble.blockID);
		world.setBlock(i + 0, j + 0, k + 5, Blocks.redCobble.blockID);
		world.setBlock(i + 0, j + 0, k + 6, Blocks.redCobble.blockID);
		world.setBlock(i + 0, j + 0, k + 7, Blocks.redCobble.blockID);
		world.setBlock(i + 0, j + 0, k + 8, Blocks.redCobble.blockID);
		world.setBlock(i + 0, j + 0, k + 9, Blocks.redCobble.blockID);
		world.setBlock(i + 0, j + 0, k + 10, Blocks.redCobble.blockID);
		world.setBlock(i + 0, j + 0, k + 11, Blocks.redCobble.blockID);
		world.setBlock(i + 0, j + 0, k + 12, Blocks.redCobble.blockID);
		world.setBlock(i + 0, j + 0, k + 13, Blocks.redCobble.blockID);
		world.setBlock(i + 0, j + 0, k + 14, Blocks.redCobble.blockID);
		world.setBlock(i + 0, j + 0, k + 15, Blocks.redCobble.blockID);
		world.setBlock(i + 0, j + 0, k + 16, Blocks.redCobble.blockID);
		world.setBlock(i + 0, j + 0, k + 17, Blocks.redCobble.blockID);
		world.setBlock(i + 0, j + 0, k + 18, Blocks.redCobble.blockID);
		world.setBlock(i + 0, j + 0, k + 19, Blocks.redCobble.blockID);
		world.setBlock(i + 0, j + 0, k + 20, Blocks.redCobble.blockID);
		world.setBlock(i + 0, j + 0, k + 21, Blocks.redCobble.blockID);
		world.setBlock(i + 0, j + 0, k + 22, Blocks.redCobble.blockID);
		world.setBlock(i + 0, j + 0, k + 23, Blocks.redCobble.blockID);
		world.setBlock(i + 0, j + 0, k + 24, Blocks.redCobble.blockID);
		world.setBlock(i + 0, j + 0, k + 25, Blocks.redCobble.blockID);
		world.setBlock(i + 0, j + 0, k + 26, Blocks.redCobble.blockID);
		world.setBlock(i + 0, j + 0, k + 27, Blocks.redCobble.blockID);
		world.setBlock(i + 0, j + 0, k + 28, Blocks.redCobble.blockID);
		world.setBlock(i + 0, j + 0, k + 29, Blocks.redCobble.blockID);
		world.setBlock(i + 0, j + 0, k + 30, Blocks.redCobble.blockID);
		world.setBlock(i + 0, j + 0, k + 31, Blocks.redCobble.blockID);
		world.setBlock(i + 0, j + 0, k + 32, Blocks.redCobble.blockID);
		world.setBlock(i + 0, j + 0, k + 33, Blocks.redCobble.blockID);
		world.setBlock(i + 0, j + 0, k + 34, Blocks.redCobble.blockID);
		world.setBlock(i + 0, j + 0, k + 35, Blocks.redCobble.blockID);
		world.setBlock(i + 0, j + 0, k + 36, Blocks.redCobble.blockID);
		world.setBlock(i + 0, j + 0, k + 37, Blocks.redCobble.blockID);
		world.setBlock(i + 0, j + 0, k + 38, Blocks.redCobble.blockID);
		world.setBlock(i + 0, j + 0, k + 39, Blocks.redCobble.blockID);
		world.setBlock(i + 0, j + 0, k + 40, Blocks.redCobble.blockID);
		world.setBlock(i + 0, j + 1, k + 0, Blocks.redCobble.blockID);
		world.setBlock(i + 0, j + 1, k + 1, Blocks.redCobble.blockID);
		world.setBlock(i + 0, j + 1, k + 2, Blocks.redCobble.blockID);
		world.setBlock(i + 0, j + 1, k + 3, Blocks.redCobble.blockID);
		world.setBlock(i + 0, j + 1, k + 4, Blocks.redCobble.blockID);
		world.setBlock(i + 0, j + 1, k + 5, Blocks.redCobble.blockID);
		world.setBlock(i + 0, j + 1, k + 6, Blocks.redCobble.blockID);
		world.setBlock(i + 0, j + 1, k + 7, Blocks.redCobble.blockID);
		world.setBlock(i + 0, j + 1, k + 8, Blocks.redCobble.blockID);
		world.setBlock(i + 0, j + 1, k + 9, Blocks.redCobble.blockID);
		world.setBlock(i + 0, j + 1, k + 10, Blocks.redCobble.blockID);
		world.setBlock(i + 0, j + 1, k + 11, Blocks.redCobble.blockID);
		world.setBlock(i + 0, j + 1, k + 12, Blocks.redCobble.blockID);
		world.setBlock(i + 0, j + 1, k + 13, Blocks.redCobble.blockID);
		world.setBlock(i + 0, j + 1, k + 14, Blocks.redCobble.blockID);
		world.setBlock(i + 0, j + 1, k + 15, Blocks.redCobble.blockID);
		world.setBlock(i + 0, j + 1, k + 16, Blocks.redCobble.blockID);
		world.setBlock(i + 0, j + 1, k + 17, Blocks.redCobble.blockID);
		world.setBlock(i + 0, j + 1, k + 18, Blocks.redCobble.blockID);
		world.setBlock(i + 0, j + 1, k + 19, Blocks.redCobble.blockID);
		world.setBlock(i + 0, j + 1, k + 20, Blocks.redCobble.blockID);
		world.setBlock(i + 0, j + 1, k + 21, Blocks.redCobble.blockID);
		world.setBlock(i + 0, j + 1, k + 22, Blocks.redCobble.blockID);
		world.setBlock(i + 0, j + 1, k + 23, Blocks.redCobble.blockID);
		world.setBlock(i + 0, j + 1, k + 24, Blocks.redCobble.blockID);
		world.setBlock(i + 0, j + 1, k + 25, Blocks.redCobble.blockID);
		world.setBlock(i + 0, j + 1, k + 26, Blocks.redCobble.blockID);
		world.setBlock(i + 0, j + 1, k + 27, Blocks.redCobble.blockID);
		world.setBlock(i + 0, j + 1, k + 28, Blocks.redCobble.blockID);
		world.setBlock(i + 0, j + 1, k + 29, Blocks.redCobble.blockID);
		world.setBlock(i + 0, j + 1, k + 30, Blocks.redCobble.blockID);
		world.setBlock(i + 0, j + 1, k + 31, Blocks.redCobble.blockID);
		world.setBlock(i + 0, j + 1, k + 32, Blocks.redCobble.blockID);
		world.setBlock(i + 0, j + 1, k + 33, Blocks.redCobble.blockID);
		world.setBlock(i + 0, j + 1, k + 34, Blocks.redCobble.blockID);
		world.setBlock(i + 0, j + 1, k + 35, Blocks.redCobble.blockID);
		world.setBlock(i + 0, j + 1, k + 36, Blocks.redCobble.blockID);
		world.setBlock(i + 0, j + 1, k + 37, Blocks.redCobble.blockID);
		world.setBlock(i + 0, j + 1, k + 38, Blocks.redCobble.blockID);
		world.setBlock(i + 0, j + 1, k + 39, Blocks.redCobble.blockID);
		world.setBlock(i + 0, j + 1, k + 40, Blocks.redCobble.blockID);
		world.setBlock(i + 0, j + 2, k + 0, Blocks.redCobble.blockID);
		world.setBlock(i + 0, j + 2, k + 1, Blocks.redCobble.blockID);
		world.setBlock(i + 0, j + 2, k + 2, Blocks.redCobble.blockID);
		world.setBlock(i + 0, j + 2, k + 3, Blocks.redCobble.blockID);
		world.setBlock(i + 0, j + 2, k + 4, Blocks.redCobble.blockID);
		world.setBlock(i + 0, j + 2, k + 5, Blocks.redCobble.blockID);
		world.setBlock(i + 0, j + 2, k + 6, Blocks.redCobble.blockID);
		world.setBlock(i + 0, j + 2, k + 7, Blocks.redCobble.blockID);
		world.setBlock(i + 0, j + 2, k + 8, Blocks.redCobble.blockID);
		world.setBlock(i + 0, j + 2, k + 9, Blocks.redCobble.blockID);
		world.setBlock(i + 0, j + 2, k + 10, Blocks.redCobble.blockID);
		world.setBlock(i + 0, j + 2, k + 11, Blocks.redCobble.blockID);
		world.setBlock(i + 0, j + 2, k + 12, Blocks.redCobble.blockID);
		world.setBlock(i + 0, j + 2, k + 13, Blocks.redCobble.blockID);
		world.setBlock(i + 0, j + 2, k + 14, Blocks.redCobble.blockID);
		world.setBlock(i + 0, j + 2, k + 15, Blocks.redCobble.blockID);
		world.setBlock(i + 0, j + 2, k + 16, Blocks.redCobble.blockID);
		world.setBlock(i + 0, j + 2, k + 17, Blocks.redCobble.blockID);
		world.setBlock(i + 0, j + 2, k + 18, Blocks.redCobble.blockID);
		world.setBlock(i + 0, j + 2, k + 19, Blocks.redCobble.blockID);
		world.setBlock(i + 0, j + 2, k + 20, Blocks.redCobble.blockID);
		world.setBlock(i + 0, j + 2, k + 21, Blocks.redCobble.blockID);
		world.setBlock(i + 0, j + 2, k + 22, Blocks.redCobble.blockID);
		world.setBlock(i + 0, j + 2, k + 23, Blocks.redCobble.blockID);
		world.setBlock(i + 0, j + 2, k + 24, Blocks.redCobble.blockID);
		world.setBlock(i + 0, j + 2, k + 25, Blocks.redCobble.blockID);
		world.setBlock(i + 0, j + 2, k + 26, Blocks.redCobble.blockID);
		world.setBlock(i + 0, j + 2, k + 27, Blocks.redCobble.blockID);
		world.setBlock(i + 0, j + 2, k + 28, Blocks.redCobble.blockID);
		world.setBlock(i + 0, j + 2, k + 29, Blocks.betterGlass.blockID);
		world.setBlock(i + 0, j + 2, k + 30, Blocks.redCobble.blockID);
		world.setBlock(i + 0, j + 2, k + 31, Blocks.redCobble.blockID);
		world.setBlock(i + 0, j + 2, k + 32, Blocks.redCobble.blockID);
		world.setBlock(i + 0, j + 2, k + 33, Blocks.redCobble.blockID);
		world.setBlock(i + 0, j + 2, k + 34, Blocks.redCobble.blockID);
		world.setBlock(i + 0, j + 2, k + 35, Blocks.redCobble.blockID);
		world.setBlock(i + 0, j + 2, k + 36, Blocks.redCobble.blockID);
		world.setBlock(i + 0, j + 2, k + 37, Blocks.redCobble.blockID);
		world.setBlock(i + 0, j + 2, k + 38, Blocks.redCobble.blockID);
		world.setBlock(i + 0, j + 2, k + 39, Blocks.redCobble.blockID);
		world.setBlock(i + 0, j + 2, k + 40, Blocks.redCobble.blockID);
		world.setBlock(i + 0, j + 3, k + 0, Blocks.redCobble.blockID);
		world.setBlock(i + 0, j + 3, k + 1, Blocks.redCobble.blockID);
		world.setBlock(i + 0, j + 3, k + 2, Blocks.redCobble.blockID);
		world.setBlock(i + 0, j + 3, k + 3, Blocks.redCobble.blockID);
		world.setBlock(i + 0, j + 3, k + 4, Blocks.redCobble.blockID);
		world.setBlock(i + 0, j + 3, k + 5, Blocks.redCobble.blockID);
		world.setBlock(i + 0, j + 3, k + 6, Blocks.redCobble.blockID);
		world.setBlock(i + 0, j + 3, k + 7, Blocks.redCobble.blockID);
		world.setBlock(i + 0, j + 3, k + 8, Blocks.redCobble.blockID);
		world.setBlock(i + 0, j + 3, k + 9, Blocks.redCobble.blockID);
		world.setBlock(i + 0, j + 3, k + 10, Blocks.redCobble.blockID);
		world.setBlock(i + 0, j + 3, k + 11, Blocks.redCobble.blockID);
		world.setBlock(i + 0, j + 3, k + 12, Blocks.redCobble.blockID);
		world.setBlock(i + 0, j + 3, k + 13, Blocks.redCobble.blockID);
		world.setBlock(i + 0, j + 3, k + 14, Blocks.redCobble.blockID);
		world.setBlock(i + 0, j + 3, k + 15, Blocks.redCobble.blockID);
		world.setBlock(i + 0, j + 3, k + 16, Blocks.redCobble.blockID);
		world.setBlock(i + 0, j + 3, k + 17, Blocks.redCobble.blockID);
		world.setBlock(i + 0, j + 3, k + 18, Blocks.redCobble.blockID);
		world.setBlock(i + 0, j + 3, k + 19, Blocks.redCobble.blockID);
		world.setBlock(i + 0, j + 3, k + 20, Blocks.redCobble.blockID);
		world.setBlock(i + 0, j + 3, k + 21, Blocks.redCobble.blockID);
		world.setBlock(i + 0, j + 3, k + 22, Blocks.redCobble.blockID);
		world.setBlock(i + 0, j + 3, k + 23, Blocks.redCobble.blockID);
		world.setBlock(i + 0, j + 3, k + 24, Blocks.redCobble.blockID);
		world.setBlock(i + 0, j + 3, k + 25, Blocks.redCobble.blockID);
		world.setBlock(i + 0, j + 3, k + 26, Blocks.redCobble.blockID);
		world.setBlock(i + 0, j + 3, k + 27, Blocks.redCobble.blockID);
		world.setBlock(i + 0, j + 3, k + 28, Blocks.redCobble.blockID);
		world.setBlock(i + 0, j + 3, k + 29, Blocks.redCobble.blockID);
		world.setBlock(i + 0, j + 3, k + 30, Blocks.redCobble.blockID);
		world.setBlock(i + 0, j + 3, k + 31, Blocks.redCobble.blockID);
		world.setBlock(i + 0, j + 3, k + 32, Blocks.redCobble.blockID);
		world.setBlock(i + 0, j + 3, k + 33, Blocks.redCobble.blockID);
		world.setBlock(i + 0, j + 3, k + 34, Blocks.redCobble.blockID);
		world.setBlock(i + 0, j + 3, k + 35, Blocks.redCobble.blockID);
		world.setBlock(i + 0, j + 3, k + 36, Blocks.redCobble.blockID);
		world.setBlock(i + 0, j + 3, k + 37, Blocks.redCobble.blockID);
		world.setBlock(i + 0, j + 3, k + 38, Blocks.redCobble.blockID);
		world.setBlock(i + 0, j + 3, k + 39, Blocks.redCobble.blockID);
		world.setBlock(i + 0, j + 3, k + 40, Blocks.redCobble.blockID);
		world.setBlock(i + 0, j + 4, k + 0, Blocks.redCobble.blockID);
		world.setBlock(i + 0, j + 4, k + 1, Blocks.redCobble.blockID);
		world.setBlock(i + 0, j + 4, k + 2, Blocks.redCobble.blockID);
		world.setBlock(i + 0, j + 4, k + 3, Blocks.redCobble.blockID);
		world.setBlock(i + 0, j + 4, k + 4, Blocks.redCobble.blockID);
		world.setBlock(i + 0, j + 4, k + 5, Blocks.redCobble.blockID);
		world.setBlock(i + 0, j + 4, k + 6, Blocks.redCobble.blockID);
		world.setBlock(i + 0, j + 4, k + 7, Blocks.redCobble.blockID);
		world.setBlock(i + 0, j + 4, k + 8, Blocks.redCobble.blockID);
		world.setBlock(i + 0, j + 4, k + 9, Blocks.redCobble.blockID);
		world.setBlock(i + 0, j + 4, k + 10, Blocks.redCobble.blockID);
		world.setBlock(i + 0, j + 4, k + 11, Blocks.redCobble.blockID);
		world.setBlock(i + 0, j + 4, k + 12, Blocks.redCobble.blockID);
		world.setBlock(i + 0, j + 4, k + 13, Blocks.redCobble.blockID);
		world.setBlock(i + 0, j + 4, k + 14, Blocks.redCobble.blockID);
		world.setBlock(i + 0, j + 4, k + 15, Blocks.redCobble.blockID);
		world.setBlock(i + 0, j + 4, k + 16, Blocks.redCobble.blockID);
		world.setBlock(i + 0, j + 4, k + 17, Blocks.redCobble.blockID);
		world.setBlock(i + 0, j + 4, k + 18, Blocks.redCobble.blockID);
		world.setBlock(i + 0, j + 4, k + 19, Blocks.redCobble.blockID);
		world.setBlock(i + 0, j + 4, k + 20, Blocks.redCobble.blockID);
		world.setBlock(i + 0, j + 4, k + 21, Blocks.redCobble.blockID);
		world.setBlock(i + 0, j + 4, k + 22, Blocks.redCobble.blockID);
		world.setBlock(i + 0, j + 4, k + 23, Blocks.redCobble.blockID);
		world.setBlock(i + 0, j + 4, k + 24, Blocks.redCobble.blockID);
		world.setBlock(i + 0, j + 4, k + 25, Blocks.redCobble.blockID);
		world.setBlock(i + 0, j + 4, k + 26, Blocks.redCobble.blockID);
		world.setBlock(i + 0, j + 4, k + 27, Blocks.redCobble.blockID);
		world.setBlock(i + 0, j + 4, k + 28, Blocks.redCobble.blockID);
		world.setBlock(i + 0, j + 4, k + 29, Blocks.redCobble.blockID);
		world.setBlock(i + 0, j + 4, k + 30, Blocks.redCobble.blockID);
		world.setBlock(i + 0, j + 4, k + 31, Blocks.redCobble.blockID);
		world.setBlock(i + 0, j + 4, k + 32, Blocks.redCobble.blockID);
		world.setBlock(i + 0, j + 4, k + 33, Blocks.redCobble.blockID);
		world.setBlock(i + 0, j + 4, k + 34, Blocks.redCobble.blockID);
		world.setBlock(i + 0, j + 4, k + 35, Blocks.redCobble.blockID);
		world.setBlock(i + 0, j + 4, k + 36, Blocks.redCobble.blockID);
		world.setBlock(i + 0, j + 4, k + 37, Blocks.redCobble.blockID);
		world.setBlock(i + 0, j + 4, k + 38, Blocks.redCobble.blockID);
		world.setBlock(i + 0, j + 4, k + 39, Blocks.redCobble.blockID);
		world.setBlock(i + 0, j + 4, k + 40, Blocks.redCobble.blockID);
		world.setBlock(i + 0, j + 5, k + 0, Blocks.redCobble.blockID);
		world.setBlock(i + 0, j + 5, k + 1, Blocks.redCobble.blockID);
		world.setBlock(i + 0, j + 5, k + 2, Blocks.redCobble.blockID);
		world.setBlock(i + 0, j + 5, k + 3, Blocks.redCobble.blockID);
		world.setBlock(i + 0, j + 5, k + 4, Blocks.redCobble.blockID);
		world.setBlock(i + 0, j + 5, k + 5, Blocks.redCobble.blockID);
		world.setBlock(i + 0, j + 5, k + 6, Blocks.redCobble.blockID);
		world.setBlock(i + 0, j + 5, k + 7, Blocks.redCobble.blockID);
		world.setBlock(i + 0, j + 5, k + 8, Blocks.redCobble.blockID);
		world.setBlock(i + 0, j + 5, k + 9, Blocks.redCobble.blockID);
		world.setBlock(i + 0, j + 5, k + 10, Blocks.redCobble.blockID);
		world.setBlock(i + 0, j + 5, k + 11, Blocks.redCobble.blockID);
		world.setBlock(i + 0, j + 5, k + 12, Blocks.redCobble.blockID);
		world.setBlock(i + 0, j + 5, k + 13, Blocks.redCobble.blockID);
		world.setBlock(i + 0, j + 5, k + 14, Blocks.redCobble.blockID);
		world.setBlock(i + 0, j + 5, k + 15, Blocks.redCobble.blockID);
		world.setBlock(i + 0, j + 5, k + 16, Blocks.redCobble.blockID);
		world.setBlock(i + 0, j + 5, k + 17, Blocks.redCobble.blockID);
		world.setBlock(i + 0, j + 5, k + 18, Blocks.redCobble.blockID);
		world.setBlock(i + 0, j + 5, k + 19, Blocks.redCobble.blockID);
		world.setBlock(i + 0, j + 5, k + 20, Blocks.redCobble.blockID);
		world.setBlock(i + 0, j + 5, k + 21, Blocks.redCobble.blockID);
		world.setBlock(i + 0, j + 5, k + 22, Blocks.redCobble.blockID);
		world.setBlock(i + 0, j + 5, k + 23, Blocks.redCobble.blockID);
		world.setBlock(i + 0, j + 5, k + 24, Blocks.redCobble.blockID);
		world.setBlock(i + 0, j + 5, k + 25, Blocks.redCobble.blockID);
		world.setBlock(i + 0, j + 5, k + 26, Blocks.redCobble.blockID);
		world.setBlock(i + 0, j + 5, k + 27, Blocks.redCobble.blockID);
		world.setBlock(i + 0, j + 5, k + 28, Blocks.redCobble.blockID);
		world.setBlock(i + 0, j + 5, k + 29, Blocks.redCobble.blockID);
		world.setBlock(i + 0, j + 5, k + 30, Blocks.redCobble.blockID);
		world.setBlock(i + 0, j + 5, k + 31, Blocks.redCobble.blockID);
		world.setBlock(i + 0, j + 5, k + 32, Blocks.redCobble.blockID);
		world.setBlock(i + 0, j + 5, k + 33, Blocks.redCobble.blockID);
		world.setBlock(i + 0, j + 5, k + 34, Blocks.redCobble.blockID);
		world.setBlock(i + 0, j + 5, k + 35, Blocks.redCobble.blockID);
		world.setBlock(i + 0, j + 5, k + 36, Blocks.redCobble.blockID);
		world.setBlock(i + 0, j + 5, k + 37, Blocks.redCobble.blockID);
		world.setBlock(i + 0, j + 5, k + 38, Blocks.redCobble.blockID);
		world.setBlock(i + 0, j + 5, k + 39, Blocks.redCobble.blockID);
		world.setBlock(i + 0, j + 5, k + 40, Blocks.redCobble.blockID);
		world.setBlock(i + 0, j + 6, k + 0, Blocks.redCobble.blockID);
		world.setBlock(i + 0, j + 6, k + 1, Blocks.redCobble.blockID);
		world.setBlock(i + 0, j + 6, k + 2, Blocks.redCobble.blockID);
		world.setBlock(i + 0, j + 6, k + 3, Blocks.redCobble.blockID);
		world.setBlock(i + 0, j + 6, k + 4, Blocks.redCobble.blockID);
		world.setBlock(i + 0, j + 6, k + 5, Blocks.redCobble.blockID);
		world.setBlock(i + 0, j + 6, k + 6, Blocks.redCobble.blockID);
		world.setBlock(i + 0, j + 6, k + 7, Blocks.redCobble.blockID);
		world.setBlock(i + 0, j + 6, k + 8, Blocks.redCobble.blockID);
		world.setBlock(i + 0, j + 6, k + 9, Blocks.redCobble.blockID);
		world.setBlock(i + 0, j + 6, k + 10, Blocks.redCobble.blockID);
		world.setBlock(i + 0, j + 6, k + 11, Blocks.redCobble.blockID);
		world.setBlock(i + 0, j + 6, k + 12, Blocks.redCobble.blockID);
		world.setBlock(i + 0, j + 6, k + 13, Blocks.redCobble.blockID);
		world.setBlock(i + 0, j + 6, k + 14, Blocks.redCobble.blockID);
		world.setBlock(i + 0, j + 6, k + 15, Blocks.redCobble.blockID);
		world.setBlock(i + 0, j + 6, k + 16, Blocks.redCobble.blockID);
		world.setBlock(i + 0, j + 6, k + 17, Blocks.redCobble.blockID);
		world.setBlock(i + 0, j + 6, k + 18, Blocks.redCobble.blockID);
		world.setBlock(i + 0, j + 6, k + 19, Blocks.redCobble.blockID);
		world.setBlock(i + 0, j + 6, k + 20, Blocks.redCobble.blockID);
		world.setBlock(i + 0, j + 6, k + 21, Blocks.redCobble.blockID);
		world.setBlock(i + 0, j + 6, k + 22, Blocks.redCobble.blockID);
		world.setBlock(i + 0, j + 6, k + 23, Blocks.redCobble.blockID);
		world.setBlock(i + 0, j + 6, k + 24, Blocks.redCobble.blockID);
		world.setBlock(i + 0, j + 6, k + 25, Blocks.redCobble.blockID);
		world.setBlock(i + 0, j + 6, k + 26, Blocks.redCobble.blockID);
		world.setBlock(i + 0, j + 6, k + 27, Blocks.redCobble.blockID);
		world.setBlock(i + 0, j + 6, k + 28, Blocks.redCobble.blockID);
		world.setBlock(i + 0, j + 6, k + 29, Blocks.redCobble.blockID);
		world.setBlock(i + 0, j + 6, k + 30, Blocks.redCobble.blockID);
		world.setBlock(i + 0, j + 6, k + 31, Blocks.redCobble.blockID);
		world.setBlock(i + 0, j + 6, k + 32, Blocks.redCobble.blockID);
		world.setBlock(i + 0, j + 6, k + 33, Blocks.redCobble.blockID);
		world.setBlock(i + 0, j + 6, k + 34, Blocks.redCobble.blockID);
		world.setBlock(i + 0, j + 6, k + 35, Blocks.redCobble.blockID);
		world.setBlock(i + 0, j + 6, k + 36, Blocks.redCobble.blockID);
		world.setBlock(i + 0, j + 6, k + 37, Blocks.redCobble.blockID);
		world.setBlock(i + 0, j + 6, k + 38, Blocks.redCobble.blockID);
		world.setBlock(i + 0, j + 6, k + 39, Blocks.redCobble.blockID);
		world.setBlock(i + 0, j + 6, k + 40, Blocks.redCobble.blockID);
		world.setBlock(i + 1, j + 0, k + 0, Blocks.redCobble.blockID);
		world.setBlock(i + 1, j + 0, k + 1, Blocks.redCobble.blockID);
		world.setBlock(i + 1, j + 0, k + 2, Blocks.redCobble.blockID);
		world.setBlock(i + 1, j + 0, k + 3, Blocks.redCobble.blockID);
		world.setBlock(i + 1, j + 0, k + 4, Blocks.shineStone.blockID);
		world.setBlock(i + 1, j + 0, k + 5, Blocks.redCobble.blockID);
		world.setBlock(i + 1, j + 0, k + 6, Blocks.redCobble.blockID);
		world.setBlock(i + 1, j + 0, k + 7, Blocks.redCobble.blockID);
		world.setBlock(i + 1, j + 0, k + 8, Blocks.redCobble.blockID);
		world.setBlock(i + 1, j + 0, k + 9, Blocks.redCobble.blockID);
		world.setBlock(i + 1, j + 0, k + 10, Blocks.redCobble.blockID);
		world.setBlock(i + 1, j + 0, k + 11, Blocks.redCobble.blockID);
		world.setBlock(i + 1, j + 0, k + 12, Blocks.redCobble.blockID);
		world.setBlock(i + 1, j + 0, k + 13, Blocks.redCobble.blockID);
		world.setBlock(i + 1, j + 0, k + 14, Blocks.shineStone.blockID);
		world.setBlock(i + 1, j + 0, k + 15, Blocks.redCobble.blockID);
		world.setBlock(i + 1, j + 0, k + 16, Blocks.redCobble.blockID);
		world.setBlock(i + 1, j + 0, k + 17, Blocks.redCobble.blockID);
		world.setBlock(i + 1, j + 0, k + 18, Blocks.redCobble.blockID);
		world.setBlock(i + 1, j + 0, k + 19, Blocks.redCobble.blockID);
		world.setBlock(i + 1, j + 0, k + 20, Blocks.redCobble.blockID);
		world.setBlock(i + 1, j + 0, k + 21, Blocks.redCobble.blockID);
		world.setBlock(i + 1, j + 0, k + 22, Blocks.shineStone.blockID);
		world.setBlock(i + 1, j + 0, k + 23, Blocks.redCobble.blockID);
		world.setBlock(i + 1, j + 0, k + 24, Blocks.redCobble.blockID);
		world.setBlock(i + 1, j + 0, k + 25, Blocks.redCobble.blockID);
		world.setBlock(i + 1, j + 0, k + 26, Blocks.redCobble.blockID);
		world.setBlock(i + 1, j + 0, k + 27, Blocks.redCobble.blockID);
		world.setBlock(i + 1, j + 0, k + 28, Blocks.redCobble.blockID);
		world.setBlock(i + 1, j + 0, k + 29, Blocks.redCobble.blockID);
		world.setBlock(i + 1, j + 0, k + 30, Blocks.redCobble.blockID);
		world.setBlock(i + 1, j + 0, k + 31, Blocks.redCobble.blockID);
		world.setBlock(i + 1, j + 0, k + 32, Blocks.redCobble.blockID);
		world.setBlock(i + 1, j + 0, k + 33, Blocks.redCobble.blockID);
		world.setBlock(i + 1, j + 0, k + 34, Blocks.redCobble.blockID);
		world.setBlock(i + 1, j + 0, k + 35, Blocks.redCobble.blockID);
		world.setBlock(i + 1, j + 0, k + 36, Blocks.redCobble.blockID);
		world.setBlock(i + 1, j + 0, k + 37, Blocks.redCobble.blockID);
		world.setBlock(i + 1, j + 0, k + 38, Blocks.redCobble.blockID);
		world.setBlock(i + 1, j + 0, k + 39, Blocks.redCobble.blockID);
		world.setBlock(i + 1, j + 0, k + 40, Blocks.redCobble.blockID);
		world.setBlock(i + 1, j + 1, k + 0, Blocks.redCobble.blockID);
		world.setBlock(i + 1, j + 1, k + 1, Block.workbench.blockID);
		world.setBlock(i + 1, j + 1, k + 6, Blocks.redCobble.blockID);
		world.setBlock(i + 1, j + 1, k + 7, Block.workbench.blockID);
		world.setBlock(i + 1, j + 1, k + 11, -111);
		world.setBlock(i + 1, j + 1, k + 12, Blocks.redCobble.blockID);
		world.setBlock(i + 1, j + 1, k + 13, Block.workbench.blockID);
		int randInt = (new Random()).nextInt(8);
		if (randInt == 2) {
			int chestX = i + 1;
			int chestY = j + 1;
			int chestZ = k + 18;
			int chestRand = (int) (Math.random() * Math.floor(2));
			boolean isBigChest = (chestRand == 1) ? true : false;
			String chestString = chestX + " " + chestY + " " + chestZ;
			Treasures.spawnChest(world, rand, chestX, chestY, chestZ,
					isBigChest,
					Treasures.pickChestType());
		}
		world.setBlock(i + 1, j + 1, k + 19, Blocks.redCobble.blockID);
		world.setBlock(i + 1, j + 1, k + 20, Block.workbench.blockID);
		world.setBlock(i + 1, j + 1, k + 26, Blocks.redCobble.blockID);
		world.setBlock(i + 1, j + 1, k + 27, Block.workbench.blockID);
		int randInt2 = (new Random()).nextInt(8);
		if (randInt2 == 4) {
			int chestX = i + 1;
			int chestY = j + 1;
			int chestZ = k + 32;
			int chestRand = (int) (Math.random() * Math.floor(2));
			boolean isBigChest = (chestRand == 1) ? true : false;
			String chestString = chestX + " " + chestY + " " + chestZ;
			Treasures.spawnChest(world, rand, chestX, chestY, chestZ,
					isBigChest,
					Treasures.pickChestType());
		}
		world.setBlock(i + 1, j + 1, k + 33, Blocks.redCobble.blockID);
		world.setBlock(i + 1, j + 1, k + 34, Block.workbench.blockID);
		int randInt3 = (new Random()).nextInt(8);
		if (randInt3 == 6) {
			int chestX = i + 1;
			int chestY = j + 1;
			int chestZ = k + 39;
			int chestRand = (int) (Math.random() * Math.floor(2));
			boolean isBigChest = (chestRand == 1) ? true : false;
			String chestString = chestX + " " + chestY + " " + chestZ;
			Treasures.spawnChest(world, rand, chestX, chestY, chestZ,
					isBigChest,
					Treasures.pickChestType());
		}
		world.setBlock(i + 1, j + 1, k + 40, Blocks.redCobble.blockID);
		world.setBlock(i + 1, j + 2, k + 0, Blocks.redCobble.blockID);
		world.setBlock(i + 1, j + 2, k + 3, -112);
		world.setBlock(i + 1, j + 2, k + 6, Blocks.betterGlass.blockID);
		world.setBlock(i + 1, j + 2, k + 8, -112);
		world.setBlock(i + 1, j + 2, k + 12, Blocks.redCobble.blockID);
		world.setBlock(i + 1, j + 2, k + 19, Blocks.betterGlass.blockID);
		world.setBlock(i + 1, j + 2, k + 26, Blocks.betterGlass.blockID);
		world.setBlock(i + 1, j + 2, k + 30, -112);
		world.setBlock(i + 1, j + 2, k + 33, Blocks.redCobble.blockID);
		world.setBlock(i + 1, j + 2, k + 36, -112);
		world.setBlock(i + 1, j + 2, k + 40, Blocks.redCobble.blockID);
		world.setBlock(i + 1, j + 3, k + 0, Blocks.redCobble.blockID);
		world.setBlock(i + 1, j + 3, k + 6, Blocks.redCobble.blockID);
		world.setBlock(i + 1, j + 3, k + 12, Blocks.redCobble.blockID);
		world.setBlock(i + 1, j + 3, k + 19, Blocks.redCobble.blockID);
		world.setBlock(i + 1, j + 3, k + 26, Blocks.redCobble.blockID);
		world.setBlock(i + 1, j + 3, k + 33, Blocks.redCobble.blockID);
		world.setBlock(i + 1, j + 3, k + 40, Blocks.redCobble.blockID);
		world.setBlock(i + 1, j + 4, k + 0, Blocks.redCobble.blockID);
		world.setBlock(i + 1, j + 4, k + 6, Blocks.redCobble.blockID);
		world.setBlock(i + 1, j + 4, k + 12, Blocks.redCobble.blockID);
		world.setBlock(i + 1, j + 4, k + 19, Blocks.redCobble.blockID);
		world.setBlock(i + 1, j + 4, k + 26, Blocks.redCobble.blockID);
		world.setBlock(i + 1, j + 4, k + 33, Blocks.redCobble.blockID);
		world.setBlock(i + 1, j + 4, k + 40, Blocks.redCobble.blockID);
		world.setBlock(i + 1, j + 5, k + 0, Blocks.redCobble.blockID);
		world.setBlock(i + 1, j + 5, k + 6, Blocks.redCobble.blockID);
		world.setBlock(i + 1, j + 5, k + 12, Blocks.redCobble.blockID);
		world.setBlock(i + 1, j + 5, k + 19, Blocks.redCobble.blockID);
		world.setBlock(i + 1, j + 5, k + 26, Blocks.redCobble.blockID);
		world.setBlock(i + 1, j + 5, k + 33, Blocks.redCobble.blockID);
		world.setBlock(i + 1, j + 5, k + 40, Blocks.redCobble.blockID);
		world.setBlock(i + 1, j + 6, k + 0, Blocks.redCobble.blockID);
		world.setBlock(i + 1, j + 6, k + 1, Blocks.redCobble.blockID);
		world.setBlock(i + 1, j + 6, k + 2, Blocks.redCobble.blockID);
		world.setBlock(i + 1, j + 6, k + 3, Blocks.redCobble.blockID);
		world.setBlock(i + 1, j + 6, k + 4, Blocks.redCobble.blockID);
		world.setBlock(i + 1, j + 6, k + 5, Blocks.redCobble.blockID);
		world.setBlock(i + 1, j + 6, k + 6, Blocks.redCobble.blockID);
		world.setBlock(i + 1, j + 6, k + 7, Blocks.redCobble.blockID);
		world.setBlock(i + 1, j + 6, k + 8, Blocks.redCobble.blockID);
		world.setBlock(i + 1, j + 6, k + 9, Blocks.redCobble.blockID);
		world.setBlock(i + 1, j + 6, k + 10, Blocks.redCobble.blockID);
		world.setBlock(i + 1, j + 6, k + 11, Blocks.redCobble.blockID);
		world.setBlock(i + 1, j + 6, k + 12, Blocks.redCobble.blockID);
		world.setBlock(i + 1, j + 6, k + 13, Blocks.redCobble.blockID);
		world.setBlock(i + 1, j + 6, k + 14, Blocks.redCobble.blockID);
		world.setBlock(i + 1, j + 6, k + 15, Blocks.redCobble.blockID);
		world.setBlock(i + 1, j + 6, k + 16, Blocks.redCobble.blockID);
		world.setBlock(i + 1, j + 6, k + 17, Blocks.redCobble.blockID);
		world.setBlock(i + 1, j + 6, k + 18, Blocks.redCobble.blockID);
		world.setBlock(i + 1, j + 6, k + 19, Blocks.redCobble.blockID);
		world.setBlock(i + 1, j + 6, k + 20, Blocks.redCobble.blockID);
		world.setBlock(i + 1, j + 6, k + 21, Blocks.redCobble.blockID);
		world.setBlock(i + 1, j + 6, k + 22, Blocks.redCobble.blockID);
		world.setBlock(i + 1, j + 6, k + 23, Blocks.redCobble.blockID);
		world.setBlock(i + 1, j + 6, k + 24, Blocks.redCobble.blockID);
		world.setBlock(i + 1, j + 6, k + 25, Blocks.redCobble.blockID);
		world.setBlock(i + 1, j + 6, k + 26, Blocks.redCobble.blockID);
		world.setBlock(i + 1, j + 6, k + 27, Blocks.redCobble.blockID);
		world.setBlock(i + 1, j + 6, k + 28, Blocks.redCobble.blockID);
		world.setBlock(i + 1, j + 6, k + 29, Blocks.redCobble.blockID);
		world.setBlock(i + 1, j + 6, k + 30, Blocks.redCobble.blockID);
		world.setBlock(i + 1, j + 6, k + 31, Blocks.redCobble.blockID);
		world.setBlock(i + 1, j + 6, k + 32, Blocks.redCobble.blockID);
		world.setBlock(i + 1, j + 6, k + 33, Blocks.redCobble.blockID);
		world.setBlock(i + 1, j + 6, k + 34, Blocks.redCobble.blockID);
		world.setBlock(i + 1, j + 6, k + 35, Blocks.redCobble.blockID);
		world.setBlock(i + 1, j + 6, k + 36, Blocks.redCobble.blockID);
		world.setBlock(i + 1, j + 6, k + 37, Blocks.redCobble.blockID);
		world.setBlock(i + 1, j + 6, k + 38, Blocks.redCobble.blockID);
		world.setBlock(i + 1, j + 6, k + 39, Blocks.redCobble.blockID);
		world.setBlock(i + 1, j + 6, k + 40, Blocks.redCobble.blockID);
		world.setBlock(i + 2, j + 0, k + 0, Blocks.redCobble.blockID);
		world.setBlock(i + 2, j + 0, k + 1, Blocks.redCobble.blockID);
		world.setBlock(i + 2, j + 0, k + 2, Blocks.redCobble.blockID);
		world.setBlock(i + 2, j + 0, k + 3, Blocks.redCobble.blockID);
		world.setBlock(i + 2, j + 0, k + 4, Blocks.redCobble.blockID);
		world.setBlock(i + 2, j + 0, k + 5, Blocks.redCobble.blockID);
		world.setBlock(i + 2, j + 0, k + 6, Blocks.redCobble.blockID);
		world.setBlock(i + 2, j + 0, k + 7, Blocks.redCobble.blockID);
		world.setBlock(i + 2, j + 0, k + 8, Blocks.redCobble.blockID);
		world.setBlock(i + 2, j + 0, k + 9, Blocks.shineStone.blockID);
		world.setBlock(i + 2, j + 0, k + 10, Blocks.redCobble.blockID);
		world.setBlock(i + 2, j + 0, k + 11, Blocks.redCobble.blockID);
		world.setBlock(i + 2, j + 0, k + 12, Blocks.redCobble.blockID);
		world.setBlock(i + 2, j + 0, k + 13, Blocks.redCobble.blockID);
		world.setBlock(i + 2, j + 0, k + 14, Blocks.redCobble.blockID);
		world.setBlock(i + 2, j + 0, k + 15, Blocks.redCobble.blockID);
		world.setBlock(i + 2, j + 0, k + 16, Blocks.redCobble.blockID);
		world.setBlock(i + 2, j + 0, k + 17, Blocks.redCobble.blockID);
		world.setBlock(i + 2, j + 0, k + 18, Blocks.redCobble.blockID);
		world.setBlock(i + 2, j + 0, k + 19, Blocks.redCobble.blockID);
		world.setBlock(i + 2, j + 0, k + 20, Blocks.redCobble.blockID);
		world.setBlock(i + 2, j + 0, k + 21, Blocks.redCobble.blockID);
		world.setBlock(i + 2, j + 0, k + 22, Blocks.redCobble.blockID);
		world.setBlock(i + 2, j + 0, k + 23, Blocks.redCobble.blockID);
		world.setBlock(i + 2, j + 0, k + 24, Blocks.redCobble.blockID);
		world.setBlock(i + 2, j + 0, k + 25, Blocks.redCobble.blockID);
		world.setBlock(i + 2, j + 0, k + 26, Blocks.redCobble.blockID);
		world.setBlock(i + 2, j + 0, k + 27, Blocks.redCobble.blockID);
		world.setBlock(i + 2, j + 0, k + 28, Blocks.redCobble.blockID);
		world.setBlock(i + 2, j + 0, k + 29, Blocks.redCobble.blockID);
		world.setBlock(i + 2, j + 0, k + 30, Blocks.shineStone.blockID);
		world.setBlock(i + 2, j + 0, k + 31, Blocks.redCobble.blockID);
		world.setBlock(i + 2, j + 0, k + 32, Blocks.redCobble.blockID);
		world.setBlock(i + 2, j + 0, k + 33, Blocks.redCobble.blockID);
		world.setBlock(i + 2, j + 0, k + 34, Blocks.redCobble.blockID);
		world.setBlock(i + 2, j + 0, k + 35, Blocks.redCobble.blockID);
		world.setBlock(i + 2, j + 0, k + 36, Blocks.redCobble.blockID);
		world.setBlock(i + 2, j + 0, k + 37, Blocks.redCobble.blockID);
		world.setBlock(i + 2, j + 0, k + 38, Blocks.redCobble.blockID);
		world.setBlock(i + 2, j + 0, k + 39, Blocks.redCobble.blockID);
		world.setBlock(i + 2, j + 0, k + 40, Blocks.redCobble.blockID);
		world.setBlock(i + 2, j + 1, k + 0, Blocks.redCobble.blockID);
		world.setBlock(i + 2, j + 1, k + 1, Block.bed.blockID);
		world.setBlock(i + 2, j + 1, k + 2, Block.bed.blockID);
		world.setBlock(i + 2, j + 1, k + 19, Blocks.redCobble.blockID);
		world.setBlock(i + 2, j + 1, k + 26, Blocks.redCobble.blockID);
		world.setBlock(i + 2, j + 1, k + 33, Blocks.redCobble.blockID);
		world.setBlock(i + 2, j + 1, k + 40, Blocks.redCobble.blockID);
		world.setBlock(i + 2, j + 2, k + 0, Blocks.redCobble.blockID);
		world.setBlock(i + 2, j + 2, k + 18, -112);
		world.setBlock(i + 2, j + 2, k + 19, Blocks.redCobble.blockID);
		world.setBlock(i + 2, j + 2, k + 20, -112);
		world.setBlock(i + 2, j + 2, k + 25, -112);
		world.setBlock(i + 2, j + 2, k + 26, Blocks.redCobble.blockID);
		world.setBlock(i + 2, j + 2, k + 33, Blocks.betterGlass.blockID);
		world.setBlock(i + 2, j + 2, k + 40, Blocks.redCobble.blockID);
		world.setBlock(i + 2, j + 3, k + 0, Blocks.redCobble.blockID);
		world.setBlock(i + 2, j + 3, k + 6, Blocks.redCobble.blockID);
		world.setBlock(i + 2, j + 3, k + 12, Blocks.redCobble.blockID);
		world.setBlock(i + 2, j + 3, k + 19, Blocks.redCobble.blockID);
		world.setBlock(i + 2, j + 3, k + 26, Blocks.redCobble.blockID);
		world.setBlock(i + 2, j + 3, k + 33, Blocks.redCobble.blockID);
		world.setBlock(i + 2, j + 3, k + 40, Blocks.redCobble.blockID);
		world.setBlock(i + 2, j + 4, k + 0, Blocks.redCobble.blockID);
		world.setBlock(i + 2, j + 4, k + 6, Blocks.redCobble.blockID);
		world.setBlock(i + 2, j + 4, k + 12, Blocks.redCobble.blockID);
		world.setBlock(i + 2, j + 4, k + 19, Blocks.redCobble.blockID);
		world.setBlock(i + 2, j + 4, k + 26, Blocks.redCobble.blockID);
		world.setBlock(i + 2, j + 4, k + 33, Blocks.redCobble.blockID);
		world.setBlock(i + 2, j + 4, k + 40, Blocks.redCobble.blockID);
		world.setBlock(i + 2, j + 5, k + 0, Blocks.redCobble.blockID);
		world.setBlock(i + 2, j + 5, k + 6, Blocks.redCobble.blockID);
		world.setBlock(i + 2, j + 5, k + 12, Blocks.redCobble.blockID);
		world.setBlock(i + 2, j + 5, k + 19, Blocks.redCobble.blockID);
		world.setBlock(i + 2, j + 5, k + 26, Blocks.redCobble.blockID);
		world.setBlock(i + 2, j + 5, k + 33, Blocks.redCobble.blockID);
		world.setBlock(i + 2, j + 5, k + 40, Blocks.redCobble.blockID);
		world.setBlock(i + 2, j + 6, k + 0, Blocks.redCobble.blockID);
		world.setBlock(i + 2, j + 6, k + 1, Blocks.redCobble.blockID);
		world.setBlock(i + 2, j + 6, k + 2, Blocks.redCobble.blockID);
		world.setBlock(i + 2, j + 6, k + 3, Blocks.redCobble.blockID);
		world.setBlock(i + 2, j + 6, k + 4, Blocks.redCobble.blockID);
		world.setBlock(i + 2, j + 6, k + 5, Blocks.redCobble.blockID);
		world.setBlock(i + 2, j + 6, k + 6, Blocks.redCobble.blockID);
		world.setBlock(i + 2, j + 6, k + 7, Blocks.redCobble.blockID);
		world.setBlock(i + 2, j + 6, k + 8, Blocks.redCobble.blockID);
		world.setBlock(i + 2, j + 6, k + 9, Blocks.redCobble.blockID);
		world.setBlock(i + 2, j + 6, k + 10, Blocks.redCobble.blockID);
		world.setBlock(i + 2, j + 6, k + 11, Blocks.redCobble.blockID);
		world.setBlock(i + 2, j + 6, k + 12, Blocks.redCobble.blockID);
		world.setBlock(i + 2, j + 6, k + 13, Blocks.redCobble.blockID);
		world.setBlock(i + 2, j + 6, k + 14, Blocks.redCobble.blockID);
		world.setBlock(i + 2, j + 6, k + 15, Blocks.redCobble.blockID);
		world.setBlock(i + 2, j + 6, k + 16, Blocks.redCobble.blockID);
		world.setBlock(i + 2, j + 6, k + 17, Blocks.redCobble.blockID);
		world.setBlock(i + 2, j + 6, k + 18, Blocks.redCobble.blockID);
		world.setBlock(i + 2, j + 6, k + 19, Blocks.redCobble.blockID);
		world.setBlock(i + 2, j + 6, k + 20, Blocks.redCobble.blockID);
		world.setBlock(i + 2, j + 6, k + 21, Blocks.redCobble.blockID);
		world.setBlock(i + 2, j + 6, k + 22, Blocks.redCobble.blockID);
		world.setBlock(i + 2, j + 6, k + 23, Blocks.redCobble.blockID);
		world.setBlock(i + 2, j + 6, k + 24, Blocks.redCobble.blockID);
		world.setBlock(i + 2, j + 6, k + 25, Blocks.redCobble.blockID);
		world.setBlock(i + 2, j + 6, k + 26, Blocks.redCobble.blockID);
		world.setBlock(i + 2, j + 6, k + 27, Blocks.redCobble.blockID);
		world.setBlock(i + 2, j + 6, k + 28, Blocks.redCobble.blockID);
		world.setBlock(i + 2, j + 6, k + 29, Blocks.redCobble.blockID);
		world.setBlock(i + 2, j + 6, k + 30, Blocks.redCobble.blockID);
		world.setBlock(i + 2, j + 6, k + 31, Blocks.redCobble.blockID);
		world.setBlock(i + 2, j + 6, k + 32, Blocks.redCobble.blockID);
		world.setBlock(i + 2, j + 6, k + 33, Blocks.redCobble.blockID);
		world.setBlock(i + 2, j + 6, k + 34, Blocks.redCobble.blockID);
		world.setBlock(i + 2, j + 6, k + 35, Blocks.redCobble.blockID);
		world.setBlock(i + 2, j + 6, k + 36, Blocks.redCobble.blockID);
		world.setBlock(i + 2, j + 6, k + 37, Blocks.redCobble.blockID);
		world.setBlock(i + 2, j + 6, k + 38, Blocks.redCobble.blockID);
		world.setBlock(i + 2, j + 6, k + 39, Blocks.redCobble.blockID);
		world.setBlock(i + 2, j + 6, k + 40, Blocks.redCobble.blockID);
		world.setBlock(i + 3, j + 0, k + 0, Blocks.redCobble.blockID);
		world.setBlock(i + 3, j + 0, k + 1, Blocks.redCobble.blockID);
		world.setBlock(i + 3, j + 0, k + 2, Blocks.redCobble.blockID);
		world.setBlock(i + 3, j + 0, k + 3, Blocks.redCobble.blockID);
		world.setBlock(i + 3, j + 0, k + 4, Blocks.redCobble.blockID);
		world.setBlock(i + 3, j + 0, k + 5, Blocks.redCobble.blockID);
		world.setBlock(i + 3, j + 0, k + 6, Blocks.redCobble.blockID);
		world.setBlock(i + 3, j + 0, k + 7, Blocks.redCobble.blockID);
		world.setBlock(i + 3, j + 0, k + 8, Blocks.redCobble.blockID);
		world.setBlock(i + 3, j + 0, k + 9, Blocks.redCobble.blockID);
		world.setBlock(i + 3, j + 0, k + 10, Blocks.redCobble.blockID);
		world.setBlock(i + 3, j + 0, k + 11, Blocks.redCobble.blockID);
		world.setBlock(i + 3, j + 0, k + 12, Blocks.redCobble.blockID);
		world.setBlock(i + 3, j + 0, k + 13, Blocks.redCobble.blockID);
		world.setBlock(i + 3, j + 0, k + 14, Blocks.redCobble.blockID);
		world.setBlock(i + 3, j + 0, k + 15, Blocks.redCobble.blockID);
		world.setBlock(i + 3, j + 0, k + 16, Blocks.redCobble.blockID);
		world.setBlock(i + 3, j + 0, k + 17, Blocks.redCobble.blockID);
		world.setBlock(i + 3, j + 0, k + 18, Blocks.redCobble.blockID);
		world.setBlock(i + 3, j + 0, k + 19, Blocks.redCobble.blockID);
		world.setBlock(i + 3, j + 0, k + 20, Blocks.redCobble.blockID);
		world.setBlock(i + 3, j + 0, k + 21, Blocks.redCobble.blockID);
		world.setBlock(i + 3, j + 0, k + 22, Blocks.redCobble.blockID);
		world.setBlock(i + 3, j + 0, k + 23, Blocks.redCobble.blockID);
		world.setBlock(i + 3, j + 0, k + 24, Blocks.redCobble.blockID);
		world.setBlock(i + 3, j + 0, k + 25, Blocks.redCobble.blockID);
		world.setBlock(i + 3, j + 0, k + 26, Blocks.redCobble.blockID);
		world.setBlock(i + 3, j + 0, k + 27, Blocks.redCobble.blockID);
		world.setBlock(i + 3, j + 0, k + 28, Blocks.redCobble.blockID);
		world.setBlock(i + 3, j + 0, k + 29, Blocks.redCobble.blockID);
		world.setBlock(i + 3, j + 0, k + 30, Blocks.redCobble.blockID);
		world.setBlock(i + 3, j + 0, k + 31, Blocks.redCobble.blockID);
		world.setBlock(i + 3, j + 0, k + 32, Blocks.redCobble.blockID);
		world.setBlock(i + 3, j + 0, k + 33, Blocks.redCobble.blockID);
		world.setBlock(i + 3, j + 0, k + 34, Blocks.redCobble.blockID);
		world.setBlock(i + 3, j + 0, k + 35, Blocks.redCobble.blockID);
		world.setBlock(i + 3, j + 0, k + 36, Blocks.shineStone.blockID);
		world.setBlock(i + 3, j + 0, k + 37, Blocks.redCobble.blockID);
		world.setBlock(i + 3, j + 0, k + 38, Blocks.redCobble.blockID);
		world.setBlock(i + 3, j + 0, k + 39, Blocks.redCobble.blockID);
		world.setBlock(i + 3, j + 0, k + 40, Blocks.redCobble.blockID);
		world.setBlock(i + 3, j + 1, k + 0, Blocks.redCobble.blockID);
		world.setBlock(i + 3, j + 1, k + 6, Blocks.redCobble.blockID);
		world.setBlock(i + 3, j + 1, k + 12, Blocks.redCobble.blockID);
		world.setBlock(i + 3, j + 1, k + 40, Blocks.redCobble.blockID);
		world.setBlock(i + 3, j + 2, k + 0, Blocks.redCobble.blockID);
		world.setBlock(i + 3, j + 2, k + 5, -112);
		world.setBlock(i + 3, j + 2, k + 6, Blocks.redCobble.blockID);
		world.setBlock(i + 3, j + 2, k + 12, Blocks.redCobble.blockID);
		world.setBlock(i + 3, j + 2, k + 40, Blocks.redCobble.blockID);
		world.setBlock(i + 3, j + 3, k + 0, Blocks.redCobble.blockID);
		world.setBlock(i + 3, j + 3, k + 6, Blocks.redCobble.blockID);
		world.setBlock(i + 3, j + 3, k + 12, Blocks.redCobble.blockID);
		world.setBlock(i + 3, j + 3, k + 19, Blocks.redCobble.blockID);
		world.setBlock(i + 3, j + 3, k + 26, Blocks.redCobble.blockID);
		world.setBlock(i + 3, j + 3, k + 33, Blocks.redCobble.blockID);
		world.setBlock(i + 3, j + 3, k + 40, Blocks.redCobble.blockID);
		world.setBlock(i + 3, j + 4, k + 0, Blocks.redCobble.blockID);
		world.setBlock(i + 3, j + 4, k + 6, Blocks.redCobble.blockID);
		world.setBlock(i + 3, j + 4, k + 12, Blocks.redCobble.blockID);
		world.setBlock(i + 3, j + 4, k + 19, Blocks.redCobble.blockID);
		world.setBlock(i + 3, j + 4, k + 26, Blocks.redCobble.blockID);
		world.setBlock(i + 3, j + 4, k + 33, Blocks.redCobble.blockID);
		world.setBlock(i + 3, j + 4, k + 40, Blocks.redCobble.blockID);
		world.setBlock(i + 3, j + 5, k + 0, Blocks.redCobble.blockID);
		world.setBlock(i + 3, j + 5, k + 6, Blocks.redCobble.blockID);
		world.setBlock(i + 3, j + 5, k + 12, Blocks.redCobble.blockID);
		world.setBlock(i + 3, j + 5, k + 19, Blocks.redCobble.blockID);
		world.setBlock(i + 3, j + 5, k + 26, Blocks.redCobble.blockID);
		world.setBlock(i + 3, j + 5, k + 33, Blocks.redCobble.blockID);
		world.setBlock(i + 3, j + 5, k + 40, Blocks.redCobble.blockID);
		world.setBlock(i + 3, j + 6, k + 0, Blocks.redCobble.blockID);
		world.setBlock(i + 3, j + 6, k + 1, Blocks.redCobble.blockID);
		world.setBlock(i + 3, j + 6, k + 2, Blocks.redCobble.blockID);
		world.setBlock(i + 3, j + 6, k + 3, Blocks.redCobble.blockID);
		world.setBlock(i + 3, j + 6, k + 4, Blocks.redCobble.blockID);
		world.setBlock(i + 3, j + 6, k + 5, Blocks.redCobble.blockID);
		world.setBlock(i + 3, j + 6, k + 6, Blocks.redCobble.blockID);
		world.setBlock(i + 3, j + 6, k + 7, Blocks.redCobble.blockID);
		world.setBlock(i + 3, j + 6, k + 8, Blocks.redCobble.blockID);
		world.setBlock(i + 3, j + 6, k + 9, Blocks.redCobble.blockID);
		world.setBlock(i + 3, j + 6, k + 10, Blocks.redCobble.blockID);
		world.setBlock(i + 3, j + 6, k + 11, Blocks.redCobble.blockID);
		world.setBlock(i + 3, j + 6, k + 12, Blocks.redCobble.blockID);
		world.setBlock(i + 3, j + 6, k + 13, Blocks.redCobble.blockID);
		world.setBlock(i + 3, j + 6, k + 14, Blocks.redCobble.blockID);
		world.setBlock(i + 3, j + 6, k + 15, Blocks.redCobble.blockID);
		world.setBlock(i + 3, j + 6, k + 16, Blocks.redCobble.blockID);
		world.setBlock(i + 3, j + 6, k + 17, Blocks.redCobble.blockID);
		world.setBlock(i + 3, j + 6, k + 18, Blocks.redCobble.blockID);
		world.setBlock(i + 3, j + 6, k + 19, Blocks.redCobble.blockID);
		world.setBlock(i + 3, j + 6, k + 20, Blocks.redCobble.blockID);
		world.setBlock(i + 3, j + 6, k + 21, Blocks.redCobble.blockID);
		world.setBlock(i + 3, j + 6, k + 22, Blocks.redCobble.blockID);
		world.setBlock(i + 3, j + 6, k + 23, Blocks.redCobble.blockID);
		world.setBlock(i + 3, j + 6, k + 24, Blocks.redCobble.blockID);
		world.setBlock(i + 3, j + 6, k + 25, Blocks.redCobble.blockID);
		world.setBlock(i + 3, j + 6, k + 26, Blocks.redCobble.blockID);
		world.setBlock(i + 3, j + 6, k + 27, Blocks.redCobble.blockID);
		world.setBlock(i + 3, j + 6, k + 28, Blocks.redCobble.blockID);
		world.setBlock(i + 3, j + 6, k + 29, Blocks.redCobble.blockID);
		world.setBlock(i + 3, j + 6, k + 30, Blocks.redCobble.blockID);
		world.setBlock(i + 3, j + 6, k + 31, Blocks.redCobble.blockID);
		world.setBlock(i + 3, j + 6, k + 32, Blocks.redCobble.blockID);
		world.setBlock(i + 3, j + 6, k + 33, Blocks.redCobble.blockID);
		world.setBlock(i + 3, j + 6, k + 34, Blocks.redCobble.blockID);
		world.setBlock(i + 3, j + 6, k + 35, Blocks.redCobble.blockID);
		world.setBlock(i + 3, j + 6, k + 36, Blocks.redCobble.blockID);
		world.setBlock(i + 3, j + 6, k + 37, Blocks.redCobble.blockID);
		world.setBlock(i + 3, j + 6, k + 38, Blocks.redCobble.blockID);
		world.setBlock(i + 3, j + 6, k + 39, Blocks.redCobble.blockID);
		world.setBlock(i + 3, j + 6, k + 40, Blocks.redCobble.blockID);
		world.setBlock(i + 4, j + 0, k + 0, Blocks.redCobble.blockID);
		world.setBlock(i + 4, j + 0, k + 1, Blocks.redCobble.blockID);
		world.setBlock(i + 4, j + 0, k + 2, Blocks.redCobble.blockID);
		world.setBlock(i + 4, j + 0, k + 3, Blocks.redCobble.blockID);
		world.setBlock(i + 4, j + 0, k + 4, Blocks.redCobble.blockID);
		world.setBlock(i + 4, j + 0, k + 5, Blocks.redCobble.blockID);
		world.setBlock(i + 4, j + 0, k + 6, Blocks.redCobble.blockID);
		world.setBlock(i + 4, j + 0, k + 7, Blocks.redCobble.blockID);
		world.setBlock(i + 4, j + 0, k + 8, Blocks.redCobble.blockID);
		world.setBlock(i + 4, j + 0, k + 9, Blocks.redCobble.blockID);
		world.setBlock(i + 4, j + 0, k + 10, Blocks.redCobble.blockID);
		world.setBlock(i + 4, j + 0, k + 11, Blocks.redCobble.blockID);
		world.setBlock(i + 4, j + 0, k + 12, Blocks.redCobble.blockID);
		world.setBlock(i + 4, j + 0, k + 13, Blocks.redCobble.blockID);
		world.setBlock(i + 4, j + 0, k + 14, Blocks.redCobble.blockID);
		world.setBlock(i + 4, j + 0, k + 15, Blocks.shineStone.blockID);
		world.setBlock(i + 4, j + 0, k + 16, Blocks.redCobble.blockID);
		world.setBlock(i + 4, j + 0, k + 17, Blocks.redCobble.blockID);
		world.setBlock(i + 4, j + 0, k + 18, Blocks.redCobble.blockID);
		world.setBlock(i + 4, j + 0, k + 19, Blocks.redCobble.blockID);
		world.setBlock(i + 4, j + 0, k + 20, Blocks.redCobble.blockID);
		world.setBlock(i + 4, j + 0, k + 21, Blocks.redCobble.blockID);
		world.setBlock(i + 4, j + 0, k + 22, Blocks.redCobble.blockID);
		world.setBlock(i + 4, j + 0, k + 23, Blocks.redCobble.blockID);
		world.setBlock(i + 4, j + 0, k + 24, Blocks.redCobble.blockID);
		world.setBlock(i + 4, j + 0, k + 25, Blocks.redCobble.blockID);
		world.setBlock(i + 4, j + 0, k + 26, Blocks.redCobble.blockID);
		world.setBlock(i + 4, j + 0, k + 27, Blocks.redCobble.blockID);
		world.setBlock(i + 4, j + 0, k + 28, Blocks.redCobble.blockID);
		world.setBlock(i + 4, j + 0, k + 29, Blocks.redCobble.blockID);
		world.setBlock(i + 4, j + 0, k + 30, Blocks.redCobble.blockID);
		world.setBlock(i + 4, j + 0, k + 31, Blocks.redCobble.blockID);
		world.setBlock(i + 4, j + 0, k + 32, Blocks.redCobble.blockID);
		world.setBlock(i + 4, j + 0, k + 33, Blocks.redCobble.blockID);
		world.setBlock(i + 4, j + 0, k + 34, Blocks.redCobble.blockID);
		world.setBlock(i + 4, j + 0, k + 35, Blocks.redCobble.blockID);
		world.setBlock(i + 4, j + 0, k + 36, Blocks.redCobble.blockID);
		world.setBlock(i + 4, j + 0, k + 37, Blocks.redCobble.blockID);
		world.setBlock(i + 4, j + 0, k + 38, Blocks.redCobble.blockID);
		world.setBlock(i + 4, j + 0, k + 39, Blocks.shineStone.blockID);
		world.setBlock(i + 4, j + 0, k + 40, Blocks.redCobble.blockID);
		world.setBlock(i + 4, j + 1, k + 0, Blocks.redCobble.blockID);
		int randInt4 = (new Random()).nextInt(8);
		if (randInt4 == 8) {
			int chestX = i + 4;
			int chestY = j + 1;
			int chestZ = k + 1;
			int chestRand = (int) (Math.random() * Math.floor(2));
			boolean isBigChest = (chestRand == 1) ? true : false;
			String chestString = chestX + " " + chestY + " " + chestZ;
			Treasures.spawnChest(world, rand, chestX, chestY, chestZ,
					isBigChest,
					Treasures.pickChestType());
		}
		world.setBlock(i + 4, j + 1, k + 6, Blocks.redCobble.blockID);
		world.setBlock(i + 4, j + 1, k + 7, Block.bed.blockID);
		world.setBlock(i + 4, j + 1, k + 8, Block.bed.blockID);
		int randInt5 = (new Random()).nextInt(8);
		if (randInt5 == 1) {
			int chestX = i + 4;
			int chestY = j + 1;
			int chestZ = k + 11;
			int chestRand = (int) (Math.random() * Math.floor(2));
			boolean isBigChest = (chestRand == 1) ? true : false;
			String chestString = chestX + " " + chestY + " " + chestZ;
			Treasures.spawnChest(world, rand, chestX, chestY, chestZ,
					isBigChest,
					Treasures.pickChestType());
		}
		world.setBlock(i + 4, j + 1, k + 12, Blocks.redCobble.blockID);
		world.setBlock(i + 4, j + 1, k + 13, Block.bed.blockID);
		world.setBlock(i + 4, j + 1, k + 14, Block.bed.blockID);
		world.setBlock(i + 4, j + 1, k + 19, Blocks.redCobble.blockID);
		world.setBlock(i + 4, j + 1, k + 20, Block.bed.blockID);
		world.setBlock(i + 4, j + 1, k + 21, Block.bed.blockID);
		int randInt6 = (new Random()).nextInt(8);
		if (randInt6 == 2) {
			int chestX = i + 4;
			int chestY = j + 1;
			int chestZ = k + 25;
			int chestRand = (int) (Math.random() * Math.floor(2));
			boolean isBigChest = (chestRand == 1) ? true : false;
			String chestString = chestX + " " + chestY + " " + chestZ;
			Treasures.spawnChest(world, rand, chestX, chestY, chestZ,
					isBigChest,
					Treasures.pickChestType());
		}
		world.setBlock(i + 4, j + 1, k + 26, Blocks.redCobble.blockID);
		world.setBlock(i + 4, j + 1, k + 27, Block.bed.blockID);
		world.setBlock(i + 4, j + 1, k + 28, Block.bed.blockID);
		world.setBlock(i + 4, j + 1, k + 33, Blocks.redCobble.blockID);
		world.setBlock(i + 4, j + 1, k + 34, Block.bed.blockID);
		world.setBlock(i + 4, j + 1, k + 35, Block.bed.blockID);
		world.setBlock(i + 4, j + 1, k + 40, Blocks.redCobble.blockID);
		world.setBlock(i + 4, j + 2, k + 0, Blocks.redCobble.blockID);
		world.setBlock(i + 4, j + 2, k + 2, -112);
		world.setBlock(i + 4, j + 2, k + 6, Blocks.betterGlass.blockID);
		world.setBlock(i + 4, j + 2, k + 12, Blocks.redCobble.blockID);
		world.setBlock(i + 4, j + 2, k + 19, Blocks.redCobble.blockID);
		world.setBlock(i + 4, j + 2, k + 23, -112);
		world.setBlock(i + 4, j + 2, k + 26, Blocks.redCobble.blockID);
		world.setBlock(i + 4, j + 2, k + 32, -112);
		world.setBlock(i + 4, j + 2, k + 33, Blocks.betterGlass.blockID);
		world.setBlock(i + 4, j + 2, k + 38, -112);
		world.setBlock(i + 4, j + 2, k + 40, Blocks.redCobble.blockID);
		world.setBlock(i + 4, j + 3, k + 0, Blocks.redCobble.blockID);
		world.setBlock(i + 4, j + 3, k + 6, Blocks.redCobble.blockID);
		world.setBlock(i + 4, j + 3, k + 12, Blocks.redCobble.blockID);
		world.setBlock(i + 4, j + 3, k + 19, Blocks.redCobble.blockID);
		world.setBlock(i + 4, j + 3, k + 26, Blocks.redCobble.blockID);
		world.setBlock(i + 4, j + 3, k + 33, Blocks.redCobble.blockID);
		world.setBlock(i + 4, j + 3, k + 40, Blocks.redCobble.blockID);
		world.setBlock(i + 4, j + 4, k + 0, Blocks.redCobble.blockID);
		world.setBlock(i + 4, j + 4, k + 6, Blocks.redCobble.blockID);
		world.setBlock(i + 4, j + 4, k + 12, Blocks.redCobble.blockID);
		world.setBlock(i + 4, j + 4, k + 19, Blocks.redCobble.blockID);
		world.setBlock(i + 4, j + 4, k + 26, Blocks.redCobble.blockID);
		world.setBlock(i + 4, j + 4, k + 33, Blocks.redCobble.blockID);
		world.setBlock(i + 4, j + 4, k + 40, Blocks.redCobble.blockID);
		world.setBlock(i + 4, j + 5, k + 0, Blocks.redCobble.blockID);
		world.setBlock(i + 4, j + 5, k + 6, Blocks.redCobble.blockID);
		world.setBlock(i + 4, j + 5, k + 12, Blocks.redCobble.blockID);
		world.setBlock(i + 4, j + 5, k + 19, Blocks.redCobble.blockID);
		world.setBlock(i + 4, j + 5, k + 26, Blocks.redCobble.blockID);
		world.setBlock(i + 4, j + 5, k + 33, Blocks.redCobble.blockID);
		world.setBlock(i + 4, j + 5, k + 40, Blocks.redCobble.blockID);
		world.setBlock(i + 4, j + 6, k + 0, Blocks.redCobble.blockID);
		world.setBlock(i + 4, j + 6, k + 1, Blocks.redCobble.blockID);
		world.setBlock(i + 4, j + 6, k + 2, Blocks.redCobble.blockID);
		world.setBlock(i + 4, j + 6, k + 3, Blocks.redCobble.blockID);
		world.setBlock(i + 4, j + 6, k + 4, Blocks.redCobble.blockID);
		world.setBlock(i + 4, j + 6, k + 5, Blocks.redCobble.blockID);
		world.setBlock(i + 4, j + 6, k + 6, Blocks.redCobble.blockID);
		world.setBlock(i + 4, j + 6, k + 7, Blocks.redCobble.blockID);
		world.setBlock(i + 4, j + 6, k + 8, Blocks.redCobble.blockID);
		world.setBlock(i + 4, j + 6, k + 9, Blocks.redCobble.blockID);
		world.setBlock(i + 4, j + 6, k + 10, Blocks.redCobble.blockID);
		world.setBlock(i + 4, j + 6, k + 11, Blocks.redCobble.blockID);
		world.setBlock(i + 4, j + 6, k + 12, Blocks.redCobble.blockID);
		world.setBlock(i + 4, j + 6, k + 13, Blocks.redCobble.blockID);
		world.setBlock(i + 4, j + 6, k + 14, Blocks.redCobble.blockID);
		world.setBlock(i + 4, j + 6, k + 15, Blocks.redCobble.blockID);
		world.setBlock(i + 4, j + 6, k + 16, Blocks.redCobble.blockID);
		world.setBlock(i + 4, j + 6, k + 17, Blocks.redCobble.blockID);
		world.setBlock(i + 4, j + 6, k + 18, Blocks.redCobble.blockID);
		world.setBlock(i + 4, j + 6, k + 19, Blocks.redCobble.blockID);
		world.setBlock(i + 4, j + 6, k + 20, Blocks.redCobble.blockID);
		world.setBlock(i + 4, j + 6, k + 21, Blocks.redCobble.blockID);
		world.setBlock(i + 4, j + 6, k + 22, Blocks.redCobble.blockID);
		world.setBlock(i + 4, j + 6, k + 23, Blocks.redCobble.blockID);
		world.setBlock(i + 4, j + 6, k + 24, Blocks.redCobble.blockID);
		world.setBlock(i + 4, j + 6, k + 25, Blocks.redCobble.blockID);
		world.setBlock(i + 4, j + 6, k + 26, Blocks.redCobble.blockID);
		world.setBlock(i + 4, j + 6, k + 27, Blocks.redCobble.blockID);
		world.setBlock(i + 4, j + 6, k + 28, Blocks.redCobble.blockID);
		world.setBlock(i + 4, j + 6, k + 29, Blocks.redCobble.blockID);
		world.setBlock(i + 4, j + 6, k + 30, Blocks.redCobble.blockID);
		world.setBlock(i + 4, j + 6, k + 31, Blocks.redCobble.blockID);
		world.setBlock(i + 4, j + 6, k + 32, Blocks.redCobble.blockID);
		world.setBlock(i + 4, j + 6, k + 33, Blocks.redCobble.blockID);
		world.setBlock(i + 4, j + 6, k + 34, Blocks.redCobble.blockID);
		world.setBlock(i + 4, j + 6, k + 35, Blocks.redCobble.blockID);
		world.setBlock(i + 4, j + 6, k + 36, Blocks.redCobble.blockID);
		world.setBlock(i + 4, j + 6, k + 37, Blocks.redCobble.blockID);
		world.setBlock(i + 4, j + 6, k + 38, Blocks.redCobble.blockID);
		world.setBlock(i + 4, j + 6, k + 39, Blocks.redCobble.blockID);
		world.setBlock(i + 4, j + 6, k + 40, Blocks.redCobble.blockID);
		world.setBlock(i + 5, j + 0, k + 0, Blocks.redCobble.blockID);
		world.setBlock(i + 5, j + 0, k + 1, Blocks.redCobble.blockID);
		world.setBlock(i + 5, j + 0, k + 2, Blocks.redCobble.blockID);
		world.setBlock(i + 5, j + 0, k + 3, Blocks.redCobble.blockID);
		world.setBlock(i + 5, j + 0, k + 4, Blocks.redCobble.blockID);
		world.setBlock(i + 5, j + 0, k + 5, Blocks.redCobble.blockID);
		world.setBlock(i + 5, j + 0, k + 6, Blocks.redCobble.blockID);
		world.setBlock(i + 5, j + 0, k + 7, Blocks.redCobble.blockID);
		world.setBlock(i + 5, j + 0, k + 8, Blocks.redCobble.blockID);
		world.setBlock(i + 5, j + 0, k + 9, Blocks.redCobble.blockID);
		world.setBlock(i + 5, j + 0, k + 10, Blocks.redCobble.blockID);
		world.setBlock(i + 5, j + 0, k + 11, Blocks.redCobble.blockID);
		world.setBlock(i + 5, j + 0, k + 12, Blocks.redCobble.blockID);
		world.setBlock(i + 5, j + 0, k + 13, Blocks.redCobble.blockID);
		world.setBlock(i + 5, j + 0, k + 14, Blocks.redCobble.blockID);
		world.setBlock(i + 5, j + 0, k + 15, Blocks.redCobble.blockID);
		world.setBlock(i + 5, j + 0, k + 16, Blocks.redCobble.blockID);
		world.setBlock(i + 5, j + 0, k + 17, Blocks.redCobble.blockID);
		world.setBlock(i + 5, j + 0, k + 18, Blocks.redCobble.blockID);
		world.setBlock(i + 5, j + 0, k + 19, Blocks.redCobble.blockID);
		world.setBlock(i + 5, j + 0, k + 20, Blocks.redCobble.blockID);
		world.setBlock(i + 5, j + 0, k + 21, Blocks.redCobble.blockID);
		world.setBlock(i + 5, j + 0, k + 22, Blocks.redCobble.blockID);
		world.setBlock(i + 5, j + 0, k + 23, Blocks.redCobble.blockID);
		world.setBlock(i + 5, j + 0, k + 24, Blocks.redCobble.blockID);
		world.setBlock(i + 5, j + 0, k + 25, Blocks.redCobble.blockID);
		world.setBlock(i + 5, j + 0, k + 26, Blocks.redCobble.blockID);
		world.setBlock(i + 5, j + 0, k + 27, Blocks.redCobble.blockID);
		world.setBlock(i + 5, j + 0, k + 28, Blocks.redCobble.blockID);
		world.setBlock(i + 5, j + 0, k + 29, Blocks.redCobble.blockID);
		world.setBlock(i + 5, j + 0, k + 30, Blocks.redCobble.blockID);
		world.setBlock(i + 5, j + 0, k + 31, Blocks.redCobble.blockID);
		world.setBlock(i + 5, j + 0, k + 32, Blocks.redCobble.blockID);
		world.setBlock(i + 5, j + 0, k + 33, Blocks.redCobble.blockID);
		world.setBlock(i + 5, j + 0, k + 34, Blocks.redCobble.blockID);
		world.setBlock(i + 5, j + 0, k + 35, Blocks.redCobble.blockID);
		world.setBlock(i + 5, j + 0, k + 36, Blocks.redCobble.blockID);
		world.setBlock(i + 5, j + 0, k + 37, Blocks.redCobble.blockID);
		world.setBlock(i + 5, j + 0, k + 38, Blocks.redCobble.blockID);
		world.setBlock(i + 5, j + 0, k + 39, Blocks.redCobble.blockID);
		world.setBlock(i + 5, j + 0, k + 40, Blocks.redCobble.blockID);
		world.setBlock(i + 5, j + 1, k + 0, Blocks.redCobble.blockID);
		world.setBlock(i + 5, j + 1, k + 1, Blocks.redCobble.blockID);
		world.setBlock(i + 5, j + 1, k + 2, Blocks.redCobble.blockID);
		world.setBlock(i + 5, j + 1, k + 4, Blocks.redCobble.blockID);
		world.setBlock(i + 5, j + 1, k + 5, Blocks.redCobble.blockID);
		world.setBlock(i + 5, j + 1, k + 6, Blocks.redCobble.blockID);
		world.setBlock(i + 5, j + 1, k + 7, Blocks.redCobble.blockID);
		world.setBlock(i + 5, j + 1, k + 8, Blocks.redCobble.blockID);
		world.setBlock(i + 5, j + 1, k + 10, Blocks.redCobble.blockID);
		world.setBlock(i + 5, j + 1, k + 11, Blocks.redCobble.blockID);
		world.setBlock(i + 5, j + 1, k + 12, Blocks.redCobble.blockID);
		world.setBlock(i + 5, j + 1, k + 13, Blocks.redCobble.blockID);
		world.setBlock(i + 5, j + 1, k + 14, Blocks.redCobble.blockID);
		world.setBlock(i + 5, j + 1, k + 15, Blocks.redCobble.blockID);
		world.setBlock(i + 5, j + 1, k + 16, Blocks.redCobble.blockID);
		world.setBlock(i + 5, j + 1, k + 18, Blocks.redCobble.blockID);
		world.setBlock(i + 5, j + 1, k + 19, Blocks.redCobble.blockID);
		world.setBlock(i + 5, j + 1, k + 20, Blocks.redCobble.blockID);
		world.setBlock(i + 5, j + 1, k + 21, Blocks.redCobble.blockID);
		world.setBlock(i + 5, j + 1, k + 23, Blocks.redCobble.blockID);
		world.setBlock(i + 5, j + 1, k + 24, Blocks.redCobble.blockID);
		world.setBlock(i + 5, j + 1, k + 25, Blocks.redCobble.blockID);
		world.setBlock(i + 5, j + 1, k + 26, Blocks.redCobble.blockID);
		world.setBlock(i + 5, j + 1, k + 27, Blocks.redCobble.blockID);
		world.setBlock(i + 5, j + 1, k + 28, Blocks.redCobble.blockID);
		world.setBlock(i + 5, j + 1, k + 30, Blocks.redCobble.blockID);
		world.setBlock(i + 5, j + 1, k + 31, Blocks.redCobble.blockID);
		world.setBlock(i + 5, j + 1, k + 32, Blocks.redCobble.blockID);
		world.setBlock(i + 5, j + 1, k + 33, Blocks.redCobble.blockID);
		world.setBlock(i + 5, j + 1, k + 34, Blocks.redCobble.blockID);
		world.setBlock(i + 5, j + 1, k + 35, Blocks.redCobble.blockID);
		world.setBlock(i + 5, j + 1, k + 36, Blocks.redCobble.blockID);
		world.setBlock(i + 5, j + 1, k + 38, Blocks.redCobble.blockID);
		world.setBlock(i + 5, j + 1, k + 39, Blocks.redCobble.blockID);
		world.setBlock(i + 5, j + 1, k + 40, Blocks.redCobble.blockID);
		world.setBlock(i + 5, j + 2, k + 0, Blocks.redCobble.blockID);
		world.setBlock(i + 5, j + 2, k + 1, Blocks.betterGlass.blockID);
		world.setBlock(i + 5, j + 2, k + 2, Blocks.redCobble.blockID);
		world.setBlock(i + 5, j + 2, k + 4, Blocks.redCobble.blockID);
		world.setBlock(i + 5, j + 2, k + 5, Blocks.redCobble.blockID);
		world.setBlock(i + 5, j + 2, k + 6, Blocks.redCobble.blockID);
		world.setBlock(i + 5, j + 2, k + 7, Blocks.redCobble.blockID);
		world.setBlock(i + 5, j + 2, k + 8, Blocks.redCobble.blockID);
		world.setBlock(i + 5, j + 2, k + 10, Blocks.redCobble.blockID);
		world.setBlock(i + 5, j + 2, k + 11, Blocks.redCobble.blockID);
		world.setBlock(i + 5, j + 2, k + 12, Blocks.redCobble.blockID);
		world.setBlock(i + 5, j + 2, k + 13, Blocks.redCobble.blockID);
		world.setBlock(i + 5, j + 2, k + 14, Blocks.redCobble.blockID);
		world.setBlock(i + 5, j + 2, k + 15, Blocks.betterGlass.blockID);
		world.setBlock(i + 5, j + 2, k + 16, Blocks.redCobble.blockID);
		world.setBlock(i + 5, j + 2, k + 18, Blocks.redCobble.blockID);
		world.setBlock(i + 5, j + 2, k + 19, Blocks.redCobble.blockID);
		world.setBlock(i + 5, j + 2, k + 20, Blocks.betterGlass.blockID);
		world.setBlock(i + 5, j + 2, k + 21, Blocks.redCobble.blockID);
		world.setBlock(i + 5, j + 2, k + 23, Blocks.redCobble.blockID);
		world.setBlock(i + 5, j + 2, k + 24, Blocks.betterGlass.blockID);
		world.setBlock(i + 5, j + 2, k + 25, Blocks.redCobble.blockID);
		world.setBlock(i + 5, j + 2, k + 26, Blocks.redCobble.blockID);
		world.setBlock(i + 5, j + 2, k + 27, Blocks.redCobble.blockID);
		world.setBlock(i + 5, j + 2, k + 28, Blocks.redCobble.blockID);
		world.setBlock(i + 5, j + 2, k + 30, Blocks.redCobble.blockID);
		world.setBlock(i + 5, j + 2, k + 31, Blocks.betterGlass.blockID);
		world.setBlock(i + 5, j + 2, k + 32, Blocks.redCobble.blockID);
		world.setBlock(i + 5, j + 2, k + 33, Blocks.redCobble.blockID);
		world.setBlock(i + 5, j + 2, k + 34, Blocks.redCobble.blockID);
		world.setBlock(i + 5, j + 2, k + 35, Blocks.betterGlass.blockID);
		world.setBlock(i + 5, j + 2, k + 36, Blocks.redCobble.blockID);
		world.setBlock(i + 5, j + 2, k + 38, Blocks.redCobble.blockID);
		world.setBlock(i + 5, j + 2, k + 39, Blocks.betterGlass.blockID);
		world.setBlock(i + 5, j + 2, k + 40, Blocks.redCobble.blockID);
		world.setBlock(i + 5, j + 3, k + 0, Blocks.redCobble.blockID);
		world.setBlock(i + 5, j + 3, k + 1, Blocks.redCobble.blockID);
		world.setBlock(i + 5, j + 3, k + 2, Blocks.redCobble.blockID);
		world.setBlock(i + 5, j + 3, k + 3, Blocks.redCobble.blockID);
		world.setBlock(i + 5, j + 3, k + 4, Blocks.redCobble.blockID);
		world.setBlock(i + 5, j + 3, k + 5, Blocks.redCobble.blockID);
		world.setBlock(i + 5, j + 3, k + 6, Blocks.redCobble.blockID);
		world.setBlock(i + 5, j + 3, k + 7, Blocks.redCobble.blockID);
		world.setBlock(i + 5, j + 3, k + 8, Blocks.redCobble.blockID);
		world.setBlock(i + 5, j + 3, k + 9, Blocks.redCobble.blockID);
		world.setBlock(i + 5, j + 3, k + 10, Blocks.redCobble.blockID);
		world.setBlock(i + 5, j + 3, k + 11, Blocks.redCobble.blockID);
		world.setBlock(i + 5, j + 3, k + 12, Blocks.redCobble.blockID);
		world.setBlock(i + 5, j + 3, k + 13, Blocks.redCobble.blockID);
		world.setBlock(i + 5, j + 3, k + 14, Blocks.redCobble.blockID);
		world.setBlock(i + 5, j + 3, k + 15, Blocks.redCobble.blockID);
		world.setBlock(i + 5, j + 3, k + 16, Blocks.redCobble.blockID);
		world.setBlock(i + 5, j + 3, k + 17, Blocks.redCobble.blockID);
		world.setBlock(i + 5, j + 3, k + 18, Blocks.redCobble.blockID);
		world.setBlock(i + 5, j + 3, k + 19, Blocks.redCobble.blockID);
		world.setBlock(i + 5, j + 3, k + 20, Blocks.redCobble.blockID);
		world.setBlock(i + 5, j + 3, k + 21, Blocks.redCobble.blockID);
		world.setBlock(i + 5, j + 3, k + 22, Blocks.redCobble.blockID);
		world.setBlock(i + 5, j + 3, k + 23, Blocks.redCobble.blockID);
		world.setBlock(i + 5, j + 3, k + 24, Blocks.redCobble.blockID);
		world.setBlock(i + 5, j + 3, k + 25, Blocks.redCobble.blockID);
		world.setBlock(i + 5, j + 3, k + 26, Blocks.redCobble.blockID);
		world.setBlock(i + 5, j + 3, k + 27, Blocks.redCobble.blockID);
		world.setBlock(i + 5, j + 3, k + 28, Blocks.redCobble.blockID);
		world.setBlock(i + 5, j + 3, k + 29, Blocks.redCobble.blockID);
		world.setBlock(i + 5, j + 3, k + 30, Blocks.redCobble.blockID);
		world.setBlock(i + 5, j + 3, k + 31, Blocks.redCobble.blockID);
		world.setBlock(i + 5, j + 3, k + 32, Blocks.redCobble.blockID);
		world.setBlock(i + 5, j + 3, k + 33, Blocks.redCobble.blockID);
		world.setBlock(i + 5, j + 3, k + 34, Blocks.redCobble.blockID);
		world.setBlock(i + 5, j + 3, k + 35, Blocks.redCobble.blockID);
		world.setBlock(i + 5, j + 3, k + 36, Blocks.redCobble.blockID);
		world.setBlock(i + 5, j + 3, k + 37, Blocks.redCobble.blockID);
		world.setBlock(i + 5, j + 3, k + 38, Blocks.redCobble.blockID);
		world.setBlock(i + 5, j + 3, k + 39, Blocks.redCobble.blockID);
		world.setBlock(i + 5, j + 3, k + 40, Blocks.redCobble.blockID);
		world.setBlock(i + 5, j + 4, k + 0, Blocks.redCobble.blockID);
		world.setBlock(i + 5, j + 4, k + 1, Blocks.redCobble.blockID);
		world.setBlock(i + 5, j + 4, k + 2, Blocks.redCobble.blockID);
		world.setBlock(i + 5, j + 4, k + 3, Blocks.redCobble.blockID);
		world.setBlock(i + 5, j + 4, k + 4, Blocks.redCobble.blockID);
		world.setBlock(i + 5, j + 4, k + 5, Blocks.redCobble.blockID);
		world.setBlock(i + 5, j + 4, k + 6, Blocks.redCobble.blockID);
		world.setBlock(i + 5, j + 4, k + 7, Blocks.redCobble.blockID);
		world.setBlock(i + 5, j + 4, k + 8, Blocks.redCobble.blockID);
		world.setBlock(i + 5, j + 4, k + 9, Blocks.redCobble.blockID);
		world.setBlock(i + 5, j + 4, k + 10, Blocks.redCobble.blockID);
		world.setBlock(i + 5, j + 4, k + 11, Blocks.redCobble.blockID);
		world.setBlock(i + 5, j + 4, k + 12, Blocks.redCobble.blockID);
		world.setBlock(i + 5, j + 4, k + 13, Blocks.redCobble.blockID);
		world.setBlock(i + 5, j + 4, k + 14, Blocks.redCobble.blockID);
		world.setBlock(i + 5, j + 4, k + 15, Blocks.redCobble.blockID);
		world.setBlock(i + 5, j + 4, k + 16, Blocks.redCobble.blockID);
		world.setBlock(i + 5, j + 4, k + 17, Blocks.redCobble.blockID);
		world.setBlock(i + 5, j + 4, k + 18, Blocks.redCobble.blockID);
		world.setBlock(i + 5, j + 4, k + 19, Blocks.redCobble.blockID);
		world.setBlock(i + 5, j + 4, k + 20, Blocks.redCobble.blockID);
		world.setBlock(i + 5, j + 4, k + 21, Blocks.redCobble.blockID);
		world.setBlock(i + 5, j + 4, k + 22, Blocks.redCobble.blockID);
		world.setBlock(i + 5, j + 4, k + 23, Blocks.redCobble.blockID);
		world.setBlock(i + 5, j + 4, k + 24, Blocks.redCobble.blockID);
		world.setBlock(i + 5, j + 4, k + 25, Blocks.redCobble.blockID);
		world.setBlock(i + 5, j + 4, k + 26, Blocks.redCobble.blockID);
		world.setBlock(i + 5, j + 4, k + 27, Blocks.redCobble.blockID);
		world.setBlock(i + 5, j + 4, k + 28, Blocks.redCobble.blockID);
		world.setBlock(i + 5, j + 4, k + 29, Blocks.redCobble.blockID);
		world.setBlock(i + 5, j + 4, k + 30, Blocks.redCobble.blockID);
		world.setBlock(i + 5, j + 4, k + 31, Blocks.redCobble.blockID);
		world.setBlock(i + 5, j + 4, k + 32, Blocks.redCobble.blockID);
		world.setBlock(i + 5, j + 4, k + 33, Blocks.redCobble.blockID);
		world.setBlock(i + 5, j + 4, k + 34, Blocks.redCobble.blockID);
		world.setBlock(i + 5, j + 4, k + 35, Blocks.redCobble.blockID);
		world.setBlock(i + 5, j + 4, k + 36, Blocks.redCobble.blockID);
		world.setBlock(i + 5, j + 4, k + 37, Blocks.redCobble.blockID);
		world.setBlock(i + 5, j + 4, k + 38, Blocks.redCobble.blockID);
		world.setBlock(i + 5, j + 4, k + 39, Blocks.redCobble.blockID);
		world.setBlock(i + 5, j + 4, k + 40, Blocks.redCobble.blockID);
		world.setBlock(i + 5, j + 5, k + 0, Blocks.redCobble.blockID);
		world.setBlock(i + 5, j + 5, k + 1, Blocks.redCobble.blockID);
		world.setBlock(i + 5, j + 5, k + 2, Blocks.redCobble.blockID);
		world.setBlock(i + 5, j + 5, k + 3, Blocks.redCobble.blockID);
		world.setBlock(i + 5, j + 5, k + 4, Blocks.redCobble.blockID);
		world.setBlock(i + 5, j + 5, k + 5, Blocks.redCobble.blockID);
		world.setBlock(i + 5, j + 5, k + 6, Blocks.redCobble.blockID);
		world.setBlock(i + 5, j + 5, k + 7, Blocks.redCobble.blockID);
		world.setBlock(i + 5, j + 5, k + 8, Blocks.redCobble.blockID);
		world.setBlock(i + 5, j + 5, k + 9, Blocks.redCobble.blockID);
		world.setBlock(i + 5, j + 5, k + 10, Blocks.redCobble.blockID);
		world.setBlock(i + 5, j + 5, k + 11, Blocks.redCobble.blockID);
		world.setBlock(i + 5, j + 5, k + 12, Blocks.redCobble.blockID);
		world.setBlock(i + 5, j + 5, k + 13, Blocks.redCobble.blockID);
		world.setBlock(i + 5, j + 5, k + 14, Blocks.redCobble.blockID);
		world.setBlock(i + 5, j + 5, k + 15, Blocks.redCobble.blockID);
		world.setBlock(i + 5, j + 5, k + 16, Blocks.redCobble.blockID);
		world.setBlock(i + 5, j + 5, k + 17, Blocks.redCobble.blockID);
		world.setBlock(i + 5, j + 5, k + 18, Blocks.redCobble.blockID);
		world.setBlock(i + 5, j + 5, k + 19, Blocks.redCobble.blockID);
		world.setBlock(i + 5, j + 5, k + 20, Blocks.redCobble.blockID);
		world.setBlock(i + 5, j + 5, k + 21, Blocks.redCobble.blockID);
		world.setBlock(i + 5, j + 5, k + 22, Blocks.redCobble.blockID);
		world.setBlock(i + 5, j + 5, k + 23, Blocks.redCobble.blockID);
		world.setBlock(i + 5, j + 5, k + 24, Blocks.redCobble.blockID);
		world.setBlock(i + 5, j + 5, k + 25, Blocks.redCobble.blockID);
		world.setBlock(i + 5, j + 5, k + 26, Blocks.redCobble.blockID);
		world.setBlock(i + 5, j + 5, k + 27, Blocks.redCobble.blockID);
		world.setBlock(i + 5, j + 5, k + 28, Blocks.redCobble.blockID);
		world.setBlock(i + 5, j + 5, k + 29, Blocks.redCobble.blockID);
		world.setBlock(i + 5, j + 5, k + 30, Blocks.redCobble.blockID);
		world.setBlock(i + 5, j + 5, k + 31, Blocks.redCobble.blockID);
		world.setBlock(i + 5, j + 5, k + 32, Blocks.redCobble.blockID);
		world.setBlock(i + 5, j + 5, k + 33, Blocks.redCobble.blockID);
		world.setBlock(i + 5, j + 5, k + 34, Blocks.redCobble.blockID);
		world.setBlock(i + 5, j + 5, k + 35, Blocks.redCobble.blockID);
		world.setBlock(i + 5, j + 5, k + 36, Blocks.redCobble.blockID);
		world.setBlock(i + 5, j + 5, k + 37, Blocks.redCobble.blockID);
		world.setBlock(i + 5, j + 5, k + 38, Blocks.redCobble.blockID);
		world.setBlock(i + 5, j + 5, k + 39, Blocks.redCobble.blockID);
		world.setBlock(i + 5, j + 5, k + 40, Blocks.redCobble.blockID);
		world.setBlock(i + 5, j + 6, k + 0, Blocks.redCobble.blockID);
		world.setBlock(i + 5, j + 6, k + 1, Blocks.redCobble.blockID);
		world.setBlock(i + 5, j + 6, k + 2, Blocks.redCobble.blockID);
		world.setBlock(i + 5, j + 6, k + 3, Blocks.redCobble.blockID);
		world.setBlock(i + 5, j + 6, k + 4, Blocks.redCobble.blockID);
		world.setBlock(i + 5, j + 6, k + 5, Blocks.redCobble.blockID);
		world.setBlock(i + 5, j + 6, k + 6, Blocks.redCobble.blockID);
		world.setBlock(i + 5, j + 6, k + 7, Blocks.redCobble.blockID);
		world.setBlock(i + 5, j + 6, k + 8, Blocks.redCobble.blockID);
		world.setBlock(i + 5, j + 6, k + 9, Blocks.redCobble.blockID);
		world.setBlock(i + 5, j + 6, k + 10, Blocks.redCobble.blockID);
		world.setBlock(i + 5, j + 6, k + 11, Blocks.redCobble.blockID);
		world.setBlock(i + 5, j + 6, k + 12, Blocks.redCobble.blockID);
		world.setBlock(i + 5, j + 6, k + 13, Blocks.redCobble.blockID);
		world.setBlock(i + 5, j + 6, k + 14, Blocks.redCobble.blockID);
		world.setBlock(i + 5, j + 6, k + 15, Blocks.redCobble.blockID);
		world.setBlock(i + 5, j + 6, k + 16, Blocks.redCobble.blockID);
		world.setBlock(i + 5, j + 6, k + 17, Blocks.redCobble.blockID);
		world.setBlock(i + 5, j + 6, k + 18, Blocks.redCobble.blockID);
		world.setBlock(i + 5, j + 6, k + 19, Blocks.redCobble.blockID);
		world.setBlock(i + 5, j + 6, k + 20, Blocks.redCobble.blockID);
		world.setBlock(i + 5, j + 6, k + 21, Blocks.redCobble.blockID);
		world.setBlock(i + 5, j + 6, k + 22, Blocks.redCobble.blockID);
		world.setBlock(i + 5, j + 6, k + 23, Blocks.redCobble.blockID);
		world.setBlock(i + 5, j + 6, k + 24, Blocks.redCobble.blockID);
		world.setBlock(i + 5, j + 6, k + 25, Blocks.redCobble.blockID);
		world.setBlock(i + 5, j + 6, k + 26, Blocks.redCobble.blockID);
		world.setBlock(i + 5, j + 6, k + 27, Blocks.redCobble.blockID);
		world.setBlock(i + 5, j + 6, k + 28, Blocks.redCobble.blockID);
		world.setBlock(i + 5, j + 6, k + 29, Blocks.redCobble.blockID);
		world.setBlock(i + 5, j + 6, k + 30, Blocks.redCobble.blockID);
		world.setBlock(i + 5, j + 6, k + 31, Blocks.redCobble.blockID);
		world.setBlock(i + 5, j + 6, k + 32, Blocks.redCobble.blockID);
		world.setBlock(i + 5, j + 6, k + 33, Blocks.redCobble.blockID);
		world.setBlock(i + 5, j + 6, k + 34, Blocks.redCobble.blockID);
		world.setBlock(i + 5, j + 6, k + 35, Blocks.redCobble.blockID);
		world.setBlock(i + 5, j + 6, k + 36, Blocks.redCobble.blockID);
		world.setBlock(i + 5, j + 6, k + 37, Blocks.redCobble.blockID);
		world.setBlock(i + 5, j + 6, k + 38, Blocks.redCobble.blockID);
		world.setBlock(i + 5, j + 6, k + 39, Blocks.redCobble.blockID);
		world.setBlock(i + 5, j + 6, k + 40, Blocks.redCobble.blockID);
		world.setBlock(i + 6, j + 0, k + 0, Blocks.redCobble.blockID);
		world.setBlock(i + 6, j + 0, k + 1, Blocks.redCobble.blockID);
		world.setBlock(i + 6, j + 0, k + 2, Blocks.redCobble.blockID);
		world.setBlock(i + 6, j + 0, k + 3, Blocks.redCobble.blockID);
		world.setBlock(i + 6, j + 0, k + 4, Blocks.redCobble.blockID);
		world.setBlock(i + 6, j + 0, k + 5, Blocks.redCobble.blockID);
		world.setBlock(i + 6, j + 0, k + 6, Blocks.redCobble.blockID);
		world.setBlock(i + 6, j + 0, k + 7, Blocks.redCobble.blockID);
		world.setBlock(i + 6, j + 0, k + 8, Blocks.redCobble.blockID);
		world.setBlock(i + 6, j + 0, k + 9, Blocks.redCobble.blockID);
		world.setBlock(i + 6, j + 0, k + 10, Blocks.redCobble.blockID);
		world.setBlock(i + 6, j + 0, k + 11, Blocks.redCobble.blockID);
		world.setBlock(i + 6, j + 0, k + 12, Blocks.redCobble.blockID);
		world.setBlock(i + 6, j + 0, k + 13, Blocks.redCobble.blockID);
		world.setBlock(i + 6, j + 0, k + 14, Blocks.redCobble.blockID);
		world.setBlock(i + 6, j + 0, k + 15, Blocks.redCobble.blockID);
		world.setBlock(i + 6, j + 0, k + 16, Blocks.redCobble.blockID);
		world.setBlock(i + 6, j + 0, k + 17, Blocks.redCobble.blockID);
		world.setBlock(i + 6, j + 0, k + 18, Blocks.redCobble.blockID);
		world.setBlock(i + 6, j + 0, k + 19, Blocks.redCobble.blockID);
		world.setBlock(i + 6, j + 0, k + 20, Blocks.redCobble.blockID);
		world.setBlock(i + 6, j + 0, k + 21, Blocks.redCobble.blockID);
		world.setBlock(i + 6, j + 0, k + 22, Blocks.redCobble.blockID);
		world.setBlock(i + 6, j + 0, k + 23, Blocks.redCobble.blockID);
		world.setBlock(i + 6, j + 0, k + 24, Blocks.redCobble.blockID);
		world.setBlock(i + 6, j + 0, k + 25, Blocks.redCobble.blockID);
		world.setBlock(i + 6, j + 0, k + 26, Blocks.redCobble.blockID);
		world.setBlock(i + 6, j + 0, k + 27, Blocks.redCobble.blockID);
		world.setBlock(i + 6, j + 0, k + 28, Blocks.redCobble.blockID);
		world.setBlock(i + 6, j + 0, k + 29, Blocks.redCobble.blockID);
		world.setBlock(i + 6, j + 0, k + 30, Blocks.redCobble.blockID);
		world.setBlock(i + 6, j + 0, k + 31, Blocks.redCobble.blockID);
		world.setBlock(i + 6, j + 0, k + 32, Blocks.redCobble.blockID);
		world.setBlock(i + 6, j + 0, k + 33, Blocks.redCobble.blockID);
		world.setBlock(i + 6, j + 0, k + 34, Blocks.redCobble.blockID);
		world.setBlock(i + 6, j + 0, k + 35, Blocks.redCobble.blockID);
		world.setBlock(i + 6, j + 0, k + 36, Blocks.redCobble.blockID);
		world.setBlock(i + 6, j + 0, k + 37, Blocks.redCobble.blockID);
		world.setBlock(i + 6, j + 0, k + 38, Blocks.redCobble.blockID);
		world.setBlock(i + 6, j + 0, k + 39, Blocks.redCobble.blockID);
		world.setBlock(i + 6, j + 0, k + 40, Blocks.redCobble.blockID);
		world.setBlock(i + 6, j + 1, k + 0, Blocks.redCobble.blockID);
		world.setBlock(i + 6, j + 1, k + 1, Block.workbench.blockID);
		world.setBlock(i + 6, j + 1, k + 6, Blocks.redCobble.blockID);
		int randInt7 = (new Random()).nextInt(8);
		if (randInt7 == 6) {
			int chestX = i + 6;
			int chestY = j + 1;
			int chestZ = k + 7;
			int chestRand = (int) (Math.random() * Math.floor(2));
			boolean isBigChest = (chestRand == 1) ? true : false;
			String chestString = chestX + " " + chestY + " " + chestZ;
			Treasures.spawnChest(world, rand, chestX, chestY, chestZ,
					isBigChest,
					Treasures.pickChestType());
		}
		world.setBlock(i + 6, j + 1, k + 11, -111);
		world.setBlock(i + 6, j + 1, k + 12, Blocks.redCobble.blockID);
		world.setBlock(i + 6, j + 1, k + 18, Block.workbench.blockID);
		world.setBlock(i + 6, j + 1, k + 19, Blocks.redCobble.blockID);
		world.setBlock(i + 6, j + 1, k + 24, Block.bed.blockID);
		world.setBlock(i + 6, j + 1, k + 25, Block.bed.blockID);
		world.setBlock(i + 6, j + 1, k + 26, Blocks.redCobble.blockID);
		world.setBlock(i + 6, j + 1, k + 31, Block.bed.blockID);
		world.setBlock(i + 6, j + 1, k + 32, Block.bed.blockID);
		world.setBlock(i + 6, j + 1, k + 33, Blocks.redCobble.blockID);
		world.setBlock(i + 6, j + 1, k + 40, Blocks.redCobble.blockID);
		world.setBlock(i + 6, j + 2, k + 0, Blocks.redCobble.blockID);
		world.setBlock(i + 6, j + 2, k + 4, -112);
		world.setBlock(i + 6, j + 2, k + 6, Blocks.betterGlass.blockID);
		world.setBlock(i + 6, j + 2, k + 10, -112);
		world.setBlock(i + 6, j + 2, k + 12, Blocks.redCobble.blockID);
		world.setBlock(i + 6, j + 2, k + 19, Blocks.betterGlass.blockID);
		world.setBlock(i + 6, j + 2, k + 23, -112);
		world.setBlock(i + 6, j + 2, k + 26, Blocks.redCobble.blockID);
		world.setBlock(i + 6, j + 2, k + 33, Blocks.betterGlass.blockID);
		world.setBlock(i + 6, j + 2, k + 36, -112);
		world.setBlock(i + 6, j + 2, k + 40, Blocks.redCobble.blockID);
		world.setBlock(i + 6, j + 3, k + 0, Blocks.redCobble.blockID);
		world.setBlock(i + 6, j + 3, k + 6, Blocks.redCobble.blockID);
		world.setBlock(i + 6, j + 3, k + 12, Blocks.redCobble.blockID);
		world.setBlock(i + 6, j + 3, k + 19, Blocks.redCobble.blockID);
		world.setBlock(i + 6, j + 3, k + 26, Blocks.redCobble.blockID);
		world.setBlock(i + 6, j + 3, k + 33, Blocks.redCobble.blockID);
		world.setBlock(i + 6, j + 3, k + 40, Blocks.redCobble.blockID);
		world.setBlock(i + 6, j + 4, k + 0, Blocks.redCobble.blockID);
		world.setBlock(i + 6, j + 4, k + 6, Blocks.redCobble.blockID);
		world.setBlock(i + 6, j + 4, k + 12, Blocks.redCobble.blockID);
		world.setBlock(i + 6, j + 4, k + 19, Blocks.redCobble.blockID);
		world.setBlock(i + 6, j + 4, k + 26, Blocks.redCobble.blockID);
		world.setBlock(i + 6, j + 4, k + 33, Blocks.redCobble.blockID);
		world.setBlock(i + 6, j + 4, k + 40, Blocks.redCobble.blockID);
		world.setBlock(i + 6, j + 5, k + 0, Blocks.redCobble.blockID);
		world.setBlock(i + 6, j + 5, k + 6, Blocks.redCobble.blockID);
		world.setBlock(i + 6, j + 5, k + 12, Blocks.redCobble.blockID);
		world.setBlock(i + 6, j + 5, k + 19, Blocks.redCobble.blockID);
		world.setBlock(i + 6, j + 5, k + 26, Blocks.redCobble.blockID);
		world.setBlock(i + 6, j + 5, k + 33, Blocks.redCobble.blockID);
		world.setBlock(i + 6, j + 5, k + 40, Blocks.redCobble.blockID);
		world.setBlock(i + 6, j + 6, k + 0, Blocks.redCobble.blockID);
		world.setBlock(i + 6, j + 6, k + 1, Blocks.redCobble.blockID);
		world.setBlock(i + 6, j + 6, k + 2, Blocks.redCobble.blockID);
		world.setBlock(i + 6, j + 6, k + 3, Blocks.redCobble.blockID);
		world.setBlock(i + 6, j + 6, k + 4, Blocks.redCobble.blockID);
		world.setBlock(i + 6, j + 6, k + 5, Blocks.redCobble.blockID);
		world.setBlock(i + 6, j + 6, k + 6, Blocks.redCobble.blockID);
		world.setBlock(i + 6, j + 6, k + 7, Blocks.redCobble.blockID);
		world.setBlock(i + 6, j + 6, k + 8, Blocks.redCobble.blockID);
		world.setBlock(i + 6, j + 6, k + 9, Blocks.redCobble.blockID);
		world.setBlock(i + 6, j + 6, k + 10, Blocks.redCobble.blockID);
		world.setBlock(i + 6, j + 6, k + 11, Blocks.redCobble.blockID);
		world.setBlock(i + 6, j + 6, k + 12, Blocks.redCobble.blockID);
		world.setBlock(i + 6, j + 6, k + 13, Blocks.redCobble.blockID);
		world.setBlock(i + 6, j + 6, k + 14, Blocks.redCobble.blockID);
		world.setBlock(i + 6, j + 6, k + 15, Blocks.redCobble.blockID);
		world.setBlock(i + 6, j + 6, k + 16, Blocks.redCobble.blockID);
		world.setBlock(i + 6, j + 6, k + 17, Blocks.redCobble.blockID);
		world.setBlock(i + 6, j + 6, k + 18, Blocks.redCobble.blockID);
		world.setBlock(i + 6, j + 6, k + 19, Blocks.redCobble.blockID);
		world.setBlock(i + 6, j + 6, k + 20, Blocks.redCobble.blockID);
		world.setBlock(i + 6, j + 6, k + 21, Blocks.redCobble.blockID);
		world.setBlock(i + 6, j + 6, k + 22, Blocks.redCobble.blockID);
		world.setBlock(i + 6, j + 6, k + 23, Blocks.redCobble.blockID);
		world.setBlock(i + 6, j + 6, k + 24, Blocks.redCobble.blockID);
		world.setBlock(i + 6, j + 6, k + 25, Blocks.redCobble.blockID);
		world.setBlock(i + 6, j + 6, k + 26, Blocks.redCobble.blockID);
		world.setBlock(i + 6, j + 6, k + 27, Blocks.redCobble.blockID);
		world.setBlock(i + 6, j + 6, k + 28, Blocks.redCobble.blockID);
		world.setBlock(i + 6, j + 6, k + 29, Blocks.redCobble.blockID);
		world.setBlock(i + 6, j + 6, k + 30, Blocks.redCobble.blockID);
		world.setBlock(i + 6, j + 6, k + 31, Blocks.redCobble.blockID);
		world.setBlock(i + 6, j + 6, k + 32, Blocks.redCobble.blockID);
		world.setBlock(i + 6, j + 6, k + 33, Blocks.redCobble.blockID);
		world.setBlock(i + 6, j + 6, k + 34, Blocks.redCobble.blockID);
		world.setBlock(i + 6, j + 6, k + 35, Blocks.redCobble.blockID);
		world.setBlock(i + 6, j + 6, k + 36, Blocks.redCobble.blockID);
		world.setBlock(i + 6, j + 6, k + 37, Blocks.redCobble.blockID);
		world.setBlock(i + 6, j + 6, k + 38, Blocks.redCobble.blockID);
		world.setBlock(i + 6, j + 6, k + 39, Blocks.redCobble.blockID);
		world.setBlock(i + 6, j + 6, k + 40, Blocks.redCobble.blockID);
		world.setBlock(i + 7, j + 0, k + 0, Blocks.redCobble.blockID);
		world.setBlock(i + 7, j + 0, k + 1, Blocks.redCobble.blockID);
		world.setBlock(i + 7, j + 0, k + 2, Blocks.redCobble.blockID);
		world.setBlock(i + 7, j + 0, k + 3, Blocks.shineStone.blockID);
		world.setBlock(i + 7, j + 0, k + 4, Blocks.redCobble.blockID);
		world.setBlock(i + 7, j + 0, k + 5, Blocks.redCobble.blockID);
		world.setBlock(i + 7, j + 0, k + 6, Blocks.redCobble.blockID);
		world.setBlock(i + 7, j + 0, k + 7, Blocks.redCobble.blockID);
		world.setBlock(i + 7, j + 0, k + 8, Blocks.redCobble.blockID);
		world.setBlock(i + 7, j + 0, k + 9, Blocks.redCobble.blockID);
		world.setBlock(i + 7, j + 0, k + 10, Blocks.redCobble.blockID);
		world.setBlock(i + 7, j + 0, k + 11, Blocks.redCobble.blockID);
		world.setBlock(i + 7, j + 0, k + 12, Blocks.redCobble.blockID);
		world.setBlock(i + 7, j + 0, k + 13, Blocks.redCobble.blockID);
		world.setBlock(i + 7, j + 0, k + 14, Blocks.redCobble.blockID);
		world.setBlock(i + 7, j + 0, k + 15, Blocks.redCobble.blockID);
		world.setBlock(i + 7, j + 0, k + 16, Blocks.redCobble.blockID);
		world.setBlock(i + 7, j + 0, k + 17, Blocks.shineStone.blockID);
		world.setBlock(i + 7, j + 0, k + 18, Blocks.redCobble.blockID);
		world.setBlock(i + 7, j + 0, k + 19, Blocks.redCobble.blockID);
		world.setBlock(i + 7, j + 0, k + 20, Blocks.redCobble.blockID);
		world.setBlock(i + 7, j + 0, k + 21, Blocks.redCobble.blockID);
		world.setBlock(i + 7, j + 0, k + 22, Blocks.shineStone.blockID);
		world.setBlock(i + 7, j + 0, k + 23, Blocks.redCobble.blockID);
		world.setBlock(i + 7, j + 0, k + 24, Blocks.redCobble.blockID);
		world.setBlock(i + 7, j + 0, k + 25, Blocks.redCobble.blockID);
		world.setBlock(i + 7, j + 0, k + 26, Blocks.redCobble.blockID);
		world.setBlock(i + 7, j + 0, k + 27, Blocks.redCobble.blockID);
		world.setBlock(i + 7, j + 0, k + 28, Blocks.redCobble.blockID);
		world.setBlock(i + 7, j + 0, k + 29, Blocks.redCobble.blockID);
		world.setBlock(i + 7, j + 0, k + 30, Blocks.redCobble.blockID);
		world.setBlock(i + 7, j + 0, k + 31, Blocks.redCobble.blockID);
		world.setBlock(i + 7, j + 0, k + 32, Blocks.redCobble.blockID);
		world.setBlock(i + 7, j + 0, k + 33, Blocks.redCobble.blockID);
		world.setBlock(i + 7, j + 0, k + 34, Blocks.shineStone.blockID);
		world.setBlock(i + 7, j + 0, k + 35, Blocks.redCobble.blockID);
		world.setBlock(i + 7, j + 0, k + 36, Blocks.redCobble.blockID);
		world.setBlock(i + 7, j + 0, k + 37, Blocks.redCobble.blockID);
		world.setBlock(i + 7, j + 0, k + 38, Blocks.redCobble.blockID);
		world.setBlock(i + 7, j + 0, k + 39, Blocks.redCobble.blockID);
		world.setBlock(i + 7, j + 0, k + 40, Blocks.redCobble.blockID);
		world.setBlock(i + 7, j + 1, k + 0, Blocks.redCobble.blockID);
		world.setBlock(i + 7, j + 1, k + 6, Blocks.redCobble.blockID);
		int randInt8 = (new Random()).nextInt(8);
		if (randInt8 == 3) {
			int chestX = i + 7;
			int chestY = j + 1;
			int chestZ = k + 18;
			int chestRand = (int) (Math.random() * Math.floor(2));
			boolean isBigChest = (chestRand == 1) ? true : false;
			String chestString = chestX + " " + chestY + " " + chestZ;
			Treasures.spawnChest(world, rand, chestX, chestY, chestZ,
					isBigChest,
					Treasures.pickChestType());
		}
		world.setBlock(i + 7, j + 1, k + 19, Blocks.redCobble.blockID);
		world.setBlock(i + 7, j + 1, k + 26, Blocks.redCobble.blockID);
		world.setBlock(i + 7, j + 1, k + 33, Blocks.redCobble.blockID);
		int randInt9 = (new Random()).nextInt(8);
		if (randInt9 == 4) {
			int chestX = i + 7;
			int chestY = j + 1;
			int chestZ = k + 39;
			int chestRand = (int) (Math.random() * Math.floor(2));
			boolean isBigChest = (chestRand == 1) ? true : false;
			String chestString = chestX + " " + chestY + " " + chestZ;
			Treasures.spawnChest(world, rand, chestX, chestY, chestZ,
					isBigChest,
					Treasures.pickChestType());
		}
		world.setBlock(i + 7, j + 1, k + 40, Blocks.redCobble.blockID);
		world.setBlock(i + 7, j + 2, k + 0, Blocks.redCobble.blockID);
		world.setBlock(i + 7, j + 2, k + 6, Blocks.redCobble.blockID);
		world.setBlock(i + 7, j + 2, k + 19, Blocks.redCobble.blockID);
		world.setBlock(i + 7, j + 2, k + 20, -112);
		world.setBlock(i + 7, j + 2, k + 26, Blocks.redCobble.blockID);
		world.setBlock(i + 7, j + 2, k + 32, -112);
		world.setBlock(i + 7, j + 2, k + 33, Blocks.redCobble.blockID);
		world.setBlock(i + 7, j + 2, k + 40, Blocks.redCobble.blockID);
		world.setBlock(i + 7, j + 3, k + 0, Blocks.redCobble.blockID);
		world.setBlock(i + 7, j + 3, k + 6, Blocks.redCobble.blockID);
		world.setBlock(i + 7, j + 3, k + 12, Blocks.redCobble.blockID);
		world.setBlock(i + 7, j + 3, k + 19, Blocks.redCobble.blockID);
		world.setBlock(i + 7, j + 3, k + 26, Blocks.redCobble.blockID);
		world.setBlock(i + 7, j + 3, k + 33, Blocks.redCobble.blockID);
		world.setBlock(i + 7, j + 3, k + 40, Blocks.redCobble.blockID);
		world.setBlock(i + 7, j + 4, k + 0, Blocks.redCobble.blockID);
		world.setBlock(i + 7, j + 4, k + 6, Blocks.redCobble.blockID);
		world.setBlock(i + 7, j + 4, k + 12, Blocks.redCobble.blockID);
		world.setBlock(i + 7, j + 4, k + 19, Blocks.redCobble.blockID);
		world.setBlock(i + 7, j + 4, k + 26, Blocks.redCobble.blockID);
		world.setBlock(i + 7, j + 4, k + 33, Blocks.redCobble.blockID);
		world.setBlock(i + 7, j + 4, k + 40, Blocks.redCobble.blockID);
		world.setBlock(i + 7, j + 5, k + 0, Blocks.redCobble.blockID);
		world.setBlock(i + 7, j + 5, k + 6, Blocks.redCobble.blockID);
		world.setBlock(i + 7, j + 5, k + 12, Blocks.redCobble.blockID);
		world.setBlock(i + 7, j + 5, k + 19, Blocks.redCobble.blockID);
		world.setBlock(i + 7, j + 5, k + 26, Blocks.redCobble.blockID);
		world.setBlock(i + 7, j + 5, k + 33, Blocks.redCobble.blockID);
		world.setBlock(i + 7, j + 5, k + 40, Blocks.redCobble.blockID);
		world.setBlock(i + 7, j + 6, k + 0, Blocks.redCobble.blockID);
		world.setBlock(i + 7, j + 6, k + 1, Blocks.redCobble.blockID);
		world.setBlock(i + 7, j + 6, k + 2, Blocks.redCobble.blockID);
		world.setBlock(i + 7, j + 6, k + 3, Blocks.redCobble.blockID);
		world.setBlock(i + 7, j + 6, k + 4, Blocks.redCobble.blockID);
		world.setBlock(i + 7, j + 6, k + 5, Blocks.redCobble.blockID);
		world.setBlock(i + 7, j + 6, k + 6, Blocks.redCobble.blockID);
		world.setBlock(i + 7, j + 6, k + 7, Blocks.redCobble.blockID);
		world.setBlock(i + 7, j + 6, k + 8, Blocks.redCobble.blockID);
		world.setBlock(i + 7, j + 6, k + 9, Blocks.redCobble.blockID);
		world.setBlock(i + 7, j + 6, k + 10, Blocks.redCobble.blockID);
		world.setBlock(i + 7, j + 6, k + 11, Blocks.redCobble.blockID);
		world.setBlock(i + 7, j + 6, k + 12, Blocks.redCobble.blockID);
		world.setBlock(i + 7, j + 6, k + 13, Blocks.redCobble.blockID);
		world.setBlock(i + 7, j + 6, k + 14, Blocks.redCobble.blockID);
		world.setBlock(i + 7, j + 6, k + 15, Blocks.redCobble.blockID);
		world.setBlock(i + 7, j + 6, k + 16, Blocks.redCobble.blockID);
		world.setBlock(i + 7, j + 6, k + 17, Blocks.redCobble.blockID);
		world.setBlock(i + 7, j + 6, k + 18, Blocks.redCobble.blockID);
		world.setBlock(i + 7, j + 6, k + 19, Blocks.redCobble.blockID);
		world.setBlock(i + 7, j + 6, k + 20, Blocks.redCobble.blockID);
		world.setBlock(i + 7, j + 6, k + 21, Blocks.redCobble.blockID);
		world.setBlock(i + 7, j + 6, k + 22, Blocks.redCobble.blockID);
		world.setBlock(i + 7, j + 6, k + 23, Blocks.redCobble.blockID);
		world.setBlock(i + 7, j + 6, k + 24, Blocks.redCobble.blockID);
		world.setBlock(i + 7, j + 6, k + 25, Blocks.redCobble.blockID);
		world.setBlock(i + 7, j + 6, k + 26, Blocks.redCobble.blockID);
		world.setBlock(i + 7, j + 6, k + 27, Blocks.redCobble.blockID);
		world.setBlock(i + 7, j + 6, k + 28, Blocks.redCobble.blockID);
		world.setBlock(i + 7, j + 6, k + 29, Blocks.redCobble.blockID);
		world.setBlock(i + 7, j + 6, k + 30, Blocks.redCobble.blockID);
		world.setBlock(i + 7, j + 6, k + 31, Blocks.redCobble.blockID);
		world.setBlock(i + 7, j + 6, k + 32, Blocks.redCobble.blockID);
		world.setBlock(i + 7, j + 6, k + 33, Blocks.redCobble.blockID);
		world.setBlock(i + 7, j + 6, k + 34, Blocks.redCobble.blockID);
		world.setBlock(i + 7, j + 6, k + 35, Blocks.redCobble.blockID);
		world.setBlock(i + 7, j + 6, k + 36, Blocks.redCobble.blockID);
		world.setBlock(i + 7, j + 6, k + 37, Blocks.redCobble.blockID);
		world.setBlock(i + 7, j + 6, k + 38, Blocks.redCobble.blockID);
		world.setBlock(i + 7, j + 6, k + 39, Blocks.redCobble.blockID);
		world.setBlock(i + 7, j + 6, k + 40, Blocks.redCobble.blockID);
		world.setBlock(i + 8, j + 0, k + 0, Blocks.redCobble.blockID);
		world.setBlock(i + 8, j + 0, k + 1, Blocks.redCobble.blockID);
		world.setBlock(i + 8, j + 0, k + 2, Blocks.redCobble.blockID);
		world.setBlock(i + 8, j + 0, k + 3, Blocks.redCobble.blockID);
		world.setBlock(i + 8, j + 0, k + 4, Blocks.redCobble.blockID);
		world.setBlock(i + 8, j + 0, k + 5, Blocks.redCobble.blockID);
		world.setBlock(i + 8, j + 0, k + 6, Blocks.redCobble.blockID);
		world.setBlock(i + 8, j + 0, k + 7, Blocks.redCobble.blockID);
		world.setBlock(i + 8, j + 0, k + 8, Blocks.redCobble.blockID);
		world.setBlock(i + 8, j + 0, k + 9, Blocks.shineStone.blockID);
		world.setBlock(i + 8, j + 0, k + 10, Blocks.redCobble.blockID);
		world.setBlock(i + 8, j + 0, k + 11, Blocks.redCobble.blockID);
		world.setBlock(i + 8, j + 0, k + 12, Blocks.redCobble.blockID);
		world.setBlock(i + 8, j + 0, k + 13, Blocks.redCobble.blockID);
		world.setBlock(i + 8, j + 0, k + 14, Blocks.redCobble.blockID);
		world.setBlock(i + 8, j + 0, k + 15, Blocks.redCobble.blockID);
		world.setBlock(i + 8, j + 0, k + 16, Blocks.redCobble.blockID);
		world.setBlock(i + 8, j + 0, k + 17, Blocks.redCobble.blockID);
		world.setBlock(i + 8, j + 0, k + 18, Blocks.redCobble.blockID);
		world.setBlock(i + 8, j + 0, k + 19, Blocks.redCobble.blockID);
		world.setBlock(i + 8, j + 0, k + 20, Blocks.redCobble.blockID);
		world.setBlock(i + 8, j + 0, k + 21, Blocks.redCobble.blockID);
		world.setBlock(i + 8, j + 0, k + 22, Blocks.redCobble.blockID);
		world.setBlock(i + 8, j + 0, k + 23, Blocks.redCobble.blockID);
		world.setBlock(i + 8, j + 0, k + 24, Blocks.redCobble.blockID);
		world.setBlock(i + 8, j + 0, k + 25, Blocks.redCobble.blockID);
		world.setBlock(i + 8, j + 0, k + 26, Blocks.redCobble.blockID);
		world.setBlock(i + 8, j + 0, k + 27, Blocks.redCobble.blockID);
		world.setBlock(i + 8, j + 0, k + 28, Blocks.redCobble.blockID);
		world.setBlock(i + 8, j + 0, k + 29, Blocks.redCobble.blockID);
		world.setBlock(i + 8, j + 0, k + 30, Blocks.shineStone.blockID);
		world.setBlock(i + 8, j + 0, k + 31, Blocks.redCobble.blockID);
		world.setBlock(i + 8, j + 0, k + 32, Blocks.redCobble.blockID);
		world.setBlock(i + 8, j + 0, k + 33, Blocks.redCobble.blockID);
		world.setBlock(i + 8, j + 0, k + 34, Blocks.redCobble.blockID);
		world.setBlock(i + 8, j + 0, k + 35, Blocks.redCobble.blockID);
		world.setBlock(i + 8, j + 0, k + 36, Blocks.redCobble.blockID);
		world.setBlock(i + 8, j + 0, k + 37, Blocks.redCobble.blockID);
		world.setBlock(i + 8, j + 0, k + 38, Blocks.redCobble.blockID);
		world.setBlock(i + 8, j + 0, k + 39, Blocks.redCobble.blockID);
		world.setBlock(i + 8, j + 0, k + 40, Blocks.redCobble.blockID);
		world.setBlock(i + 8, j + 1, k + 0, Blocks.redCobble.blockID);
		world.setBlock(i + 8, j + 1, k + 1, Block.bed.blockID);
		world.setBlock(i + 8, j + 1, k + 2, Block.bed.blockID);
		world.setBlock(i + 8, j + 1, k + 12, Blocks.redCobble.blockID);
		int randInt10 = (new Random()).nextInt(8);
		if (randInt10 == 5) {
			int chestX = i + 8;
			int chestY = j + 1;
			int chestZ = k + 23;
			int chestRand = (int) (Math.random() * Math.floor(2));
			boolean isBigChest = (chestRand == 1) ? true : false;
			String chestString = chestX + " " + chestY + " " + chestZ;
			Treasures.spawnChest(world, rand, chestX, chestY, chestZ,
					isBigChest,
					Treasures.pickChestType());
		}
		int randInt11 = (new Random()).nextInt(8);
		if (randInt11 == 4) {
			int chestX = i + 8;
			int chestY = j + 1;
			int chestZ = k + 29;
			int chestRand = (int) (Math.random() * Math.floor(2));
			boolean isBigChest = (chestRand == 1) ? true : false;
			String chestString = chestX + " " + chestY + " " + chestZ;
			Treasures.spawnChest(world, rand, chestX, chestY, chestZ,
					isBigChest,
					Treasures.pickChestType());
		}
		world.setBlock(i + 8, j + 1, k + 37, Block.bed.blockID);
		world.setBlock(i + 8, j + 1, k + 40, Blocks.redCobble.blockID);
		world.setBlock(i + 8, j + 2, k + 0, Blocks.redCobble.blockID);
		world.setBlock(i + 8, j + 2, k + 1, -112);
		world.setBlock(i + 8, j + 2, k + 12, Blocks.redCobble.blockID);
		world.setBlock(i + 8, j + 2, k + 13, -112);
		world.setBlock(i + 8, j + 2, k + 40, Blocks.redCobble.blockID);
		world.setBlock(i + 8, j + 3, k + 0, Blocks.redCobble.blockID);
		world.setBlock(i + 8, j + 3, k + 6, Blocks.redCobble.blockID);
		world.setBlock(i + 8, j + 3, k + 12, Blocks.redCobble.blockID);
		world.setBlock(i + 8, j + 3, k + 19, Blocks.redCobble.blockID);
		world.setBlock(i + 8, j + 3, k + 26, Blocks.redCobble.blockID);
		world.setBlock(i + 8, j + 3, k + 33, Blocks.redCobble.blockID);
		world.setBlock(i + 8, j + 3, k + 40, Blocks.redCobble.blockID);
		world.setBlock(i + 8, j + 4, k + 0, Blocks.redCobble.blockID);
		world.setBlock(i + 8, j + 4, k + 6, Blocks.redCobble.blockID);
		world.setBlock(i + 8, j + 4, k + 12, Blocks.redCobble.blockID);
		world.setBlock(i + 8, j + 4, k + 19, Blocks.redCobble.blockID);
		world.setBlock(i + 8, j + 4, k + 26, Blocks.redCobble.blockID);
		world.setBlock(i + 8, j + 4, k + 33, Blocks.redCobble.blockID);
		world.setBlock(i + 8, j + 4, k + 40, Blocks.redCobble.blockID);
		world.setBlock(i + 8, j + 5, k + 0, Blocks.redCobble.blockID);
		world.setBlock(i + 8, j + 5, k + 6, Blocks.redCobble.blockID);
		world.setBlock(i + 8, j + 5, k + 12, Blocks.redCobble.blockID);
		world.setBlock(i + 8, j + 5, k + 19, Blocks.redCobble.blockID);
		world.setBlock(i + 8, j + 5, k + 26, Blocks.redCobble.blockID);
		world.setBlock(i + 8, j + 5, k + 33, Blocks.redCobble.blockID);
		world.setBlock(i + 8, j + 5, k + 40, Blocks.redCobble.blockID);
		world.setBlock(i + 8, j + 6, k + 0, Blocks.redCobble.blockID);
		world.setBlock(i + 8, j + 6, k + 1, Blocks.redCobble.blockID);
		world.setBlock(i + 8, j + 6, k + 2, Blocks.redCobble.blockID);
		world.setBlock(i + 8, j + 6, k + 3, Blocks.redCobble.blockID);
		world.setBlock(i + 8, j + 6, k + 4, Blocks.redCobble.blockID);
		world.setBlock(i + 8, j + 6, k + 5, Blocks.redCobble.blockID);
		world.setBlock(i + 8, j + 6, k + 6, Blocks.redCobble.blockID);
		world.setBlock(i + 8, j + 6, k + 7, Blocks.redCobble.blockID);
		world.setBlock(i + 8, j + 6, k + 8, Blocks.redCobble.blockID);
		world.setBlock(i + 8, j + 6, k + 9, Blocks.redCobble.blockID);
		world.setBlock(i + 8, j + 6, k + 10, Blocks.redCobble.blockID);
		world.setBlock(i + 8, j + 6, k + 11, Blocks.redCobble.blockID);
		world.setBlock(i + 8, j + 6, k + 12, Blocks.redCobble.blockID);
		world.setBlock(i + 8, j + 6, k + 13, Blocks.redCobble.blockID);
		world.setBlock(i + 8, j + 6, k + 14, Blocks.redCobble.blockID);
		world.setBlock(i + 8, j + 6, k + 15, Blocks.redCobble.blockID);
		world.setBlock(i + 8, j + 6, k + 16, Blocks.redCobble.blockID);
		world.setBlock(i + 8, j + 6, k + 17, Blocks.redCobble.blockID);
		world.setBlock(i + 8, j + 6, k + 18, Blocks.redCobble.blockID);
		world.setBlock(i + 8, j + 6, k + 19, Blocks.redCobble.blockID);
		world.setBlock(i + 8, j + 6, k + 20, Blocks.redCobble.blockID);
		world.setBlock(i + 8, j + 6, k + 21, Blocks.redCobble.blockID);
		world.setBlock(i + 8, j + 6, k + 22, Blocks.redCobble.blockID);
		world.setBlock(i + 8, j + 6, k + 23, Blocks.redCobble.blockID);
		world.setBlock(i + 8, j + 6, k + 24, Blocks.redCobble.blockID);
		world.setBlock(i + 8, j + 6, k + 25, Blocks.redCobble.blockID);
		world.setBlock(i + 8, j + 6, k + 26, Blocks.redCobble.blockID);
		world.setBlock(i + 8, j + 6, k + 27, Blocks.redCobble.blockID);
		world.setBlock(i + 8, j + 6, k + 28, Blocks.redCobble.blockID);
		world.setBlock(i + 8, j + 6, k + 29, Blocks.redCobble.blockID);
		world.setBlock(i + 8, j + 6, k + 30, Blocks.redCobble.blockID);
		world.setBlock(i + 8, j + 6, k + 31, Blocks.redCobble.blockID);
		world.setBlock(i + 8, j + 6, k + 32, Blocks.redCobble.blockID);
		world.setBlock(i + 8, j + 6, k + 33, Blocks.redCobble.blockID);
		world.setBlock(i + 8, j + 6, k + 34, Blocks.redCobble.blockID);
		world.setBlock(i + 8, j + 6, k + 35, Blocks.redCobble.blockID);
		world.setBlock(i + 8, j + 6, k + 36, Blocks.redCobble.blockID);
		world.setBlock(i + 8, j + 6, k + 37, Blocks.redCobble.blockID);
		world.setBlock(i + 8, j + 6, k + 38, Blocks.redCobble.blockID);
		world.setBlock(i + 8, j + 6, k + 39, Blocks.redCobble.blockID);
		world.setBlock(i + 8, j + 6, k + 40, Blocks.redCobble.blockID);
		world.setBlock(i + 9, j + 0, k + 0, Blocks.redCobble.blockID);
		world.setBlock(i + 9, j + 0, k + 1, Blocks.redCobble.blockID);
		world.setBlock(i + 9, j + 0, k + 2, Blocks.redCobble.blockID);
		world.setBlock(i + 9, j + 0, k + 3, Blocks.redCobble.blockID);
		world.setBlock(i + 9, j + 0, k + 4, Blocks.redCobble.blockID);
		world.setBlock(i + 9, j + 0, k + 5, Blocks.redCobble.blockID);
		world.setBlock(i + 9, j + 0, k + 6, Blocks.redCobble.blockID);
		world.setBlock(i + 9, j + 0, k + 7, Blocks.redCobble.blockID);
		world.setBlock(i + 9, j + 0, k + 8, Blocks.redCobble.blockID);
		world.setBlock(i + 9, j + 0, k + 9, Blocks.redCobble.blockID);
		world.setBlock(i + 9, j + 0, k + 10, Blocks.redCobble.blockID);
		world.setBlock(i + 9, j + 0, k + 11, Blocks.redCobble.blockID);
		world.setBlock(i + 9, j + 0, k + 12, Blocks.redCobble.blockID);
		world.setBlock(i + 9, j + 0, k + 13, Blocks.redCobble.blockID);
		world.setBlock(i + 9, j + 0, k + 14, Blocks.redCobble.blockID);
		world.setBlock(i + 9, j + 0, k + 15, Blocks.redCobble.blockID);
		world.setBlock(i + 9, j + 0, k + 16, Blocks.redCobble.blockID);
		world.setBlock(i + 9, j + 0, k + 17, Blocks.redCobble.blockID);
		world.setBlock(i + 9, j + 0, k + 18, Blocks.redCobble.blockID);
		world.setBlock(i + 9, j + 0, k + 19, Blocks.redCobble.blockID);
		world.setBlock(i + 9, j + 0, k + 20, Blocks.redCobble.blockID);
		world.setBlock(i + 9, j + 0, k + 21, Blocks.redCobble.blockID);
		world.setBlock(i + 9, j + 0, k + 22, Blocks.redCobble.blockID);
		world.setBlock(i + 9, j + 0, k + 23, Blocks.redCobble.blockID);
