package alphaitems.dimensions.venus.gen.structure;

import java.util.Random;

import net.minecraft.block.Block;
import net.minecraft.tileentity.TileEntityMobSpawner;
import net.minecraft.world.World;
import net.minecraft.world.gen.feature.WorldGenerator;
import net.minecraftforge.common.DungeonHooks;
import alphaitems.blocks.Blocks;
import alphaitems.treasures.Treasures;

public class WorldGenVenusRuins extends WorldGenerator {
	int randInt = (new Random()).nextInt(10);
	
	protected int[] GetValidSpawnBlocks() {
		return new int[] { Blocks.venusRock.blockID,
				Blocks.venusSand.blockID };
	}
	
	public boolean LocationIsValidSpawn(World world, int i, int j, int k) {
		int distanceToAir = 0;
		int checkID = world.getBlockId(i, j, k);
		
		while (checkID != 0) {
			distanceToAir++;
			checkID = world.getBlockId(i, j + distanceToAir, k);
		}
		
		if (distanceToAir > 3) {
			return false;
		}
		j += distanceToAir - 1;
		
		int blockID = world.getBlockId(i, j, k);
		int blockIDAbove = world.getBlockId(i, j + 1, k);
		int blockIDBelow = world.getBlockId(i, j - 1, k);
		for (int x : GetValidSpawnBlocks()) {
			if (blockIDAbove != 0) {
				return false;
			}
			if (blockID == x) {
				return true;
			} else if (blockID == Blocks.venusRock.blockID
					&& blockIDBelow == x) {
				return true;
			}
		}
		return false;
	}
	
	public WorldGenVenusRuins() {
	}
	
	@Override
	public boolean generate(World world, Random rand, int i, int j, int k) {
		// check that each corner is one of the valid spawn blocks
		if (!LocationIsValidSpawn(world, i, j, k)) {
			return false;
		}
		
		world.setBlock(i + 0, j + 0, k + 0, Blocks.venusBrick.blockID);
		world.setBlock(i + 0, j + 0, k + 1, Blocks.venusBrick.blockID);
		world.setBlock(i + 0, j + 0, k + 2, Blocks.venusBrick.blockID);
		world.setBlock(i + 0, j + 0, k + 3, Blocks.venusBrick.blockID);
		world.setBlock(i + 0, j + 0, k + 4, Blocks.venusBrick.blockID);
		world.setBlock(i + 0, j + 0, k + 5, Blocks.venusBrick.blockID);
		world.setBlock(i + 0, j + 0, k + 6, Blocks.venusBrick.blockID);
		world.setBlock(i + 0, j + 0, k + 7, Blocks.venusBrick.blockID);
		world.setBlock(i + 0, j + 0, k + 8, Blocks.venusBrick.blockID);
		world.setBlock(i + 0, j + 0, k + 9, Blocks.venusBrick.blockID);
		world.setBlock(i + 0, j + 0, k + 10, Blocks.venusBrick.blockID);
		world.setBlock(i + 0, j + 0, k + 11, Blocks.venusBrick.blockID);
		world.setBlock(i + 0, j + 0, k + 12, Blocks.venusBrick.blockID);
		world.setBlock(i + 0, j + 0, k + 13, Blocks.venusBrick.blockID);
		world.setBlock(i + 0, j + 0, k + 14, Blocks.venusBrick.blockID);
		world.setBlock(i + 0, j + 0, k + 15, Blocks.venusBrick.blockID);
		world.setBlock(i + 0, j + 0, k + 16, Blocks.venusBrick.blockID);
		world.setBlock(i + 0, j + 0, k + 17, Blocks.venusBrick.blockID);
		world.setBlock(i + 0, j + 0, k + 18, Blocks.venusBrick.blockID);
		world.setBlock(i + 0, j + 0, k + 19, Blocks.venusBrick.blockID);
		world.setBlock(i + 0, j + 0, k + 20, Blocks.venusBrick.blockID);
		world.setBlock(i + 0, j + 0, k + 21, Blocks.venusBrick.blockID);
		world.setBlock(i + 0, j + 0, k + 22, Blocks.venusBrick.blockID);
		world.setBlock(i + 0, j + 0, k + 23, Blocks.venusBrick.blockID);
		world.setBlock(i + 0, j + 0, k + 24, Blocks.venusBrick.blockID);
		world.setBlock(i + 0, j + 0, k + 25, Blocks.venusBrick.blockID);
		world.setBlock(i + 0, j + 0, k + 26, Blocks.venusBrick.blockID);
		world.setBlock(i + 0, j + 0, k + 27, Blocks.venusBrick.blockID);
		world.setBlock(i + 0, j + 0, k + 28, Blocks.venusBrick.blockID);
		world.setBlock(i + 0, j + 0, k + 29, Blocks.venusBrick.blockID);
		world.setBlock(i + 0, j + 0, k + 30, Blocks.venusBrick.blockID);
		world.setBlock(i + 0, j + 0, k + 31, Blocks.venusBrick.blockID);
		world.setBlock(i + 0, j + 0, k + 32, Blocks.venusBrick.blockID);
		world.setBlock(i + 0, j + 0, k + 33, Blocks.venusBrick.blockID);
		world.setBlock(i + 0, j + 0, k + 34, Blocks.venusBrick.blockID);
		int chestRand2 = (new Random()).nextInt(2);
		boolean isBigChest2 = (chestRand2 == 1) ? true : false;
		if (randInt <= 8) {
			Treasures.spawnChest(world, rand, i + 0, j + 1, k + 35,
					isBigChest2,
					Treasures.pickChestType());
		}
		world.setBlock(i + 1, j + 1, k + 36, Block.mobSpawner.blockID);
		world.setBlock(i + 2, j, k + 37, 0);
		world.setBlock(i + 3, j, k + 38, 0);
		world.setBlock(i + 4, j, k + 39, 0);
		world.setBlock(i + 5, j, k + 40, 0);
		TileEntityMobSpawner tileentitymobspawner = (TileEntityMobSpawner) world
				.getBlockTileEntity(i + 1, j + 1, k + 36);
		if (tileentitymobspawner != null)
		{
			tileentitymobspawner.getSpawnerLogic().setMobID(
					DungeonHooks.getRandomDungeonMob(rand));
		}
		
		world.setBlock(i + 0, j + 1, k + 0, Blocks.venusBrick.blockID);
		world.setBlock(i + 0, j + 1, k + 1, Blocks.venusBrick.blockID);
		world.setBlock(i + 0, j + 1, k + 2, Blocks.venusBrick.blockID);
		world.setBlock(i + 0, j + 1, k + 3, Blocks.venusBrick.blockID);
		world.setBlock(i + 0, j + 1, k + 4, Blocks.venusBrick.blockID);
		world.setBlock(i + 0, j + 1, k + 5, Blocks.venusBrick.blockID);
		world.setBlock(i + 0, j + 1, k + 6, Blocks.venusBrick.blockID);
		world.setBlock(i + 0, j + 1, k + 7, Blocks.venusBrick.blockID);
		world.setBlock(i + 0, j + 1, k + 8, Blocks.venusBrick.blockID);
		world.setBlock(i + 0, j + 1, k + 9, Blocks.venusBrick.blockID);
		world.setBlock(i + 0, j + 1, k + 10, Blocks.venusBrick.blockID);
		world.setBlock(i + 0, j + 1, k + 11, Blocks.venusBrick.blockID);
		world.setBlock(i + 0, j + 1, k + 12, Blocks.venusBrick.blockID);
		world.setBlock(i + 0, j + 1, k + 13, Blocks.venusBrick.blockID);
		world.setBlock(i + 0, j + 1, k + 14, Blocks.venusBrick.blockID);
		world.setBlock(i + 0, j + 1, k + 15, Blocks.venusBrick.blockID);
		world.setBlock(i + 0, j + 1, k + 16, Blocks.venusBrick.blockID);
		world.setBlock(i + 0, j + 1, k + 17, Blocks.venusBrick.blockID);
		world.setBlock(i + 0, j + 1, k + 18, Blocks.venusBrick.blockID);
		world.setBlock(i + 0, j + 1, k + 19, Blocks.venusBrick.blockID);
		world.setBlock(i + 0, j + 1, k + 20, Blocks.venusBrick.blockID);
		world.setBlock(i + 0, j + 1, k + 21, Blocks.venusBrick.blockID);
		world.setBlock(i + 0, j + 1, k + 22, Blocks.venusBrick.blockID);
		world.setBlock(i + 0, j + 1, k + 23, Blocks.venusBrick.blockID);
		world.setBlock(i + 0, j + 1, k + 24, Blocks.venusBrick.blockID);
		world.setBlock(i + 0, j + 1, k + 25, Blocks.venusBrick.blockID);
		world.setBlock(i + 0, j + 1, k + 26, Blocks.venusBrick.blockID);
		world.setBlock(i + 0, j + 1, k + 27, Blocks.venusBrick.blockID);
		world.setBlock(i + 0, j + 1, k + 28, Blocks.venusBrick.blockID);
		world.setBlock(i + 0, j + 1, k + 29, Blocks.venusBrick.blockID);
		world.setBlock(i + 0, j + 1, k + 30, Blocks.venusBrick.blockID);
		world.setBlock(i + 0, j + 1, k + 31, Blocks.venusBrick.blockID);
		world.setBlock(i + 0, j + 1, k + 32, Blocks.venusBrick.blockID);
		world.setBlock(i + 0, j + 1, k + 33, Blocks.venusBrick.blockID);
		world.setBlock(i + 0, j + 1, k + 34, Blocks.venusBrick.blockID);
		world.setBlock(i + 0, j + 2, k + 0, Blocks.venusBrick.blockID);
		world.setBlock(i + 0, j + 2, k + 1, Blocks.venusBrick.blockID);
		world.setBlock(i + 0, j + 2, k + 2, Blocks.venusBrick.blockID);
		world.setBlock(i + 0, j + 2, k + 3, Blocks.venusBrick.blockID);
		world.setBlock(i + 0, j + 2, k + 4, Blocks.venusBrick.blockID);
		world.setBlock(i + 0, j + 2, k + 5, Blocks.venusBrick.blockID);
		world.setBlock(i + 0, j + 2, k + 6, Blocks.venusBrick.blockID);
		world.setBlock(i + 0, j + 2, k + 7, Blocks.venusBrick.blockID);
		world.setBlock(i + 0, j + 2, k + 8, Blocks.venusBrick.blockID);
		world.setBlock(i + 0, j + 2, k + 9, Blocks.venusBrick.blockID);
		world.setBlock(i + 0, j + 2, k + 10, Blocks.venusBrick.blockID);
		world.setBlock(i + 0, j + 2, k + 11, Blocks.venusBrick.blockID);
		world.setBlock(i + 0, j + 2, k + 12, Blocks.venusBrick.blockID);
		world.setBlock(i + 0, j + 2, k + 13, Blocks.venusBrick.blockID);
		world.setBlock(i + 0, j + 2, k + 14, Blocks.venusBrick.blockID);
		world.setBlock(i + 0, j + 2, k + 15, Blocks.venusBrick.blockID);
		world.setBlock(i + 0, j + 2, k + 16, Blocks.venusBrick.blockID);
		world.setBlock(i + 0, j + 2, k + 17, Blocks.venusBrick.blockID);
		world.setBlock(i + 0, j + 2, k + 18, Blocks.venusBrick.blockID);
		world.setBlock(i + 0, j + 2, k + 19, Blocks.venusBrick.blockID);
		world.setBlock(i + 0, j + 2, k + 20, Blocks.venusBrick.blockID);
		world.setBlock(i + 0, j + 2, k + 21, Blocks.venusBrick.blockID);
		world.setBlock(i + 0, j + 2, k + 22, Blocks.venusBrick.blockID);
		world.setBlock(i + 0, j + 2, k + 23, Blocks.venusBrick.blockID);
		world.setBlock(i + 0, j + 2, k + 24, Blocks.venusBrick.blockID);
		world.setBlock(i + 0, j + 2, k + 25, Blocks.venusBrick.blockID);
		world.setBlock(i + 0, j + 2, k + 26, Blocks.venusBrick.blockID);
		world.setBlock(i + 0, j + 2, k + 27, Blocks.venusBrick.blockID);
		world.setBlock(i + 0, j + 2, k + 28, Blocks.venusBrick.blockID);
		world.setBlock(i + 0, j + 2, k + 29, Blocks.venusBrick.blockID);
		world.setBlock(i + 0, j + 2, k + 30, Blocks.venusBrick.blockID);
		world.setBlock(i + 0, j + 2, k + 31, Blocks.venusBrick.blockID);
		world.setBlock(i + 0, j + 2, k + 32, Blocks.venusBrick.blockID);
		world.setBlock(i + 0, j + 2, k + 33, Blocks.venusBrick.blockID);
		world.setBlock(i + 0, j + 2, k + 34, Blocks.venusBrick.blockID);
		world.setBlock(i + 0, j + 3, k + 0, Blocks.venusBrick.blockID);
		world.setBlock(i + 0, j + 3, k + 1, Blocks.venusBrick.blockID);
		world.setBlock(i + 0, j + 3, k + 2, Blocks.venusBrick.blockID);
		world.setBlock(i + 0, j + 3, k + 3, Blocks.venusBrick.blockID);
		world.setBlock(i + 0, j + 3, k + 4, Blocks.venusBrick.blockID);
		world.setBlock(i + 0, j + 3, k + 5, Blocks.venusBrick.blockID);
		world.setBlock(i + 0, j + 3, k + 6, Blocks.venusBrick.blockID);
		world.setBlock(i + 0, j + 3, k + 7, Blocks.venusBrick.blockID);
		world.setBlock(i + 0, j + 3, k + 8, Blocks.venusBrick.blockID);
		world.setBlock(i + 0, j + 3, k + 9, Blocks.venusBrick.blockID);
		world.setBlock(i + 0, j + 3, k + 10, Blocks.venusBrick.blockID);
		world.setBlock(i + 0, j + 3, k + 11, Blocks.venusBrick.blockID);
		world.setBlock(i + 0, j + 3, k + 12, Blocks.venusBrick.blockID);
		world.setBlock(i + 0, j + 3, k + 19, Blocks.venusBrick.blockID);
		world.setBlock(i + 0, j + 3, k + 20, Blocks.venusBrick.blockID);
		world.setBlock(i + 0, j + 3, k + 21, Blocks.venusBrick.blockID);
		world.setBlock(i + 0, j + 3, k + 22, Blocks.venusBrick.blockID);
		world.setBlock(i + 0, j + 3, k + 23, Blocks.venusBrick.blockID);
		world.setBlock(i + 0, j + 3, k + 24, Blocks.venusBrick.blockID);
		world.setBlock(i + 0, j + 3, k + 25, Blocks.venusBrick.blockID);
		world.setBlock(i + 0, j + 3, k + 26, Blocks.venusBrick.blockID);
		world.setBlock(i + 0, j + 3, k + 27, Blocks.venusBrick.blockID);
		world.setBlock(i + 0, j + 3, k + 28, Blocks.venusBrick.blockID);
		world.setBlock(i + 0, j + 3, k + 29, Blocks.venusBrick.blockID);
		world.setBlock(i + 0, j + 3, k + 30, Blocks.venusBrick.blockID);
		world.setBlock(i + 0, j + 3, k + 31, Blocks.venusBrick.blockID);
		world.setBlock(i + 0, j + 3, k + 32, Blocks.venusBrick.blockID);
		world.setBlock(i + 0, j + 3, k + 33, Blocks.venusBrick.blockID);
		world.setBlock(i + 0, j + 3, k + 34, Blocks.venusBrick.blockID);
		world.setBlock(i + 0, j + 4, k + 0, Blocks.venusBrick.blockID);
		world.setBlock(i + 0, j + 4, k + 1, Blocks.venusBrick.blockID);
		world.setBlock(i + 0, j + 4, k + 2, Blocks.venusBrick.blockID);
		world.setBlock(i + 0, j + 4, k + 3, Blocks.venusBrick.blockID);
		world.setBlock(i + 0, j + 4, k + 4, Blocks.venusBrick.blockID);
		world.setBlock(i + 0, j + 4, k + 5, Blocks.venusBrick.blockID);
		world.setBlock(i + 0, j + 4, k + 6, Blocks.venusBrick.blockID);
		world.setBlock(i + 0, j + 4, k + 7, Blocks.venusBrick.blockID);
		world.setBlock(i + 0, j + 4, k + 8, Blocks.venusBrick.blockID);
		world.setBlock(i + 0, j + 4, k + 9, Blocks.venusBrick.blockID);
		world.setBlock(i + 0, j + 4, k + 10, Blocks.venusBrick.blockID);
		world.setBlock(i + 0, j + 4, k + 21, Blocks.venusBrick.blockID);
		world.setBlock(i + 0, j + 4, k + 22, Blocks.venusBrick.blockID);
		world.setBlock(i + 0, j + 4, k + 23, Blocks.venusBrick.blockID);
		world.setBlock(i + 0, j + 4, k + 24, Blocks.venusBrick.blockID);
		world.setBlock(i + 0, j + 4, k + 25, Blocks.venusBrick.blockID);
		world.setBlock(i + 0, j + 4, k + 26, Blocks.venusBrick.blockID);
		world.setBlock(i + 0, j + 4, k + 27, Blocks.venusBrick.blockID);
		world.setBlock(i + 0, j + 4, k + 28, Blocks.venusBrick.blockID);
		world.setBlock(i + 0, j + 4, k + 29, Blocks.venusBrick.blockID);
		world.setBlock(i + 0, j + 4, k + 30, Blocks.venusBrick.blockID);
		world.setBlock(i + 0, j + 4, k + 31, Blocks.venusBrick.blockID);
		world.setBlock(i + 0, j + 4, k + 32, Blocks.venusBrick.blockID);
		world.setBlock(i + 0, j + 4, k + 33, Blocks.venusBrick.blockID);
		world.setBlock(i + 0, j + 4, k + 34, Blocks.venusBrick.blockID);
		world.setBlock(i + 0, j + 5, k + 0, Blocks.venusBrick.blockID);
		world.setBlock(i + 0, j + 5, k + 1, Blocks.venusBrick.blockID);
		world.setBlock(i + 0, j + 5, k + 2, Blocks.venusBrick.blockID);
		world.setBlock(i + 0, j + 5, k + 3, Blocks.venusBrick.blockID);
		world.setBlock(i + 0, j + 5, k + 4, Blocks.venusBrick.blockID);
		world.setBlock(i + 0, j + 5, k + 5, Blocks.venusBrick.blockID);
		world.setBlock(i + 0, j + 5, k + 6, Blocks.venusBrick.blockID);
		world.setBlock(i + 0, j + 5, k + 7, Blocks.venusBrick.blockID);
		world.setBlock(i + 0, j + 5, k + 8, Blocks.venusBrick.blockID);
		world.setBlock(i + 0, j + 5, k + 9, Blocks.venusBrick.blockID);
		world.setBlock(i + 0, j + 5, k + 10, Blocks.venusBrick.blockID);
		world.setBlock(i + 0, j + 5, k + 21, Blocks.venusBrick.blockID);
		world.setBlock(i + 0, j + 5, k + 22, Blocks.venusBrick.blockID);
		world.setBlock(i + 0, j + 5, k + 23, Blocks.venusBrick.blockID);
		world.setBlock(i + 0, j + 5, k + 24, Blocks.venusBrick.blockID);
		world.setBlock(i + 0, j + 5, k + 25, Blocks.venusBrick.blockID);
		world.setBlock(i + 0, j + 5, k + 31, Blocks.venusBrick.blockID);
		world.setBlock(i + 0, j + 5, k + 32, Blocks.venusBrick.blockID);
		world.setBlock(i + 0, j + 5, k + 33, Blocks.venusBrick.blockID);
		world.setBlock(i + 0, j + 5, k + 34, Blocks.venusBrick.blockID);
		world.setBlock(i + 0, j + 6, k + 0, Blocks.venusBrick.blockID);
		world.setBlock(i + 0, j + 6, k + 1, Blocks.venusBrick.blockID);
		world.setBlock(i + 0, j + 6, k + 2, Blocks.venusBrick.blockID);
		world.setBlock(i + 0, j + 6, k + 3, Blocks.venusBrick.blockID);
		world.setBlock(i + 0, j + 6, k + 4, Blocks.venusBrick.blockID);
		world.setBlock(i + 0, j + 6, k + 5, Blocks.venusBrick.blockID);
		world.setBlock(i + 0, j + 6, k + 6, Blocks.venusBrick.blockID);
		world.setBlock(i + 0, j + 6, k + 7, Blocks.venusBrick.blockID);
		world.setBlock(i + 0, j + 6, k + 8, Blocks.venusBrick.blockID);
		world.setBlock(i + 0, j + 6, k + 9, Blocks.venusBrick.blockID);
		world.setBlock(i + 0, j + 6, k + 10, Blocks.venusBrick.blockID);
		world.setBlock(i + 0, j + 6, k + 22, Blocks.venusBrick.blockID);
		world.setBlock(i + 0, j + 6, k + 23, Blocks.venusBrick.blockID);
		world.setBlock(i + 0, j + 6, k + 24, Blocks.venusBrick.blockID);
		world.setBlock(i + 0, j + 6, k + 32, Blocks.venusBrick.blockID);
		world.setBlock(i + 0, j + 6, k + 33, Blocks.venusBrick.blockID);
		world.setBlock(i + 0, j + 6, k + 34, Blocks.venusBrick.blockID);
		world.setBlock(i + 0, j + 7, k + 0, Blocks.venusBrick.blockID);
		world.setBlock(i + 0, j + 7, k + 1, Blocks.venusBrick.blockID);
		world.setBlock(i + 0, j + 7, k + 2, Blocks.venusBrick.blockID);
		world.setBlock(i + 0, j + 7, k + 3, Blocks.venusBrick.blockID);
		world.setBlock(i + 0, j + 7, k + 4, Blocks.venusBrick.blockID);
		world.setBlock(i + 0, j + 7, k + 5, Blocks.venusBrick.blockID);
		world.setBlock(i + 0, j + 7, k + 6, Blocks.venusBrick.blockID);
		world.setBlock(i + 0, j + 7, k + 7, Blocks.venusBrick.blockID);
		world.setBlock(i + 0, j + 7, k + 8, Blocks.venusBrick.blockID);
		world.setBlock(i + 0, j + 7, k + 9, Blocks.venusBrick.blockID);
		world.setBlock(i + 0, j + 7, k + 10, Blocks.venusBrick.blockID);
		world.setBlock(i + 0, j + 7, k + 11, Blocks.venusBrick.blockID);
		world.setBlock(i + 0, j + 7, k + 22, Blocks.venusBrick.blockID);
		world.setBlock(i + 0, j + 7, k + 32, Blocks.venusBrick.blockID);
		world.setBlock(i + 0, j + 7, k + 33, Blocks.venusBrick.blockID);
		world.setBlock(i + 0, j + 7, k + 34, Blocks.venusBrick.blockID);
		world.setBlock(i + 0, j + 8, k + 0, Blocks.venusBrick.blockID);
		world.setBlock(i + 0, j + 8, k + 1, Blocks.venusBrick.blockID);
		world.setBlock(i + 0, j + 8, k + 2, Blocks.venusBrick.blockID);
		world.setBlock(i + 0, j + 8, k + 3, Blocks.venusBrick.blockID);
		world.setBlock(i + 0, j + 8, k + 4, Blocks.venusBrick.blockID);
		world.setBlock(i + 0, j + 8, k + 5, Blocks.venusBrick.blockID);
		world.setBlock(i + 0, j + 8, k + 6, Blocks.venusBrick.blockID);
		world.setBlock(i + 0, j + 8, k + 7, Blocks.venusBrick.blockID);
		world.setBlock(i + 0, j + 8, k + 8, Blocks.venusBrick.blockID);
		world.setBlock(i + 0, j + 8, k + 9, Blocks.venusBrick.blockID);
		world.setBlock(i + 0, j + 8, k + 33, Blocks.venusBrick.blockID);
		world.setBlock(i + 0, j + 8, k + 34, Blocks.venusBrick.blockID);
		world.setBlock(i + 0, j + 9, k + 0, Blocks.venusBrick.blockID);
		world.setBlock(i + 0, j + 9, k + 1, Blocks.venusBrick.blockID);
		world.setBlock(i + 0, j + 9, k + 2, Blocks.venusBrick.blockID);
		world.setBlock(i + 0, j + 9, k + 3, Blocks.venusBrick.blockID);
		world.setBlock(i + 0, j + 9, k + 4, Blocks.venusBrick.blockID);
		world.setBlock(i + 0, j + 9, k + 5, Blocks.venusBrick.blockID);
		world.setBlock(i + 0, j + 9, k + 6, Blocks.venusBrick.blockID);
		world.setBlock(i + 0, j + 9, k + 7, Blocks.venusBrick.blockID);
		world.setBlock(i + 0, j + 9, k + 8, Blocks.venusBrick.blockID);
		world.setBlock(i + 0, j + 9, k + 32, Blocks.venusBrick.blockID);
		world.setBlock(i + 0, j + 9, k + 33, Blocks.venusBrick.blockID);
		world.setBlock(i + 0, j + 9, k + 34, Blocks.venusBrick.blockID);
		world.setBlock(i + 0, j + 10, k + 0, Blocks.venusBrick.blockID);
		world.setBlock(i + 0, j + 10, k + 1, Blocks.venusBrick.blockID);
		world.setBlock(i + 0, j + 10, k + 2, Blocks.venusBrick.blockID);
		world.setBlock(i + 0, j + 10, k + 3, Blocks.venusBrick.blockID);
		world.setBlock(i + 0, j + 10, k + 4, Blocks.venusBrick.blockID);
		world.setBlock(i + 0, j + 10, k + 5, Blocks.venusBrick.blockID);
		world.setBlock(i + 0, j + 10, k + 6, Blocks.venusBrick.blockID);
		world.setBlock(i + 0, j + 10, k + 7, Blocks.venusBrick.blockID);
		world.setBlock(i + 0, j + 10, k + 8, Blocks.venusBrick.blockID);
		world.setBlock(i + 0, j + 10, k + 9, Blocks.venusBrick.blockID);
		world.setBlock(i + 0, j + 10, k + 30, Blocks.venusBrick.blockID);
		world.setBlock(i + 0, j + 10, k + 31, Blocks.venusBrick.blockID);
		world.setBlock(i + 0, j + 10, k + 32, Blocks.venusBrick.blockID);
		world.setBlock(i + 0, j + 10, k + 33, Blocks.venusBrick.blockID);
		world.setBlock(i + 0, j + 10, k + 34, Blocks.venusBrick.blockID);
		world.setBlock(i + 0, j + 11, k + 0, Blocks.venusBrick.blockID);
		world.setBlock(i + 0, j + 11, k + 1, Blocks.venusBrick.blockID);
		world.setBlock(i + 0, j + 11, k + 2, Blocks.venusBrick.blockID);
		world.setBlock(i + 0, j + 11, k + 3, Blocks.venusBrick.blockID);
		world.setBlock(i + 0, j + 11, k + 4, Blocks.venusBrick.blockID);
		world.setBlock(i + 0, j + 11, k + 5, Blocks.venusBrick.blockID);
		world.setBlock(i + 0, j + 11, k + 6, Blocks.venusBrick.blockID);
		world.setBlock(i + 0, j + 11, k + 7, Blocks.venusBrick.blockID);
		world.setBlock(i + 0, j + 11, k + 8, Blocks.venusBrick.blockID);
		world.setBlock(i + 0, j + 11, k + 9, Blocks.venusBrick.blockID);
		world.setBlock(i + 0, j + 11, k + 31, Blocks.venusBrick.blockID);
		world.setBlock(i + 0, j + 11, k + 32, Blocks.venusBrick.blockID);
		world.setBlock(i + 0, j + 11, k + 33, Blocks.venusBrick.blockID);
		world.setBlock(i + 0, j + 11, k + 34, Blocks.venusBrick.blockID);
		world.setBlock(i + 1, j + 0, k + 0, Blocks.venusBrick.blockID);
		world.setBlock(i + 1, j + 0, k + 1, Blocks.venusBrick.blockID);
		world.setBlock(i + 1, j + 0, k + 2, Blocks.venusBrick.blockID);
		world.setBlock(i + 1, j + 0, k + 3, Blocks.venusBrick.blockID);
		world.setBlock(i + 1, j + 0, k + 4, Blocks.venusBrick.blockID);
		world.setBlock(i + 1, j + 0, k + 5, Blocks.venusBrick.blockID);
		world.setBlock(i + 1, j + 0, k + 6, Blocks.venusBrick.blockID);
		world.setBlock(i + 1, j + 0, k + 7, Blocks.venusBrick.blockID);
		world.setBlock(i + 1, j + 0, k + 8, Blocks.venusBrick.blockID);
		world.setBlock(i + 1, j + 0, k + 9, Blocks.venusBrick.blockID);
		world.setBlock(i + 1, j + 0, k + 10, Blocks.venusBrick.blockID);
		world.setBlock(i + 1, j + 0, k + 11, Blocks.venusBrick.blockID);
		world.setBlock(i + 1, j + 0, k + 12, Blocks.venusBrick.blockID);
		world.setBlock(i + 1, j + 0, k + 13, Blocks.venusBrick.blockID);
		world.setBlock(i + 1, j + 0, k + 14, Blocks.venusBrick.blockID);
		world.setBlock(i + 1, j + 0, k + 15, Blocks.venusBrick.blockID);
		world.setBlock(i + 1, j + 0, k + 16, Blocks.venusBrick.blockID);
		world.setBlock(i + 1, j + 0, k + 17, Blocks.venusBrick.blockID);
		world.setBlock(i + 1, j + 0, k + 18, Blocks.venusBrick.blockID);
		world.setBlock(i + 1, j + 0, k + 19, Blocks.venusBrick.blockID);
		world.setBlock(i + 1, j + 0, k + 20, Blocks.venusBrick.blockID);
		world.setBlock(i + 1, j + 0, k + 21, Blocks.venusBrick.blockID);
		world.setBlock(i + 1, j + 0, k + 22, Blocks.venusBrick.blockID);
		world.setBlock(i + 1, j + 0, k + 23, Blocks.venusBrick.blockID);
		world.setBlock(i + 1, j + 0, k + 24, Blocks.venusBrick.blockID);
		world.setBlock(i + 1, j + 0, k + 25, Blocks.venusBrick.blockID);
		world.setBlock(i + 1, j + 0, k + 26, Blocks.venusBrick.blockID);
		world.setBlock(i + 1, j + 0, k + 27, Blocks.venusBrick.blockID);
		world.setBlock(i + 1, j + 0, k + 28, Blocks.venusBrick.blockID);
		world.setBlock(i + 1, j + 0, k + 29, Blocks.venusBrick.blockID);
		world.setBlock(i + 1, j + 0, k + 30, Blocks.venusBrick.blockID);
		world.setBlock(i + 1, j + 0, k + 31, Blocks.venusBrick.blockID);
		world.setBlock(i + 1, j + 0, k + 32, Blocks.venusBrick.blockID);
		world.setBlock(i + 1, j + 0, k + 33, Blocks.venusBrick.blockID);
		world.setBlock(i + 1, j + 0, k + 34, Blocks.venusBrick.blockID);
		world.setBlock(i + 1, j + 1, k + 0, Blocks.venusBrick.blockID);
		world.setBlock(i + 1, j + 1, k + 1, Blocks.venusBrick.blockID);
		world.setBlock(i + 1, j + 1, k + 2, Blocks.venusBrick.blockID);
		world.setBlock(i + 1, j + 1, k + 3, Blocks.venusBrick.blockID);
		world.setBlock(i + 1, j + 1, k + 4, Blocks.venusBrick.blockID);
		world.setBlock(i + 1, j + 1, k + 5, Blocks.venusBrick.blockID);
		world.setBlock(i + 1, j + 1, k + 6, Blocks.venusBrick.blockID);
		world.setBlock(i + 1, j + 1, k + 7, Blocks.venusBrick.blockID);
		world.setBlock(i + 1, j + 1, k + 8, Blocks.venusBrick.blockID);
		world.setBlock(i + 1, j + 1, k + 9, Blocks.venusBrick.blockID);
		world.setBlock(i + 1, j + 1, k + 10, Blocks.venusBrick.blockID);
		world.setBlock(i + 1, j + 1, k + 11, Blocks.venusBrick.blockID);
		world.setBlock(i + 1, j + 1, k + 12, Blocks.venusBrick.blockID);
		world.setBlock(i + 1, j + 1, k + 13, Blocks.venusBrick.blockID);
		world.setBlock(i + 1, j + 1, k + 14, Blocks.venusBrick.blockID);
		world.setBlock(i + 1, j + 1, k + 15, Blocks.venusBrick.blockID);
		world.setBlock(i + 1, j + 1, k + 16, Blocks.venusBrick.blockID);
		world.setBlock(i + 1, j + 1, k + 17, Blocks.venusBrick.blockID);
		world.setBlock(i + 1, j + 1, k + 18, Blocks.venusBrick.blockID);
		world.setBlock(i + 1, j + 1, k + 19, Blocks.venusBrick.blockID);
		world.setBlock(i + 1, j + 1, k + 20, Blocks.venusBrick.blockID);
		world.setBlock(i + 1, j + 1, k + 21, Blocks.venusBrick.blockID);
		world.setBlock(i + 1, j + 1, k + 22, Blocks.venusBrick.blockID);
		world.setBlock(i + 1, j + 1, k + 23, Blocks.venusBrick.blockID);
		world.setBlock(i + 1, j + 1, k + 24, Blocks.venusBrick.blockID);
		world.setBlock(i + 1, j + 1, k + 25, Blocks.venusBrick.blockID);
		world.setBlock(i + 1, j + 1, k + 26, Blocks.venusBrick.blockID);
		world.setBlock(i + 1, j + 1, k + 27, Blocks.venusBrick.blockID);
		world.setBlock(i + 1, j + 1, k + 28, Blocks.venusBrick.blockID);
		world.setBlock(i + 1, j + 1, k + 29, Blocks.venusBrick.blockID);
		world.setBlock(i + 1, j + 1, k + 30, Blocks.venusBrick.blockID);
		world.setBlock(i + 1, j + 1, k + 31, Blocks.venusBrick.blockID);
		world.setBlock(i + 1, j + 1, k + 32, Blocks.venusBrick.blockID);
		world.setBlock(i + 1, j + 1, k + 33, Blocks.venusBrick.blockID);
		world.setBlock(i + 1, j + 1, k + 34, Blocks.venusBrick.blockID);
		world.setBlock(i + 1, j + 2, k + 0, Blocks.venusBrick.blockID);
		world.setBlock(i + 1, j + 2, k + 1, Blocks.venusBrick.blockID);
		world.setBlock(i + 1, j + 2, k + 2, Blocks.venusBrick.blockID);
		world.setBlock(i + 1, j + 2, k + 3, Blocks.venusBrick.blockID);
		world.setBlock(i + 1, j + 2, k + 4, Blocks.venusBrick.blockID);
		world.setBlock(i + 1, j + 2, k + 5, Blocks.venusBrick.blockID);
		world.setBlock(i + 1, j + 2, k + 6, Blocks.venusBrick.blockID);
		world.setBlock(i + 1, j + 2, k + 7, Blocks.venusBrick.blockID);
		world.setBlock(i + 1, j + 2, k + 8, Blocks.venusBrick.blockID);
		world.setBlock(i + 1, j + 2, k + 9, Blocks.venusBrick.blockID);
		world.setBlock(i + 1, j + 2, k + 10, Blocks.venusBrick.blockID);
		world.setBlock(i + 1, j + 2, k + 11, Blocks.venusBrick.blockID);
		world.setBlock(i + 1, j + 2, k + 12, Blocks.venusBrick.blockID);
		world.setBlock(i + 1, j + 2, k + 13, Blocks.venusBrick.blockID);
		world.setBlock(i + 1, j + 2, k + 14, Blocks.venusBrick.blockID);
		world.setBlock(i + 1, j + 2, k + 15, Blocks.venusBrick.blockID);
		world.setBlock(i + 1, j + 2, k + 16, Blocks.venusBrick.blockID);
		world.setBlock(i + 1, j + 2, k + 17, Blocks.venusBrick.blockID);
		world.setBlock(i + 1, j + 2, k + 18, Blocks.venusBrick.blockID);
		world.setBlock(i + 1, j + 2, k + 19, Blocks.venusBrick.blockID);
		world.setBlock(i + 1, j + 2, k + 20, Blocks.venusBrick.blockID);
		world.setBlock(i + 1, j + 2, k + 21, Blocks.venusBrick.blockID);
		world.setBlock(i + 1, j + 2, k + 22, Blocks.venusBrick.blockID);
		world.setBlock(i + 1, j + 2, k + 23, Blocks.venusBrick.blockID);
		world.setBlock(i + 1, j + 2, k + 24, Blocks.venusBrick.blockID);
		world.setBlock(i + 1, j + 2, k + 25, Blocks.venusBrick.blockID);
		world.setBlock(i + 1, j + 2, k + 26, Blocks.venusBrick.blockID);
		world.setBlock(i + 1, j + 2, k + 27, Blocks.venusBrick.blockID);
		world.setBlock(i + 1, j + 2, k + 28, Blocks.venusBrick.blockID);
		world.setBlock(i + 1, j + 2, k + 29, Blocks.venusBrick.blockID);
		world.setBlock(i + 1, j + 2, k + 30, Blocks.venusBrick.blockID);
		world.setBlock(i + 1, j + 2, k + 31, Blocks.venusBrick.blockID);
		world.setBlock(i + 1, j + 2, k + 32, Blocks.venusBrick.blockID);
		world.setBlock(i + 1, j + 2, k + 33, Blocks.venusBrick.blockID);
		world.setBlock(i + 1, j + 2, k + 34, Blocks.venusBrick.blockID);
		world.setBlock(i + 1, j + 3, k + 0, Blocks.venusBrick.blockID);
		world.setBlock(i + 1, j + 3, k + 1, Blocks.venusBrick.blockID);
		world.setBlock(i + 1, j + 3, k + 2, Blocks.venusBrick.blockID);
		world.setBlock(i + 1, j + 3, k + 3, Blocks.venusBrick.blockID);
		world.setBlock(i + 1, j + 3, k + 4, Blocks.venusBrick.blockID);
		world.setBlock(i + 1, j + 3, k + 5, Blocks.venusBrick.blockID);
		world.setBlock(i + 1, j + 3, k + 6, Blocks.venusBrick.blockID);
		world.setBlock(i + 1, j + 3, k + 7, Blocks.venusBrick.blockID);
		world.setBlock(i + 1, j + 3, k + 8, Blocks.venusBrick.blockID);
		world.setBlock(i + 1, j + 3, k + 9, Blocks.venusBrick.blockID);
		world.setBlock(i + 1, j + 3, k + 10, Blocks.venusBrick.blockID);
		world.setBlock(i + 1, j + 3, k + 11, Blocks.venusBrick.blockID);
		world.setBlock(i + 1, j + 3, k + 12, Blocks.venusBrick.blockID);
		world.setBlock(i + 1, j + 3, k + 13, Blocks.venusBrick.blockID);
		world.setBlock(i + 1, j + 3, k + 18, Blocks.venusBrick.blockID);
		world.setBlock(i + 1, j + 3, k + 19, Blocks.venusBrick.blockID);
		world.setBlock(i + 1, j + 3, k + 20, Blocks.venusBrick.blockID);
		world.setBlock(i + 1, j + 3, k + 21, Blocks.venusBrick.blockID);
		world.setBlock(i + 1, j + 3, k + 22, Blocks.venusBrick.blockID);
		world.setBlock(i + 1, j + 3, k + 23, Blocks.venusBrick.blockID);
		world.setBlock(i + 1, j + 3, k + 24, Blocks.venusBrick.blockID);
		world.setBlock(i + 1, j + 3, k + 25, Blocks.venusBrick.blockID);
		world.setBlock(i + 1, j + 3, k + 26, Blocks.venusBrick.blockID);
		world.setBlock(i + 1, j + 3, k + 27, Blocks.venusBrick.blockID);
		world.setBlock(i + 1, j + 3, k + 28, Blocks.venusBrick.blockID);
		world.setBlock(i + 1, j + 3, k + 29, Blocks.venusBrick.blockID);
		world.setBlock(i + 1, j + 3, k + 30, Blocks.venusBrick.blockID);
		world.setBlock(i + 1, j + 3, k + 31, Blocks.venusBrick.blockID);
		world.setBlock(i + 1, j + 3, k + 32, Blocks.venusBrick.blockID);
		world.setBlock(i + 1, j + 3, k + 33, Blocks.venusBrick.blockID);
		world.setBlock(i + 1, j + 3, k + 34, Blocks.venusBrick.blockID);
		world.setBlock(i + 1, j + 4, k + 0, Blocks.venusBrick.blockID);
		world.setBlock(i + 1, j + 4, k + 1, Blocks.venusBrick.blockID);
		world.setBlock(i + 1, j + 4, k + 2, Blocks.venusBrick.blockID);
		world.setBlock(i + 1, j + 4, k + 3, Blocks.venusBrick.blockID);
		world.setBlock(i + 1, j + 4, k + 4, Blocks.venusBrick.blockID);
		world.setBlock(i + 1, j + 4, k + 5, Blocks.venusBrick.blockID);
		world.setBlock(i + 1, j + 4, k + 6, Blocks.venusBrick.blockID);
		world.setBlock(i + 1, j + 4, k + 7, Blocks.venusBrick.blockID);
		world.setBlock(i + 1, j + 4, k + 8, Blocks.venusBrick.blockID);
		world.setBlock(i + 1, j + 4, k + 9, Blocks.venusBrick.blockID);
		world.setBlock(i + 1, j + 4, k + 10, Blocks.venusBrick.blockID);
		world.setBlock(i + 1, j + 4, k + 11, Blocks.venusBrick.blockID);
		world.setBlock(i + 1, j + 4, k + 21, Blocks.venusBrick.blockID);
		world.setBlock(i + 1, j + 4, k + 22, Blocks.venusBrick.blockID);
		world.setBlock(i + 1, j + 4, k + 23, Blocks.venusBrick.blockID);
		world.setBlock(i + 1, j + 4, k + 24, Blocks.venusBrick.blockID);
		world.setBlock(i + 1, j + 4, k + 25, Blocks.venusBrick.blockID);
		world.setBlock(i + 1, j + 4, k + 31, Blocks.venusBrick.blockID);
		world.setBlock(i + 1, j + 4, k + 32, Blocks.venusBrick.blockID);
		world.setBlock(i + 1, j + 4, k + 33, Blocks.venusBrick.blockID);
		world.setBlock(i + 1, j + 4, k + 34, Blocks.venusBrick.blockID);
		world.setBlock(i + 1, j + 5, k + 0, Blocks.venusBrick.blockID);
		world.setBlock(i + 1, j + 5, k + 1, Blocks.venusBrick.blockID);
		world.setBlock(i + 1, j + 5, k + 2, Blocks.venusBrick.blockID);
		world.setBlock(i + 1, j + 5, k + 3, Blocks.venusBrick.blockID);
		world.setBlock(i + 1, j + 5, k + 4, Blocks.venusBrick.blockID);
		world.setBlock(i + 1, j + 5, k + 5, Blocks.venusBrick.blockID);
		world.setBlock(i + 1, j + 5, k + 6, Blocks.venusBrick.blockID);
		world.setBlock(i + 1, j + 5, k + 7, Blocks.venusBrick.blockID);
		world.setBlock(i + 1, j + 5, k + 8, Blocks.venusBrick.blockID);
		world.setBlock(i + 1, j + 5, k + 9, Blocks.venusBrick.blockID);
		world.setBlock(i + 1, j + 5, k + 10, Blocks.venusBrick.blockID);
		world.setBlock(i + 1, j + 5, k + 23, Blocks.venusBrick.blockID);
		world.setBlock(i + 1, j + 5, k + 33, Blocks.venusBrick.blockID);
		world.setBlock(i + 1, j + 5, k + 34, Blocks.venusBrick.blockID);
		world.setBlock(i + 1, j + 6, k + 0, Blocks.venusBrick.blockID);
		world.setBlock(i + 1, j + 6, k + 1, Blocks.venusBrick.blockID);
		world.setBlock(i + 1, j + 6, k + 2, Blocks.venusBrick.blockID);
		world.setBlock(i + 1, j + 6, k + 3, Blocks.venusBrick.blockID);
		world.setBlock(i + 1, j + 6, k + 4, Blocks.venusBrick.blockID);
		world.setBlock(i + 1, j + 6, k + 5, Blocks.venusBrick.blockID);
		world.setBlock(i + 1, j + 6, k + 6, Blocks.venusBrick.blockID);
		world.setBlock(i + 1, j + 6, k + 7, Blocks.venusBrick.blockID);
		world.setBlock(i + 1, j + 6, k + 8, Blocks.venusBrick.blockID);
		world.setBlock(i + 1, j + 6, k + 9, Blocks.venusBrick.blockID);
		world.setBlock(i + 1, j + 6, k + 10, Blocks.venusBrick.blockID);
		world.setBlock(i + 1, j + 6, k + 11, Blocks.venusBrick.blockID);
		world.setBlock(i + 1, j + 6, k + 34, Blocks.venusBrick.blockID);
		world.setBlock(i + 1, j + 7, k + 0, Blocks.venusBrick.blockID);
		world.setBlock(i + 1, j + 7, k + 1, Blocks.venusBrick.blockID);
		world.setBlock(i + 1, j + 7, k + 2, Blocks.venusBrick.blockID);
		world.setBlock(i + 1, j + 7, k + 3, Blocks.venusBrick.blockID);
		world.setBlock(i + 1, j + 7, k + 4, Blocks.venusBrick.blockID);
		world.setBlock(i + 1, j + 7, k + 5, Blocks.venusBrick.blockID);
		world.setBlock(i + 1, j + 7, k + 6, Blocks.venusBrick.blockID);
		world.setBlock(i + 1, j + 7, k + 7, Blocks.venusBrick.blockID);
		world.setBlock(i + 1, j + 7, k + 8, Blocks.venusBrick.blockID);
		world.setBlock(i + 1, j + 7, k + 9, Blocks.venusBrick.blockID);
		world.setBlock(i + 1, j + 7, k + 33, Blocks.venusBrick.blockID);
		world.setBlock(i + 1, j + 7, k + 34, Blocks.venusBrick.blockID);
		world.setBlock(i + 1, j + 8, k + 0, Blocks.venusBrick.blockID);
		world.setBlock(i + 1, j + 8, k + 1, Blocks.venusBrick.blockID);
		world.setBlock(i + 1, j + 8, k + 2, Blocks.venusBrick.blockID);
		world.setBlock(i + 1, j + 8, k + 3, Blocks.venusBrick.blockID);
		world.setBlock(i + 1, j + 8, k + 4, Blocks.venusBrick.blockID);
		world.setBlock(i + 1, j + 8, k + 5, Blocks.venusBrick.blockID);
		world.setBlock(i + 1, j + 8, k + 6, Blocks.venusBrick.blockID);
		world.setBlock(i + 1, j + 8, k + 7, Blocks.venusBrick.blockID);
		world.setBlock(i + 1, j + 8, k + 33, Blocks.venusBrick.blockID);
		world.setBlock(i + 1, j + 8, k + 34, Blocks.venusBrick.blockID);
		world.setBlock(i + 1, j + 9, k + 0, Blocks.venusBrick.blockID);
		world.setBlock(i + 1, j + 9, k + 1, Blocks.venusBrick.blockID);
		world.setBlock(i + 1, j + 9, k + 2, Blocks.venusBrick.blockID);
		world.setBlock(i + 1, j + 9, k + 3, Blocks.venusBrick.blockID);
		world.setBlock(i + 1, j + 9, k + 4, Blocks.venusBrick.blockID);
		world.setBlock(i + 1, j + 9, k + 5, Blocks.venusBrick.blockID);
		world.setBlock(i + 1, j + 9, k + 6, Blocks.venusBrick.blockID);
		world.setBlock(i + 1, j + 9, k + 33, Blocks.venusBrick.blockID);
		world.setBlock(i + 1, j + 9, k + 34, Blocks.venusBrick.blockID);
		world.setBlock(i + 1, j + 10, k + 0, Blocks.venusBrick.blockID);
		world.setBlock(i + 1, j + 10, k + 1, Blocks.venusBrick.blockID);
		world.setBlock(i + 1, j + 10, k + 2, Blocks.venusBrick.blockID);
		world.setBlock(i + 1, j + 10, k + 3, Blocks.venusBrick.blockID);
		world.setBlock(i + 1, j + 10, k + 4, Blocks.venusBrick.blockID);
		world.setBlock(i + 1, j + 10, k + 5, Blocks.venusBrick.blockID);
		world.setBlock(i + 1, j + 10, k + 6, Blocks.venusBrick.blockID);
		world.setBlock(i + 1, j + 10, k + 7, Blocks.venusBrick.blockID);
		world.setBlock(i + 1, j + 10, k + 31, Blocks.venusBrick.blockID);
		world.setBlock(i + 1, j + 10, k + 32, Blocks.venusBrick.blockID);
		world.setBlock(i + 1, j + 10, k + 33, Blocks.venusBrick.blockID);
		world.setBlock(i + 1, j + 10, k + 34, Blocks.venusBrick.blockID);
		world.setBlock(i + 1, j + 11, k + 0, Blocks.venusBrick.blockID);
		world.setBlock(i + 1, j + 11, k + 1, Blocks.venusBrick.blockID);
		world.setBlock(i + 1, j + 11, k + 3, Blocks.venusBrick.blockID);
		world.setBlock(i + 1, j + 11, k + 4, Blocks.venusBrick.blockID);
		world.setBlock(i + 1, j + 11, k + 5, Blocks.venusBrick.blockID);
		world.setBlock(i + 1, j + 11, k + 6, Blocks.venusBrick.blockID);
		world.setBlock(i + 1, j + 11, k + 7, Blocks.venusBrick.blockID);
		world.setBlock(i + 1, j + 11, k + 8, Blocks.venusBrick.blockID);
		world.setBlock(i + 1, j + 11, k + 9, Blocks.venusBrick.blockID);
		world.setBlock(i + 1, j + 11, k + 30, Blocks.venusBrick.blockID);
		world.setBlock(i + 1, j + 11, k + 31, Blocks.venusBrick.blockID);
		world.setBlock(i + 1, j + 11, k + 32, Blocks.venusBrick.blockID);
		world.setBlock(i + 1, j + 11, k + 33, Blocks.venusBrick.blockID);
		world.setBlock(i + 1, j + 11, k + 34, Blocks.venusBrick.blockID);
		world.setBlock(i + 2, j + 0, k + 0, Blocks.venusBrick.blockID);
		world.setBlock(i + 2, j + 0, k + 1, Blocks.venusBrick.blockID);
		world.setBlock(i + 2, j + 0, k + 2, Blocks.venusBrick.blockID);
		world.setBlock(i + 2, j + 0, k + 3, Blocks.venusBrick.blockID);
		world.setBlock(i + 2, j + 0, k + 4, Blocks.venusBrick.blockID);
		world.setBlock(i + 2, j + 0, k + 5, Blocks.venusBrick.blockID);
		world.setBlock(i + 2, j + 0, k + 6, Blocks.venusBrick.blockID);
		world.setBlock(i + 2, j + 0, k + 7, Blocks.venusBrick.blockID);
		world.setBlock(i + 2, j + 0, k + 8, Blocks.venusBrick.blockID);
		world.setBlock(i + 2, j + 0, k + 9, Blocks.venusBrick.blockID);
		world.setBlock(i + 2, j + 0, k + 10, Blocks.venusBrick.blockID);
		world.setBlock(i + 2, j + 0, k + 11, Blocks.venusBrick.blockID);
		world.setBlock(i + 2, j + 0, k + 12, Blocks.venusBrick.blockID);
		world.setBlock(i + 2, j + 0, k + 13, Blocks.venusBrick.blockID);
		world.setBlock(i + 2, j + 0, k + 14, Blocks.venusBrick.blockID);
		world.setBlock(i + 2, j + 0, k + 15, Blocks.venusBrick.blockID);
		world.setBlock(i + 2, j + 0, k + 16, Blocks.venusBrick.blockID);
		world.setBlock(i + 2, j + 0, k + 17, Blocks.venusBrick.blockID);
		world.setBlock(i + 2, j + 0, k + 18, Blocks.venusBrick.blockID);
		world.setBlock(i + 2, j + 0, k + 19, Blocks.venusBrick.blockID);
		world.setBlock(i + 2, j + 0, k + 20, Blocks.venusBrick.blockID);
		world.setBlock(i + 2, j + 0, k + 21, Blocks.venusBrick.blockID);
		world.setBlock(i + 2, j + 0, k + 22, Blocks.venusBrick.blockID);
		world.setBlock(i + 2, j + 0, k + 23, Blocks.venusBrick.blockID);
		world.setBlock(i + 2, j + 0, k + 24, Blocks.venusBrick.blockID);
		world.setBlock(i + 2, j + 0, k + 25, Blocks.venusBrick.blockID);
		world.setBlock(i + 2, j + 0, k + 26, Blocks.venusBrick.blockID);
		world.setBlock(i + 2, j + 0, k + 27, Blocks.venusBrick.blockID);
		world.setBlock(i + 2, j + 0, k + 28, Blocks.venusBrick.blockID);
		world.setBlock(i + 2, j + 0, k + 29, Blocks.venusBrick.blockID);
		world.setBlock(i + 2, j + 0, k + 30, Blocks.venusBrick.blockID);
		world.setBlock(i + 2, j + 0, k + 31, Blocks.venusBrick.blockID);
		world.setBlock(i + 2, j + 0, k + 32, Blocks.venusBrick.blockID);
		world.setBlock(i + 2, j + 0, k + 33, Blocks.venusBrick.blockID);
		world.setBlock(i + 2, j + 0, k + 34, Blocks.venusBrick.blockID);
		world.setBlock(i + 2, j + 1, k + 0, Blocks.venusBrick.blockID);
		world.setBlock(i + 2, j + 1, k + 1, Blocks.venusBrick.blockID);
		world.setBlock(i + 2, j + 1, k + 2, Blocks.venusBrick.blockID);
		world.setBlock(i + 2, j + 1, k + 3, Blocks.venusBrick.blockID);
		world.setBlock(i + 2, j + 1, k + 4, Blocks.venusBrick.blockID);
		world.setBlock(i + 2, j + 1, k + 5, Blocks.venusBrick.blockID);
		world.setBlock(i + 2, j + 1, k + 6, Blocks.venusBrick.blockID);
		world.setBlock(i + 2, j + 1, k + 7, Blocks.venusBrick.blockID);
		world.setBlock(i + 2, j + 1, k + 8, Blocks.venusBrick.blockID);
		world.setBlock(i + 2, j + 1, k + 9, Blocks.venusBrick.blockID);
		world.setBlock(i + 2, j + 1, k + 10, Blocks.venusBrick.blockID);
		world.setBlock(i + 2, j + 1, k + 11, Blocks.venusBrick.blockID);
		world.setBlock(i + 2, j + 1, k + 12, Blocks.venusBrick.blockID);
		world.setBlock(i + 2, j + 1, k + 13, Blocks.venusBrick.blockID);
		world.setBlock(i + 2, j + 1, k + 14, Blocks.venusBrick.blockID);
		world.setBlock(i + 2, j + 1, k + 15, Blocks.venusBrick.blockID);
		world.setBlock(i + 2, j + 1, k + 16, Blocks.venusBrick.blockID);
		world.setBlock(i + 2, j + 1, k + 17, Blocks.venusBrick.blockID);
		world.setBlock(i + 2, j + 1, k + 18, Blocks.venusBrick.blockID);
		world.setBlock(i + 2, j + 1, k + 19, Blocks.venusBrick.blockID);
		world.setBlock(i + 2, j + 1, k + 20, Blocks.venusBrick.blockID);
		world.setBlock(i + 2, j + 1, k + 21, Blocks.venusBrick.blockID);
		world.setBlock(i + 2, j + 1, k + 22, Blocks.venusBrick.blockID);
		world.setBlock(i + 2, j + 1, k + 23, Blocks.venusBrick.blockID);
		world.setBlock(i + 2, j + 1, k + 24, Blocks.venusBrick.blockID);
		world.setBlock(i + 2, j + 1, k + 25, Blocks.venusBrick.blockID);
		world.setBlock(i + 2, j + 1, k + 26, Blocks.venusBrick.blockID);
		world.setBlock(i + 2, j + 1, k + 27, Blocks.venusBrick.blockID);
		world.setBlock(i + 2, j + 1, k + 28, Blocks.venusBrick.blockID);
		world.setBlock(i + 2, j + 1, k + 29, Blocks.venusBrick.blockID);
		world.setBlock(i + 2, j + 1, k + 30, Blocks.venusBrick.blockID);
		world.setBlock(i + 2, j + 1, k + 31, Blocks.venusBrick.blockID);
		world.setBlock(i + 2, j + 1, k + 32, Blocks.venusBrick.blockID);
		world.setBlock(i + 2, j + 1, k + 33, Blocks.venusBrick.blockID);
		world.setBlock(i + 2, j + 1, k + 34, Blocks.venusBrick.blockID);
		world.setBlock(i + 2, j + 2, k + 0, Blocks.venusBrick.blockID);
		world.setBlock(i + 2, j + 2, k + 1, Blocks.venusBrick.blockID);
		world.setBlock(i + 2, j + 2, k + 2, Blocks.venusBrick.blockID);
		world.setBlock(i + 2, j + 2, k + 3, Blocks.venusBrick.blockID);
		world.setBlock(i + 2, j + 2, k + 4, Blocks.venusBrick.blockID);
		world.setBlock(i + 2, j + 2, k + 5, Blocks.venusBrick.blockID);
		world.setBlock(i + 2, j + 2, k + 6, Blocks.venusBrick.blockID);
		world.setBlock(i + 2, j + 2, k + 7, Blocks.venusBrick.blockID);
		world.setBlock(i + 2, j + 2, k + 8, Blocks.venusBrick.blockID);
		world.setBlock(i + 2, j + 2, k + 9, Blocks.venusBrick.blockID);
		world.setBlock(i + 2, j + 2, k + 10, Blocks.venusBrick.blockID);
		world.setBlock(i + 2, j + 2, k + 11, Blocks.venusBrick.blockID);
		world.setBlock(i + 2, j + 2, k + 12, Blocks.venusBrick.blockID);
		world.setBlock(i + 2, j + 2, k + 13, Blocks.venusBrick.blockID);
		world.setBlock(i + 2, j + 2, k + 14, Blocks.venusBrick.blockID);
		world.setBlock(i + 2, j + 2, k + 15, Blocks.venusBrick.blockID);
		world.setBlock(i + 2, j + 2, k + 16, Blocks.venusBrick.blockID);
		world.setBlock(i + 2, j + 2, k + 17, Blocks.venusBrick.blockID);
		world.setBlock(i + 2, j + 2, k + 18, Blocks.venusBrick.blockID);
		world.setBlock(i + 2, j + 2, k + 19, Blocks.venusBrick.blockID);
		world.setBlock(i + 2, j + 2, k + 20, Blocks.venusBrick.blockID);
		world.setBlock(i + 2, j + 2, k + 21, Blocks.venusBrick.blockID);
		world.setBlock(i + 2, j + 2, k + 22, Blocks.venusBrick.blockID);
		world.setBlock(i + 2, j + 2, k + 23, Blocks.venusBrick.blockID);
		world.setBlock(i + 2, j + 2, k + 24, Blocks.venusBrick.blockID);
		world.setBlock(i + 2, j + 2, k + 25, Blocks.venusBrick.blockID);
		world.setBlock(i + 2, j + 2, k + 26, Blocks.venusBrick.blockID);
		world.setBlock(i + 2, j + 2, k + 27, Blocks.venusBrick.blockID);
		world.setBlock(i + 2, j + 2, k + 28, Blocks.venusBrick.blockID);
		world.setBlock(i + 2, j + 2, k + 29, Blocks.venusBrick.blockID);
		world.setBlock(i + 2, j + 2, k + 30, Blocks.venusBrick.blockID);
		world.setBlock(i + 2, j + 2, k + 31, Blocks.venusBrick.blockID);
		world.setBlock(i + 2, j + 2, k + 32, Blocks.venusBrick.blockID);
		world.setBlock(i + 2, j + 2, k + 33, Blocks.venusBrick.blockID);
		world.setBlock(i + 2, j + 2, k + 34, Blocks.venusBrick.blockID);
		world.setBlock(i + 2, j + 3, k + 0, Blocks.venusBrick.blockID);
		world.setBlock(i + 2, j + 3, k + 1, Blocks.venusBrick.blockID);
		world.setBlock(i + 2, j + 3, k + 2, Blocks.venusBrick.blockID);
		world.setBlock(i + 2, j + 3, k + 3, Blocks.venusBrick.blockID);
		world.setBlock(i + 2, j + 3, k + 4, Blocks.venusBrick.blockID);
		world.setBlock(i + 2, j + 3, k + 5, Blocks.venusBrick.blockID);
		world.setBlock(i + 2, j + 3, k + 6, Blocks.venusBrick.blockID);
		world.setBlock(i + 2, j + 3, k + 7, Blocks.venusBrick.blockID);
		world.setBlock(i + 2, j + 3, k + 8, Blocks.venusBrick.blockID);
		world.setBlock(i + 2, j + 3, k + 9, Blocks.venusBrick.blockID);
		world.setBlock(i + 2, j + 3, k + 10, Blocks.venusBrick.blockID);
		world.setBlock(i + 2, j + 3, k + 11, Blocks.venusBrick.blockID);
		world.setBlock(i + 2, j + 3, k + 12, Blocks.venusBrick.blockID);
		world.setBlock(i + 2, j + 3, k + 13, Blocks.venusBrick.blockID);
		world.setBlock(i + 2, j + 3, k + 14, Blocks.venusBrick.blockID);
		world.setBlock(i + 2, j + 3, k + 15, Blocks.venusBrick.blockID);
		world.setBlock(i + 2, j + 3, k + 16, Blocks.venusBrick.blockID);
		world.setBlock(i + 2, j + 3, k + 17, Blocks.venusBrick.blockID);
		world.setBlock(i + 2, j + 3, k + 18, Blocks.venusBrick.blockID);
		world.setBlock(i + 2, j + 3, k + 19, Blocks.venusBrick.blockID);
		world.setBlock(i + 2, j + 3, k + 20, Blocks.venusBrick.blockID);
		world.setBlock(i + 2, j + 3, k + 21, Blocks.venusBrick.blockID);
		world.setBlock(i + 2, j + 3, k + 22, Blocks.venusBrick.blockID);
		world.setBlock(i + 2, j + 3, k + 23, Blocks.venusBrick.blockID);
		world.setBlock(i + 2, j + 3, k + 24, Blocks.venusBrick.blockID);
		world.setBlock(i + 2, j + 3, k + 25, Blocks.venusBrick.blockID);
		world.setBlock(i + 2, j + 3, k + 26, Blocks.venusBrick.blockID);
		world.setBlock(i + 2, j + 3, k + 27, Blocks.venusBrick.blockID);
		world.setBlock(i + 2, j + 3, k + 28, Blocks.venusBrick.blockID);
		world.setBlock(i + 2, j + 3, k + 29, Blocks.venusBrick.blockID);
		world.setBlock(i + 2, j + 3, k + 30, Blocks.venusBrick.blockID);
		world.setBlock(i + 2, j + 3, k + 31, Blocks.venusBrick.blockID);
		world.setBlock(i + 2, j + 3, k + 32, Blocks.venusBrick.blockID);
		world.setBlock(i + 2, j + 3, k + 33, Blocks.venusBrick.blockID);
		world.setBlock(i + 2, j + 3, k + 34, Blocks.venusBrick.blockID);
		world.setBlock(i + 2, j + 4, k + 0, Blocks.venusBrick.blockID);
		world.setBlock(i + 2, j + 4, k + 1, Blocks.venusBrick.blockID);
		world.setBlock(i + 2, j + 4, k + 2, Blocks.venusBrick.blockID);
		world.setBlock(i + 2, j + 4, k + 3, Blocks.venusBrick.blockID);
		world.setBlock(i + 2, j + 4, k + 4, Blocks.venusBrick.blockID);
		world.setBlock(i + 2, j + 4, k + 5, Blocks.venusBrick.blockID);
		world.setBlock(i + 2, j + 4, k + 6, Blocks.venusBrick.blockID);
		world.setBlock(i + 2, j + 4, k + 7, Blocks.venusBrick.blockID);
		world.setBlock(i + 2, j + 4, k + 8, Blocks.venusBrick.blockID);
		world.setBlock(i + 2, j + 4, k + 9, Blocks.venusBrick.blockID);
		world.setBlock(i + 2, j + 4, k + 10, Blocks.venusBrick.blockID);
		world.setBlock(i + 2, j + 4, k + 11, Blocks.venusBrick.blockID);
		world.setBlock(i + 2, j + 4, k + 12, Blocks.venusBrick.blockID);
		world.setBlock(i + 2, j + 4, k + 13, Blocks.venusBrick.blockID);
		world.setBlock(i + 2, j + 4, k + 32, Blocks.venusBrick.blockID);
		world.setBlock(i + 2, j + 4, k + 33, Blocks.venusBrick.blockID);
		world.setBlock(i + 2, j + 4, k + 34, Blocks.venusBrick.blockID);
		world.setBlock(i + 2, j + 5, k + 0, Blocks.venusBrick.blockID);
		world.setBlock(i + 2, j + 5, k + 1, Blocks.venusBrick.blockID);
		world.setBlock(i + 2, j + 5, k + 2, Blocks.venusBrick.blockID);
		world.setBlock(i + 2, j + 5, k + 3, Blocks.venusBrick.blockID);
		world.setBlock(i + 2, j + 5, k + 4, Blocks.venusBrick.blockID);
		world.setBlock(i + 2, j + 5, k + 5, Blocks.venusBrick.blockID);
		world.setBlock(i + 2, j + 5, k + 6, Blocks.venusBrick.blockID);
		world.setBlock(i + 2, j + 5, k + 7, Blocks.venusBrick.blockID);
		world.setBlock(i + 2, j + 5, k + 8, Blocks.venusBrick.blockID);
		world.setBlock(i + 2, j + 5, k + 9, Blocks.venusBrick.blockID);
		world.setBlock(i + 2, j + 5, k + 10, Blocks.venusBrick.blockID);
		world.setBlock(i + 2, j + 5, k + 11, Blocks.venusBrick.blockID);
		world.setBlock(i + 2, j + 5, k + 12, Blocks.venusBrick.blockID);
		world.setBlock(i + 2, j + 5, k + 34, Blocks.venusBrick.blockID);
		world.setBlock(i + 2, j + 6, k + 0, Blocks.venusBrick.blockID);
		world.setBlock(i + 2, j + 6, k + 1, Blocks.venusBrick.blockID);
		world.setBlock(i + 2, j + 6, k + 2, Blocks.venusBrick.blockID);
		world.setBlock(i + 2, j + 6, k + 3, Blocks.venusBrick.blockID);
		world.setBlock(i + 2, j + 6, k + 4, Blocks.venusBrick.blockID);
		world.setBlock(i + 2, j + 6, k + 5, Blocks.venusBrick.blockID);
		world.setBlock(i + 2, j + 6, k + 6, Blocks.venusBrick.blockID);
		world.setBlock(i + 2, j + 6, k + 7, Blocks.venusBrick.blockID);
		world.setBlock(i + 2, j + 6, k + 8, Blocks.venusBrick.blockID);
		world.setBlock(i + 2, j + 6, k + 9, Blocks.venusBrick.blockID);
		world.setBlock(i + 2, j + 6, k + 10, Blocks.venusBrick.blockID);
		world.setBlock(i + 2, j + 6, k + 11, Blocks.venusBrick.blockID);
		world.setBlock(i + 2, j + 6, k + 12, Blocks.venusBrick.blockID);
		world.setBlock(i + 2, j + 6, k + 34, Blocks.venusBrick.blockID);
		world.setBlock(i + 2, j + 7, k + 0, Blocks.venusBrick.blockID);
		world.setBlock(i + 2, j + 7, k + 1, Blocks.venusBrick.blockID);
		world.setBlock(i + 2, j + 7, k + 2, Blocks.venusBrick.blockID);
		world.setBlock(i + 2, j + 7, k + 3, Blocks.venusBrick.blockID);
		world.setBlock(i + 2, j + 7, k + 4, Blocks.venusBrick.blockID);
		world.setBlock(i + 2, j + 7, k + 5, Blocks.venusBrick.blockID);
		world.setBlock(i + 2, j + 7, k + 6, Blocks.venusBrick.blockID);
		world.setBlock(i + 2, j + 7, k + 7, Blocks.venusBrick.blockID);
		world.setBlock(i + 2, j + 7, k + 8, Blocks.venusBrick.blockID);
		world.setBlock(i + 2, j + 7, k + 34, Blocks.venusBrick.blockID);
		world.setBlock(i + 2, j + 8, k + 0, Blocks.venusBrick.blockID);
		world.setBlock(i + 2, j + 8, k + 1, Blocks.venusBrick.blockID);
		world.setBlock(i + 2, j + 8, k + 2, Blocks.venusBrick.blockID);
		world.setBlock(i + 2, j + 8, k + 3, Blocks.venusBrick.blockID);
		world.setBlock(i + 2, j + 8, k + 4, Blocks.venusBrick.blockID);
		world.setBlock(i + 2, j + 8, k + 5, Blocks.venusBrick.blockID);
		world.setBlock(i + 2, j + 8, k + 6, Blocks.venusBrick.blockID);
		world.setBlock(i + 2, j + 8, k + 33, Blocks.venusBrick.blockID);
		world.setBlock(i + 2, j + 8, k + 34, Blocks.venusBrick.blockID);
		world.setBlock(i + 2, j + 9, k + 0, Blocks.venusBrick.blockID);
		world.setBlock(i + 2, j + 9, k + 1, Blocks.venusBrick.blockID);
		world.setBlock(i + 2, j + 9, k + 2, Blocks.venusBrick.blockID);
		world.setBlock(i + 2, j + 9, k + 3, Blocks.venusBrick.blockID);
		world.setBlock(i + 2, j + 9, k + 4, Blocks.venusBrick.blockID);
		world.setBlock(i + 2, j + 9, k + 5, Blocks.venusBrick.blockID);
		world.setBlock(i + 2, j + 9, k + 6, Blocks.venusBrick.blockID);
		world.setBlock(i + 2, j + 9, k + 32, Blocks.venusBrick.blockID);
		world.setBlock(i + 2, j + 9, k + 33, Blocks.venusBrick.blockID);
		world.setBlock(i + 2, j + 9, k + 34, Blocks.venusBrick.blockID);
		world.setBlock(i + 2, j + 10, k + 0, Blocks.venusBrick.blockID);
		world.setBlock(i + 2, j + 10, k + 1, Blocks.venusBrick.blockID);
		world.setBlock(i + 2, j + 10, k + 2, Blocks.venusBrick.blockID);
		world.setBlock(i + 2, j + 10, k + 3, Blocks.venusBrick.blockID);
		world.setBlock(i + 2, j + 10, k + 4, Blocks.venusBrick.blockID);
		world.setBlock(i + 2, j + 10, k + 5, Blocks.venusBrick.blockID);
		world.setBlock(i + 2, j + 10, k + 6, Blocks.venusBrick.blockID);
		world.setBlock(i + 2, j + 10, k + 30, Blocks.venusBrick.blockID);
		world.setBlock(i + 2, j + 10, k + 31, Blocks.venusBrick.blockID);
		world.setBlock(i + 2, j + 10, k + 32, Blocks.venusBrick.blockID);
		world.setBlock(i + 2, j + 10, k + 33, Blocks.venusBrick.blockID);
		world.setBlock(i + 2, j + 10, k + 34, Blocks.venusBrick.blockID);
		world.setBlock(i + 2, j + 11, k + 0, Blocks.venusBrick.blockID);
		world.setBlock(i + 2, j + 11, k + 1, Blocks.venusBrick.blockID);
		world.setBlock(i + 2, j + 11, k + 2, Blocks.venusBrick.blockID);
		world.setBlock(i + 2, j + 11, k + 3, Blocks.venusBrick.blockID);
		world.setBlock(i + 2, j + 11, k + 4, Blocks.venusBrick.blockID);
		world.setBlock(i + 2, j + 11, k + 5, Blocks.venusBrick.blockID);
		world.setBlock(i + 2, j + 11, k + 6, Blocks.venusBrick.blockID);
		world.setBlock(i + 2, j + 11, k + 7, Blocks.venusBrick.blockID);
		world.setBlock(i + 2, j + 11, k + 8, Blocks.venusBrick.blockID);
		world.setBlock(i + 2, j + 11, k + 30, Blocks.venusBrick.blockID);
		world.setBlock(i + 2, j + 11, k + 31, Blocks.venusBrick.blockID);
		world.setBlock(i + 2, j + 11, k + 32, Blocks.venusBrick.blockID);
		world.setBlock(i + 2, j + 11, k + 33, Blocks.venusBrick.blockID);
		world.setBlock(i + 2, j + 11, k + 34, Blocks.venusBrick.blockID);
		world.setBlock(i + 3, j + 0, k + 0, Blocks.venusBrick.blockID);
		world.setBlock(i + 3, j + 0, k + 1, Blocks.venusBrick.blockID);
		world.setBlock(i + 3, j + 0, k + 2, Blocks.venusBrick.blockID);
		world.setBlock(i + 3, j + 0, k + 3, Blocks.venusBrick.blockID);
		world.setBlock(i + 3, j + 0, k + 4, Blocks.venusBrick.blockID);
		world.setBlock(i + 3, j + 0, k + 5, Blocks.venusBrick.blockID);
		world.setBlock(i + 3, j + 0, k + 6, Blocks.venusBrick.blockID);
		world.setBlock(i + 3, j + 0, k + 7, Blocks.venusBrick.blockID);
		world.setBlock(i + 3, j + 0, k + 8, Blocks.venusBrick.blockID);
		world.setBlock(i + 3, j + 0, k + 9, Blocks.venusBrick.blockID);
		world.setBlock(i + 3, j + 0, k + 10, Blocks.venusBrick.blockID);
		world.setBlock(i + 3, j + 0, k + 11, Blocks.venusBrick.blockID);
		world.setBlock(i + 3, j + 0, k + 12, Blocks.venusBrick.blockID);
		world.setBlock(i + 3, j + 0, k + 13, Blocks.venusBrick.blockID);
		world.setBlock(i + 3, j + 0, k + 14, Blocks.venusBrick.blockID);
		world.setBlock(i + 3, j + 0, k + 15, Blocks.venusBrick.blockID);
		world.setBlock(i + 3, j + 0, k + 16, Blocks.venusBrick.blockID);
		world.setBlock(i + 3, j + 0, k + 17, Blocks.venusBrick.blockID);
		world.setBlock(i + 3, j + 0, k + 18, Blocks.venusBrick.blockID);
		world.setBlock(i + 3, j + 0, k + 19, Blocks.venusBrick.blockID);
		world.setBlock(i + 3, j + 0, k + 20, Blocks.venusBrick.blockID);
		world.setBlock(i + 3, j + 0, k + 21, Blocks.venusBrick.blockID);
		world.setBlock(i + 3, j + 0, k + 22, Blocks.venusBrick.blockID);
		world.setBlock(i + 3, j + 0, k + 23, Blocks.venusBrick.blockID);
		world.setBlock(i + 3, j + 0, k + 24, Blocks.venusBrick.blockID);
		world.setBlock(i + 3, j + 0, k + 25, Blocks.venusBrick.blockID);
		world.setBlock(i + 3, j + 0, k + 26, Blocks.venusBrick.blockID);
		world.setBlock(i + 3, j + 0, k + 27, Blocks.venusBrick.blockID);
		world.setBlock(i + 3, j + 0, k + 28, Blocks.venusBrick.blockID);
		world.setBlock(i + 3, j + 0, k + 29, Blocks.venusBrick.blockID);
		world.setBlock(i + 3, j + 0, k + 30, Blocks.venusBrick.blockID);
		world.setBlock(i + 3, j + 0, k + 31, Blocks.venusBrick.blockID);
		world.setBlock(i + 3, j + 0, k + 32, Blocks.venusBrick.blockID);
		world.setBlock(i + 3, j + 0, k + 33, Blocks.venusBrick.blockID);
		world.setBlock(i + 3, j + 0, k + 34, Blocks.venusBrick.blockID);
		world.setBlock(i + 3, j + 1, k + 0, Blocks.venusBrick.blockID);
		world.setBlock(i + 3, j + 1, k + 1, Blocks.venusBrick.blockID);
		world.setBlock(i + 3, j + 1, k + 2, Blocks.venusBrick.blockID);
		world.setBlock(i + 3, j + 1, k + 3, Blocks.venusBrick.blockID);
		world.setBlock(i + 3, j + 1, k + 4, Blocks.venusBrick.blockID);
		world.setBlock(i + 3, j + 1, k + 5, Blocks.venusBrick.blockID);
		world.setBlock(i + 3, j + 1, k + 6, Blocks.venusBrick.blockID);
		world.setBlock(i + 3, j + 1, k + 7, Blocks.venusBrick.blockID);
		world.setBlock(i + 3, j + 1, k + 8, Blocks.venusBrick.blockID);
		world.setBlock(i + 3, j + 1, k + 9, Blocks.venusBrick.blockID);
		world.setBlock(i + 3, j + 1, k + 10, Blocks.venusBrick.blockID);
		world.setBlock(i + 3, j + 1, k + 11, Blocks.venusBrick.blockID);
		world.setBlock(i + 3, j + 1, k + 12, Blocks.venusBrick.blockID);
		world.setBlock(i + 3, j + 1, k + 13, Blocks.venusBrick.blockID);
		world.setBlock(i + 3, j + 1, k + 14, Blocks.venusBrick.blockID);
		world.setBlock(i + 3, j + 1, k + 15, Blocks.venusBrick.blockID);
		world.setBlock(i + 3, j + 1, k + 16, Blocks.venusBrick.blockID);
		world.setBlock(i + 3, j + 1, k + 17, Blocks.venusBrick.blockID);
		world.setBlock(i + 3, j + 1, k + 18, Blocks.venusBrick.blockID);
		world.setBlock(i + 3, j + 1, k + 19, Blocks.venusBrick.blockID);
		world.setBlock(i + 3, j + 1, k + 20, Blocks.venusBrick.blockID);
		world.setBlock(i + 3, j + 1, k + 21, Blocks.venusBrick.blockID);
		world.setBlock(i + 3, j + 1, k + 22, Blocks.venusBrick.blockID);
		world.setBlock(i + 3, j + 1, k + 23, Blocks.venusBrick.blockID);
		world.setBlock(i + 3, j + 1, k + 24, Blocks.venusBrick.blockID);
		world.setBlock(i + 3, j + 1, k + 25, Blocks.venusBrick.blockID);
		world.setBlock(i + 3, j + 1, k + 26, Blocks.venusBrick.blockID);
		world.setBlock(i + 3, j + 1, k + 27, Blocks.venusBrick.blockID);
		world.setBlock(i + 3, j + 1, k + 28, Blocks.venusBrick.blockID);
		world.setBlock(i + 3, j + 1, k + 29, Blocks.venusBrick.blockID);
		world.setBlock(i + 3, j + 1, k + 30, Blocks.venusBrick.blockID);
		world.setBlock(i + 3, j + 1, k + 31, Blocks.venusBrick.blockID);
		world.setBlock(i + 3, j + 1, k + 32, Blocks.venusBrick.blockID);
		world.setBlock(i + 3, j + 1, k + 33, Blocks.venusBrick.blockID);
		world.setBlock(i + 3, j + 1, k + 34, Blocks.venusBrick.blockID);
		world.setBlock(i + 3, j + 2, k + 0, Blocks.venusBrick.blockID);
		world.setBlock(i + 3, j + 2, k + 1, Blocks.venusBrick.blockID);
		world.setBlock(i + 3, j + 2, k + 2, Blocks.venusBrick.blockID);
		world.setBlock(i + 3, j + 2, k + 3, Blocks.venusBrick.blockID);
		world.setBlock(i + 3, j + 2, k + 4, Blocks.venusBrick.blockID);
		world.setBlock(i + 3, j + 2, k + 5, Blocks.venusBrick.blockID);
		world.setBlock(i + 3, j + 2, k + 6, Blocks.venusBrick.blockID);
		world.setBlock(i + 3, j + 2, k + 7, Blocks.venusBrick.blockID);
		world.setBlock(i + 3, j + 2, k + 8, Blocks.venusBrick.blockID);
		world.setBlock(i + 3, j + 2, k + 9, Blocks.venusBrick.blockID);
		world.setBlock(i + 3, j + 2, k + 10, Blocks.venusBrick.blockID);
		world.setBlock(i + 3, j + 2, k + 11, Blocks.venusBrick.blockID);
		world.setBlock(i + 3, j + 2, k + 12, Blocks.venusBrick.blockID);
		world.setBlock(i + 3, j + 2, k + 13, Blocks.venusBrick.blockID);
		world.setBlock(i + 3, j + 2, k + 14, Blocks.venusBrick.blockID);
		world.setBlock(i + 3, j + 2, k + 15, Blocks.venusBrick.blockID);
		world.setBlock(i + 3, j + 2, k + 16, Blocks.venusBrick.blockID);
		world.setBlock(i + 3, j + 2, k + 17, Blocks.venusBrick.blockID);
		world.setBlock(i + 3, j + 2, k + 18, Blocks.venusBrick.blockID);
		world.setBlock(i + 3, j + 2, k + 19, Blocks.venusBrick.blockID);
		world.setBlock(i + 3, j + 2, k + 20, Blocks.venusBrick.blockID);
		world.setBlock(i + 3, j + 2, k + 21, Blocks.venusBrick.blockID);
		world.setBlock(i + 3, j + 2, k + 22, Blocks.venusBrick.blockID);
		world.setBlock(i + 3, j + 2, k + 23, Blocks.venusBrick.blockID);
		world.setBlock(i + 3, j + 2, k + 24, Blocks.venusBrick.blockID);
		world.setBlock(i + 3, j + 2, k + 25, Blocks.venusBrick.blockID);
		world.setBlock(i + 3, j + 2, k + 26, Blocks.venusBrick.blockID);
		world.setBlock(i + 3, j + 2, k + 27, Blocks.venusBrick.blockID);
		world.setBlock(i + 3, j + 2, k + 28, Blocks.venusBrick.blockID);
		world.setBlock(i + 3, j + 2, k + 29, Blocks.venusBrick.blockID);
		world.setBlock(i + 3, j + 2, k + 30, Blocks.venusBrick.blockID);
		world.setBlock(i + 3, j + 2, k + 31, Blocks.venusBrick.blockID);
		world.setBlock(i + 3, j + 2, k + 32, Blocks.venusBrick.blockID);
		world.setBlock(i + 3, j + 2, k + 33, Blocks.venusBrick.blockID);
		world.setBlock(i + 3, j + 2, k + 34, Blocks.venusBrick.blockID);
		world.setBlock(i + 3, j + 3, k + 0, Blocks.venusBrick.blockID);
		world.setBlock(i + 3, j + 3, k + 1, Blocks.venusBrick.blockID);
		world.setBlock(i + 3, j + 3, k + 2, Blocks.venusBrick.blockID);
		world.setBlock(i + 3, j + 3, k + 3, Blocks.venusBrick.blockID);
		world.setBlock(i + 3, j + 3, k + 4, Blocks.venusBrick.blockID);
		world.setBlock(i + 3, j + 3, k + 5, Blocks.venusBrick.blockID);
		world.setBlock(i + 3, j + 3, k + 6, Blocks.venusBrick.blockID);
		world.setBlock(i + 3, j + 3, k + 7, Blocks.venusBrick.blockID);
		world.setBlock(i + 3, j + 3, k + 8, Blocks.venusBrick.blockID);
		world.setBlock(i + 3, j + 3, k + 9, Blocks.venusBrick.blockID);
		world.setBlock(i + 3, j + 3, k + 10, Blocks.venusBrick.blockID);
		world.setBlock(i + 3, j + 3, k + 11, Blocks.venusBrick.blockID);
		world.setBlock(i + 3, j + 3, k + 12, Blocks.venusBrick.blockID);
		world.setBlock(i + 3, j + 3, k + 13, Blocks.venusBrick.blockID);
		world.setBlock(i + 3, j + 3, k + 14, Blocks.venusBrick.blockID);
		world.setBlock(i + 3, j + 3, k + 15, Blocks.venusBrick.blockID);
		world.setBlock(i + 3, j + 3, k + 16, Blocks.venusBrick.blockID);
		world.setBlock(i + 3, j + 3, k + 17, Blocks.venusBrick.blockID);
		world.setBlock(i + 3, j + 3, k + 18, Blocks.venusBrick.blockID);
		world.setBlock(i + 3, j + 3, k + 19, Blocks.venusBrick.blockID);
		world.setBlock(i + 3, j + 3, k + 20, Blocks.venusBrick.blockID);
		world.setBlock(i + 3, j + 3, k + 21, Blocks.venusBrick.blockID);
		world.setBlock(i + 3, j + 3, k + 27, Blocks.venusBrick.blockID);
		world.setBlock(i + 3, j + 3, k + 28, Blocks.venusBrick.blockID);
		world.setBlock(i + 3, j + 3, k + 29, Blocks.venusBrick.blockID);
		world.setBlock(i + 3, j + 3, k + 30, Blocks.venusBrick.blockID);
		world.setBlock(i + 3, j + 3, k + 31, Blocks.venusBrick.blockID);
		world.setBlock(i + 3, j + 3, k + 32, Blocks.venusBrick.blockID);
		world.setBlock(i + 3, j + 3, k + 33, Blocks.venusBrick.blockID);
		world.setBlock(i + 3, j + 3, k + 34, Blocks.venusBrick.blockID);
		int chestRand = (int) (Math.random() * Math.floor(2));
		boolean isBigChest = (chestRand == 1) ? true : false;
		if (randInt <= 10) {
			Treasures.spawnChest(world, rand, i + 3, j + 3, k + 35,
					isBigChest,
					Treasures.pickChestType());
		}
		world.setBlock(i + 3, j + 4, k + 0, Blocks.venusBrick.blockID);
		world.setBlock(i + 3, j + 4, k + 1, Blocks.venusBrick.blockID);
		world.setBlock(i + 3, j + 4, k + 2, Blocks.venusBrick.blockID);
		world.setBlock(i + 3, j + 4, k + 3, Blocks.venusBrick.blockID);
		world.setBlock(i + 3, j + 4, k + 4, Blocks.venusBrick.blockID);
		world.setBlock(i + 3, j + 4, k + 5, Blocks.venusBrick.blockID);
		world.setBlock(i + 3, j + 4, k + 6, Blocks.venusBrick.blockID);
		world.setBlock(i + 3, j + 4, k + 7, Blocks.venusBrick.blockID);
		world.setBlock(i + 3, j + 4, k + 8, Blocks.venusBrick.blockID);
		world.setBlock(i + 3, j + 4, k + 9, Blocks.venusBrick.blockID);
		world.setBlock(i + 3, j + 4, k + 10, Blocks.venusBrick.blockID);
		world.setBlock(i + 3, j + 4, k + 11, Blocks.venusBrick.blockID);
		world.setBlock(i + 3, j + 4, k + 12, Blocks.venusBrick.blockID);
		world.setBlock(i + 3, j + 4, k + 13, Blocks.venusBrick.blockID);
		world.setBlock(i + 3, j + 4, k + 14, Blocks.venusBrick.blockID);
		world.setBlock(i + 3, j + 4, k + 15, Blocks.venusBrick.blockID);
		world.setBlock(i + 3, j + 4, k + 16, Blocks.venusBrick.blockID);
		world.setBlock(i + 3, j + 4, k + 31, Blocks.venusBrick.blockID);
		world.setBlock(i + 3, j + 4, k + 32, Blocks.venusBrick.blockID);
		world.setBlock(i + 3, j + 4, k + 33, Blocks.venusBrick.blockID);
		world.setBlock(i + 3, j + 4, k + 34, Blocks.venusBrick.blockID);
		world.setBlock(i + 3, j + 5, k + 0, Blocks.venusBrick.blockID);
		world.setBlock(i + 3, j + 5, k + 1, Blocks.venusBrick.blockID);
		world.setBlock(i + 3, j + 5, k + 2, Blocks.venusBrick.blockID);
		world.setBlock(i + 3, j + 5, k + 3, Blocks.venusBrick.blockID);
		world.setBlock(i + 3, j + 5, k + 4, Blocks.venusBrick.blockID);
		world.setBlock(i + 3, j + 5, k + 5, Blocks.venusBrick.blockID);
		world.setBlock(i + 3, j + 5, k + 6, Blocks.venusBrick.blockID);
		world.setBlock(i + 3, j + 5, k + 7, Blocks.venusBrick.blockID);
		world.setBlock(i + 3, j + 5, k + 8, Blocks.venusBrick.blockID);
		world.setBlock(i + 3, j + 5, k + 9, Blocks.venusBrick.blockID);
		world.setBlock(i + 3, j + 5, k + 10, Blocks.venusBrick.blockID);
		world.setBlock(i + 3, j + 5, k + 11, Blocks.venusBrick.blockID);
		world.setBlock(i + 3, j + 5, k + 12, Blocks.venusBrick.blockID);
		world.setBlock(i + 3, j + 5, k + 13, Blocks.venusBrick.blockID);
		world.setBlock(i + 3, j + 5, k + 14, Blocks.venusBrick.blockID);
		world.setBlock(i + 3, j + 5, k + 33, Blocks.venusBrick.blockID);
		world.setBlock(i + 3, j + 5, k + 34, Blocks.venusBrick.blockID);
		world.setBlock(i + 3, j + 6, k + 0, Blocks.venusBrick.blockID);
		world.setBlock(i + 3, j + 6, k + 1, Blocks.venusBrick.blockID);
		world.setBlock(i + 3, j + 6, k + 2, Blocks.venusBrick.blockID);
		world.setBlock(i + 3, j + 6, k + 3, Blocks.venusBrick.blockID);
		world.setBlock(i + 3, j + 6, k + 4, Blocks.venusBrick.blockID);
		world.setBlock(i + 3, j + 6, k + 5, Blocks.venusBrick.blockID);
		world.setBlock(i + 3, j + 6, k + 6, Blocks.venusBrick.blockID);
		world.setBlock(i + 3, j + 6, k + 7, Blocks.venusBrick.blockID);
		world.setBlock(i + 3, j + 6, k + 8, Blocks.venusBrick.blockID);
		world.setBlock(i + 3, j + 6, k + 9, Blocks.venusBrick.blockID);
		world.setBlock(i + 3, j + 6, k + 10, Blocks.venusBrick.blockID);
		world.setBlock(i + 3, j + 6, k + 11, Blocks.venusBrick.blockID);
		world.setBlock(i + 3, j + 6, k + 12, Blocks.venusBrick.blockID);
		world.setBlock(i + 3, j + 6, k + 13, Blocks.venusBrick.blockID);
		world.setBlock(i + 3, j + 6, k + 34, Blocks.venusBrick.blockID);
		world.setBlock(i + 3, j + 7, k + 0, Blocks.venusBrick.blockID);
		world.setBlock(i + 3, j + 7, k + 1, Blocks.venusBrick.blockID);
		world.setBlock(i + 3, j + 7, k + 2, Blocks.venusBrick.blockID);
		world.setBlock(i + 3, j + 7, k + 3, Blocks.venusBrick.blockID);
		world.setBlock(i + 3, j + 7, k + 4, Blocks.venusBrick.blockID);
		world.setBlock(i + 3, j + 7, k + 5, Blocks.venusBrick.blockID);
		world.setBlock(i + 3, j + 7, k + 6, Blocks.venusBrick.blockID);
		world.setBlock(i + 3, j + 7, k + 7, Blocks.venusBrick.blockID);
		world.setBlock(i + 3, j + 7, k + 8, Blocks.venusBrick.blockID);
		world.setBlock(i + 3, j + 7, k + 9, Blocks.venusBrick.blockID);
		world.setBlock(i + 3, j + 7, k + 33, Blocks.venusBrick.blockID);
		world.setBlock(i + 3, j + 7, k + 34, Blocks.venusBrick.blockID);
		world.setBlock(i + 3, j + 8, k + 0, Blocks.venusBrick.blockID);
		world.setBlock(i + 3, j + 8, k + 1, Blocks.venusBrick.blockID);
		world.setBlock(i + 3, j + 8, k + 2, Blocks.venusBrick.blockID);
		world.setBlock(i + 3, j + 8, k + 3, Blocks.venusBrick.blockID);
		world.setBlock(i + 3, j + 8, k + 4, Blocks.venusBrick.blockID);
		world.setBlock(i + 3, j + 8, k + 5, Blocks.venusBrick.blockID);
		world.setBlock(i + 3, j + 8, k + 6, Blocks.venusBrick.blockID);
		world.setBlock(i + 3, j + 8, k + 7, Blocks.venusBrick.blockID);
		world.setBlock(i + 3, j + 8, k + 31, Blocks.venusBrick.blockID);
		world.setBlock(i + 3, j + 8, k + 32, Blocks.venusBrick.blockID);
		world.setBlock(i + 3, j + 8, k + 33, Blocks.venusBrick.blockID);
		world.setBlock(i + 3, j + 8, k + 34, Blocks.venusBrick.blockID);
		world.setBlock(i + 3, j + 9, k + 0, Blocks.venusBrick.blockID);
		world.setBlock(i + 3, j + 9, k + 1, Blocks.venusBrick.blockID);
		world.setBlock(i + 3, j + 9, k + 2, Blocks.venusBrick.blockID);
		world.setBlock(i + 3, j + 9, k + 3, Blocks.venusBrick.blockID);
		world.setBlock(i + 3, j + 9, k + 4, Blocks.venusBrick.blockID);
		world.setBlock(i + 3, j + 9, k + 5, Blocks.venusBrick.blockID);
		world.setBlock(i + 3, j + 9, k + 6, Blocks.venusBrick.blockID);
		world.setBlock(i + 3, j + 9, k + 30, Blocks.venusBrick.blockID);
		world.setBlock(i + 3, j + 9, k + 31, Blocks.venusBrick.blockID);
		world.setBlock(i + 3, j + 9, k + 32, Blocks.venusBrick.blockID);
		world.setBlock(i + 3, j + 9, k + 33, Blocks.venusBrick.blockID);
		world.setBlock(i + 3, j + 9, k + 34, Blocks.venusBrick.blockID);
		world.setBlock(i + 3, j + 10, k + 0, Blocks.venusBrick.blockID);
		world.setBlock(i + 3, j + 10, k + 1, Blocks.venusBrick.blockID);
		world.setBlock(i + 3, j + 10, k + 2, Blocks.venusBrick.blockID);
		world.setBlock(i + 3, j + 10, k + 3, Blocks.venusBrick.blockID);
		world.setBlock(i + 3, j + 10, k + 4, Blocks.venusBrick.blockID);
		world.setBlock(i + 3, j + 10, k + 5, Blocks.venusBrick.blockID);
		world.setBlock(i + 3, j + 10, k + 6, Blocks.venusBrick.blockID);
		world.setBlock(i + 3, j + 10, k + 7, Blocks.venusBrick.blockID);
		world.setBlock(i + 3, j + 10, k + 30, Blocks.venusBrick.blockID);
		world.setBlock(i + 3, j + 10, k + 31, Blocks.venusBrick.blockID);
		world.setBlock(i + 3, j + 10, k + 32, Blocks.venusBrick.blockID);
		world.setBlock(i + 3, j + 10, k + 33, Blocks.venusBrick.blockID);
		world.setBlock(i + 3, j + 10, k + 34, Blocks.venusBrick.blockID);
		world.setBlock(i + 3, j + 11, k + 0, Blocks.venusBrick.blockID);
		world.setBlock(i + 3, j + 11, k + 1, Blocks.venusBrick.blockID);
		world.setBlock(i + 3, j + 11, k + 2, Blocks.venusBrick.blockID);
		world.setBlock(i + 3, j + 11, k + 3, Blocks.venusBrick.blockID);
		world.setBlock(i + 3, j + 11, k + 4, Blocks.venusBrick.blockID);
		world.setBlock(i + 3, j + 11, k + 5, Blocks.venusBrick.blockID);
		world.setBlock(i + 3, j + 11, k + 6, Blocks.venusBrick.blockID);
		world.setBlock(i + 3, j + 11, k + 7, Blocks.venusBrick.blockID);
		world.setBlock(i + 3, j + 11, k + 8, Blocks.venusBrick.blockID);
		world.setBlock(i + 3, j + 11, k + 9, Blocks.venusBrick.blockID);
		world.setBlock(i + 3, j + 11, k + 30, Blocks.venusBrick.blockID);
		world.setBlock(i + 3, j + 11, k + 31, Blocks.venusBrick.blockID);
		world.setBlock(i + 3, j + 11, k + 32, Blocks.venusBrick.blockID);
		world.setBlock(i + 3, j + 11, k + 33, Blocks.venusBrick.blockID);
		world.setBlock(i + 3, j + 11, k + 34, Blocks.venusBrick.blockID);
		world.setBlock(i + 4, j + 0, k + 0, Blocks.venusBrick.blockID);
		world.setBlock(i + 4, j + 0, k + 1, Blocks.venusBrick.blockID);
		world.setBlock(i + 4, j + 0, k + 2, Blocks.venusBrick.blockID);
		world.setBlock(i + 4, j + 0, k + 3, Blocks.venusBrick.blockID);
		world.setBlock(i + 4, j + 0, k + 4, Blocks.venusBrick.blockID);
		world.setBlock(i + 4, j + 0, k + 5, Blocks.venusBrick.blockID);
		world.setBlock(i + 4, j + 0, k + 6, Blocks.venusBrick.blockID);
		world.setBlock(i + 4, j + 0, k + 7, Blocks.venusBrick.blockID);
		world.setBlock(i + 4, j + 0, k + 8, Blocks.venusBrick.blockID);
		world.setBlock(i + 4, j + 0, k + 9, Blocks.venusBrick.blockID);
		world.setBlock(i + 4, j + 0, k + 10, Blocks.venusBrick.blockID);
		world.setBlock(i + 4, j + 0, k + 11, Blocks.venusBrick.blockID);
		world.setBlock(i + 4, j + 0, k + 12, Blocks.venusBrick.blockID);
		world.setBlock(i + 4, j + 0, k + 13, Blocks.venusBrick.blockID);
		world.setBlock(i + 4, j + 0, k + 14, Blocks.venusBrick.blockID);
		world.setBlock(i + 4, j + 0, k + 15, Blocks.venusBrick.blockID);
		world.setBlock(i + 4, j + 0, k + 16, Blocks.venusBrick.blockID);
		world.setBlock(i + 4, j + 0, k + 17, Blocks.venusBrick.blockID);
		world.setBlock(i + 4, j + 0, k + 18, Blocks.venusBrick.blockID);
		world.setBlock(i + 4, j + 0, k + 19, Blocks.venusBrick.blockID);
		world.setBlock(i + 4, j + 0, k + 20, Blocks.venusBrick.blockID);
		world.setBlock(i + 4, j + 0, k + 21, Blocks.venusBrick.blockID);
		world.setBlock(i + 4, j + 0, k + 22, Blocks.venusBrick.blockID);
		world.setBlock(i + 4, j + 0, k + 23, Blocks.venusBrick.blockID);
		world.setBlock(i + 4, j + 0, k + 24, Blocks.venusBrick.blockID);
		world.setBlock(i + 4, j + 0, k + 25, Blocks.venusBrick.blockID);
		world.setBlock(i + 4, j + 0, k + 26, Blocks.venusBrick.blockID);
		world.setBlock(i + 4, j + 0, k + 27, Blocks.venusBrick.blockID);
		world.setBlock(i + 4, j + 0, k + 28, Blocks.venusBrick.blockID);
		world.setBlock(i + 4, j + 0, k + 29, Blocks.venusBrick.blockID);
		world.setBlock(i + 4, j + 0, k + 30, Blocks.venusBrick.blockID);
		world.setBlock(i + 4, j + 0, k + 31, Blocks.venusBrick.blockID);
		world.setBlock(i + 4, j + 0, k + 32, Blocks.venusBrick.blockID);
		world.setBlock(i + 4, j + 0, k + 33, Blocks.venusBrick.blockID);
		world.setBlock(i + 4, j + 0, k + 34, Blocks.venusBrick.blockID);
		world.setBlock(i + 4, j + 1, k + 0, Blocks.venusBrick.blockID);
		world.setBlock(i + 4, j + 1, k + 1, Blocks.venusBrick.blockID);
		world.setBlock(i + 4, j + 1, k + 2, Blocks.venusBrick.blockID);
		world.setBlock(i + 4, j + 1, k + 3, Blocks.venusBrick.blockID);
		world.setBlock(i + 4, j + 1, k + 4, Blocks.venusBrick.blockID);
		world.setBlock(i + 4, j + 1, k + 5, Blocks.venusBrick.blockID);
		world.setBlock(i + 4, j + 1, k + 6, Blocks.venusBrick.blockID);
		world.setBlock(i + 4, j + 1, k + 7, Blocks.venusBrick.blockID);
		world.setBlock(i + 4, j + 1, k + 8, Blocks.venusBrick.blockID);
		world.setBlock(i + 4, j + 1, k + 9, Blocks.venusBrick.blockID);
		world.setBlock(i + 4, j + 1, k + 10, Blocks.venusBrick.blockID);
		world.setBlock(i + 4, j + 1, k + 11, Blocks.venusBrick.blockID);
		world.setBlock(i + 4, j + 1, k + 12, Blocks.venusBrick.blockID);
		world.setBlock(i + 4, j + 1, k + 13, Blocks.venusBrick.blockID);
		world.setBlock(i + 4, j + 1, k + 14, Blocks.venusBrick.blockID);
		world.setBlock(i + 4, j + 1, k + 15, Blocks.venusBrick.blockID);
		world.setBlock(i + 4, j + 1, k + 16, Blocks.venusBrick.blockID);
		world.setBlock(i + 4, j + 1, k + 17, Blocks.venusBrick.blockID);
		world.setBlock(i + 4, j + 1, k + 18, Blocks.venusBrick.blockID);
		world.setBlock(i + 4, j + 1, k + 19, Blocks.venusBrick.blockID);
		world.setBlock(i + 4, j + 1, k + 20, Blocks.venusBrick.blockID);
		world.setBlock(i + 4, j + 1, k + 21, Blocks.venusBrick.blockID);
		world.setBlock(i + 4, j + 1, k + 22, Blocks.venusBrick.blockID);
		world.setBlock(i + 4, j + 1, k + 23, Blocks.venusBrick.blockID);
		world.setBlock(i + 4, j + 1, k + 24, Blocks.venusBrick.blockID);
		world.setBlock(i + 4, j + 1, k + 25, Blocks.venusBrick.blockID);
		world.setBlock(i + 4, j + 1, k + 26, Blocks.venusBrick.blockID);
		world.setBlock(i + 4, j + 1, k + 27, Blocks.venusBrick.blockID);
		world.setBlock(i + 4, j + 1, k + 28, Blocks.venusBrick.blockID);
		world.setBlock(i + 4, j + 1, k + 29, Blocks.venusBrick.blockID);
		world.setBlock(i + 4, j + 1, k + 30, Blocks.venusBrick.blockID);
		world.setBlock(i + 4, j + 1, k + 31, Blocks.venusBrick.blockID);
		world.setBlock(i + 4, j + 1, k + 32, Blocks.venusBrick.blockID);
		world.setBlock(i + 4, j + 1, k + 33, Blocks.venusBrick.blockID);
		world.setBlock(i + 4, j + 1, k + 34, Blocks.venusBrick.blockID);
		world.setBlock(i + 4, j + 2, k + 0, Blocks.venusBrick.blockID);
		world.setBlock(i + 4, j + 2, k + 1, Blocks.venusBrick.blockID);
		world.setBlock(i + 4, j + 2, k + 2, Blocks.venusBrick.blockID);
		world.setBlock(i + 4, j + 2, k + 3, Blocks.venusBrick.blockID);
		world.setBlock(i + 4, j + 2, k + 4, Blocks.venusBrick.blockID);
		world.setBlock(i + 4, j + 2, k + 5, Blocks.venusBrick.blockID);
		world.setBlock(i + 4, j + 2, k + 6, Blocks.venusBrick.blockID);
		world.setBlock(i + 4, j + 2, k + 7, Blocks.venusBrick.blockID);
		world.setBlock(i + 4, j + 2, k + 8, Blocks.venusBrick.blockID);
		world.setBlock(i + 4, j + 2, k + 9, Blocks.venusBrick.blockID);
		world.setBlock(i + 4, j + 2, k + 10, Blocks.venusBrick.blockID);
		world.setBlock(i + 4, j + 2, k + 11, Blocks.venusBrick.blockID);
		world.setBlock(i + 4, j + 2, k + 12, Blocks.venusBrick.blockID);
		world.setBlock(i + 4, j + 2, k + 13, Blocks.venusBrick.blockID);
		world.setBlock(i + 4, j + 2, k + 14, Blocks.venusBrick.blockID);
		world.setBlock(i + 4, j + 2, k + 15, Blocks.venusBrick.blockID);
		world.setBlock(i + 4, j + 2, k + 16, Blocks.venusBrick.blockID);
		world.setBlock(i + 4, j + 2, k + 17, Blocks.venusBrick.blockID);
		world.setBlock(i + 4, j + 2, k + 18, Blocks.venusBrick.blockID);
		world.setBlock(i + 4, j + 2, k + 19, Blocks.venusBrick.blockID);
		world.setBlock(i + 4, j + 2, k + 20, Blocks.venusBrick.blockID);
		world.setBlock(i + 4, j + 2, k + 21, Blocks.venusBrick.blockID);
		world.setBlock(i + 4, j + 2, k + 22, Blocks.venusBrick.blockID);
		world.setBlock(i + 4, j + 2, k + 23, Blocks.venusBrick.blockID);
		world.setBlock(i + 4, j + 2, k + 24, Blocks.venusBrick.blockID);
		world.setBlock(i + 4, j + 2, k + 25, Blocks.venusBrick.blockID);
		world.setBlock(i + 4, j + 2, k + 26, Blocks.venusBrick.blockID);
		world.setBlock(i + 4, j + 2, k + 27, Blocks.venusBrick.blockID);
		world.setBlock(i + 4, j + 2, k + 28, Blocks.venusBrick.blockID);
		world.setBlock(i + 4, j + 2, k + 29, Blocks.venusBrick.blockID);
		world.setBlock(i + 4, j + 2, k + 30, Blocks.venusBrick.blockID);
		world.setBlock(i + 4, j + 2, k + 31, Blocks.venusBrick.blockID);
		world.setBlock(i + 4, j + 2, k + 32, Blocks.venusBrick.blockID);
		world.setBlock(i + 4, j + 2, k + 33, Blocks.venusBrick.blockID);
		world.setBlock(i + 4, j + 2, k + 34, Blocks.venusBrick.blockID);
		world.setBlock(i + 4, j + 3, k + 0, Blocks.venusBrick.blockID);
		world.setBlock(i + 4, j + 3, k + 1, Blocks.venusBrick.blockID);
		world.setBlock(i + 4, j + 3, k + 2, Blocks.venusBrick.blockID);
		world.setBlock(i + 4, j + 3, k + 3, Blocks.venusBrick.blockID);
		world.setBlock(i + 4, j + 3, k + 4, Blocks.venusBrick.blockID);
		world.setBlock(i + 4, j + 3, k + 5, Blocks.venusBrick.blockID);
		world.setBlock(i + 4, j + 3, k + 6, Blocks.venusBrick.blockID);
		world.setBlock(i + 4, j + 3, k + 7, Blocks.venusBrick.blockID);
		world.setBlock(i + 4, j + 3, k + 8, Blocks.venusBrick.blockID);
		world.setBlock(i + 4, j + 3, k + 9, Blocks.venusBrick.blockID);
		world.setBlock(i + 4, j + 3, k + 10, Blocks.venusBrick.blockID);
		world.setBlock(i + 4, j + 3, k + 11, Blocks.venusBrick.blockID);
		world.setBlock(i + 4, j + 3, k + 12, Blocks.venusBrick.blockID);
		world.setBlock(i + 4, j + 3, k + 13, Blocks.venusBrick.blockID);
		world.setBlock(i + 4, j + 3, k + 14, Blocks.venusBrick.blockID);
		world.setBlock(i + 4, j + 3, k + 15, Blocks.venusBrick.blockID);
		world.setBlock(i + 4, j + 3, k + 16, Blocks.venusBrick.blockID);
		world.setBlock(i + 4, j + 3, k + 17, Blocks.venusBrick.blockID);
		world.setBlock(i + 4, j + 3, k + 18, Blocks.venusBrick.blockID);
		world.setBlock(i + 4, j + 3, k + 19, Blocks.venusBrick.blockID);
		world.setBlock(i + 4, j + 3, k + 20, Blocks.venusBrick.blockID);
		world.setBlock(i + 4, j + 3, k + 28, Blocks.venusBrick.blockID);
		world.setBlock(i + 4, j + 3, k + 29, Blocks.venusBrick.blockID);
		world.setBlock(i + 4, j + 3, k + 30, Blocks.venusBrick.blockID);
		world.setBlock(i + 4, j + 3, k + 31, Blocks.venusBrick.blockID);
		world.setBlock(i + 4, j + 3, k + 32, Blocks.venusBrick.blockID);
		world.setBlock(i + 4, j + 3, k + 33, Blocks.venusBrick.blockID);
		world.setBlock(i + 4, j + 3, k + 34, Blocks.venusBrick.blockID);
		world.setBlock(i + 4, j + 4, k + 0, Blocks.venusBrick.blockID);
		world.setBlock(i + 4, j + 4, k + 1, Blocks.venusBrick.blockID);
		world.setBlock(i + 4, j + 4, k + 2, Blocks.venusBrick.blockID);
		world.setBlock(i + 4, j + 4, k + 3, Blocks.venusBrick.blockID);
		world.setBlock(i + 4, j + 4, k + 4, Blocks.venusBrick.blockID);
		world.setBlock(i + 4, j + 4, k + 5, Blocks.venusBrick.blockID);
		world.setBlock(i + 4, j + 4, k + 6, Blocks.venusBrick.blockID);
		world.setBlock(i + 4, j + 4, k + 7, Blocks.venusBrick.blockID);
		world.setBlock(i + 4, j + 4, k + 8, Blocks.venusBrick.blockID);
		world.setBlock(i + 4, j + 4, k + 9, Blocks.venusBrick.blockID);
		world.setBlock(i + 4, j + 4, k + 10, Blocks.venusBrick.blockID);
		world.setBlock(i + 4, j + 4, k + 11, Blocks.venusBrick.blockID);
		world.setBlock(i + 4, j + 4, k + 12, Blocks.venusBrick.blockID);
		world.setBlock(i + 4, j + 4, k + 13, Blocks.venusBrick.blockID);
		world.setBlock(i + 4, j + 4, k + 14, Blocks.venusBrick.blockID);
		world.setBlock(i + 4, j + 4, k + 15, Blocks.venusBrick.blockID);
		world.setBlock(i + 4, j + 4, k + 16, Blocks.venusBrick.blockID);
		world.setBlock(i + 4, j + 4, k + 17, Blocks.venusBrick.blockID);
		world.setBlock(i + 4, j + 4, k + 18, Blocks.venusBrick.blockID);
		world.setBlock(i + 4, j + 4, k + 30, Blocks.venusBrick.blockID);
		world.setBlock(i + 4, j + 4, k + 31, Blocks.venusBrick.blockID);
		world.setBlock(i + 4, j + 4, k + 32, Blocks.venusBrick.blockID);
		world.setBlock(i + 4, j + 4, k + 33, Blocks.venusBrick.blockID);
		world.setBlock(i + 4, j + 4, k + 34, Blocks.venusBrick.blockID);
		world.setBlock(i + 4, j + 5, k + 16, Blocks.venusBrick.blockID);
		world.setBlock(i + 4, j + 5, k + 32, Blocks.venusBrick.blockID);
		world.setBlock(i + 4, j + 5, k + 33, Blocks.venusBrick.blockID);
		world.setBlock(i + 4, j + 5, k + 34, Blocks.venusBrick.blockID);
		world.setBlock(i + 4, j + 6, k + 32, Blocks.venusBrick.blockID);
		world.setBlock(i + 4, j + 6, k + 33, Blocks.venusBrick.blockID);
		world.setBlock(i + 4, j + 6, k + 34, Blocks.venusBrick.blockID);
		world.setBlock(i + 4, j + 7, k + 32, Blocks.venusBrick.blockID);
		world.setBlock(i + 4, j + 7, k + 33, Blocks.venusBrick.blockID);
		world.setBlock(i + 4, j + 7, k + 34, Blocks.venusBrick.blockID);
		world.setBlock(i + 4, j + 8, k + 0, Blocks.venusBrick.blockID);
		world.setBlock(i + 4, j + 8, k + 1, Blocks.venusBrick.blockID);
		world.setBlock(i + 4, j + 8, k + 2, Blocks.venusBrick.blockID);
		world.setBlock(i + 4, j + 8, k + 3, Blocks.venusBrick.blockID);
		world.setBlock(i + 4, j + 8, k + 4, Blocks.venusBrick.blockID);
		world.setBlock(i + 4, j + 8, k + 5, Blocks.venusBrick.blockID);
		world.setBlock(i + 4, j + 8, k + 6, Blocks.venusBrick.blockID);
		world.setBlock(i + 4, j + 8, k + 7, Blocks.venusBrick.blockID);
		world.setBlock(i + 4, j + 8, k + 8, Blocks.venusBrick.blockID);
		world.setBlock(i + 4, j + 8, k + 32, Blocks.venusBrick.blockID);
		world.setBlock(i + 4, j + 8, k + 33, Blocks.venusBrick.blockID);
		world.setBlock(i + 4, j + 8, k + 34, Blocks.venusBrick.blockID);
		world.setBlock(i + 4, j + 9, k + 0, Blocks.venusBrick.blockID);
		world.setBlock(i + 4, j + 9, k + 1, Blocks.venusBrick.blockID);
		world.setBlock(i + 4, j + 9, k + 2, Blocks.venusBrick.blockID);
		world.setBlock(i + 4, j + 9, k + 3, Blocks.venusBrick.blockID);
		world.setBlock(i + 4, j + 9, k + 4, Blocks.venusBrick.blockID);
		world.setBlock(i + 4, j + 9, k + 5, Blocks.venusBrick.blockID);
		world.setBlock(i + 4, j + 9, k + 6, Blocks.venusBrick.blockID);
		world.setBlock(i + 4, j + 9, k + 7, Blocks.venusBrick.blockID);
		world.setBlock(i + 4, j + 9, k + 8, Blocks.venusBrick.blockID);
		world.setBlock(i + 4, j + 9, k + 32, Blocks.venusBrick.blockID);
		world.setBlock(i + 4, j + 9, k + 33, Blocks.venusBrick.blockID);
		world.setBlock(i + 4, j + 9, k + 34, Blocks.venusBrick.blockID);
		world.setBlock(i + 4, j + 10, k + 0, Blocks.venusBrick.blockID);
		world.setBlock(i + 4, j + 10, k + 1, Blocks.venusBrick.blockID);
		world.setBlock(i + 4, j + 10, k + 2, Blocks.venusBrick.blockID);
		world.setBlock(i + 4, j + 10, k + 3, Blocks.venusBrick.blockID);
		world.setBlock(i + 4, j + 10, k + 4, Blocks.venusBrick.blockID);
		world.setBlock(i + 4, j + 10, k + 5, Blocks.venusBrick.blockID);
		world.setBlock(i + 4, j + 10, k + 6, Blocks.venusBrick.blockID);
		world.setBlock(i + 4, j + 10, k + 7, Blocks.venusBrick.blockID);
		world.setBlock(i + 4, j + 10, k + 8, Blocks.venusBrick.blockID);
		world.setBlock(i + 4, j + 10, k + 30, Blocks.venusBrick.blockID);
		world.setBlock(i + 4, j + 10, k + 31, Blocks.venusBrick.blockID);
		world.setBlock(i + 4, j + 10, k + 32, Blocks.venusBrick.blockID);
		world.setBlock(i + 4, j + 10, k + 33, Blocks.venusBrick.blockID);
		world.setBlock(i + 4, j + 10, k + 34, Blocks.venusBrick.blockID);
		world.setBlock(i + 4, j + 11, k + 0, Blocks.venusBrick.blockID);
		world.setBlock(i + 4, j + 11, k + 1, Blocks.venusBrick.blockID);
		world.setBlock(i + 4, j + 11, k + 2, Blocks.venusBrick.blockID);
		world.setBlock(i + 4, j + 11, k + 3, Blocks.venusBrick.blockID);
		world.setBlock(i + 4, j + 11, k + 4, Blocks.venusBrick.blockID);
		world.setBlock(i + 4, j + 11, k + 5, Blocks.venusBrick.blockID);
		world.setBlock(i + 4, j + 11, k + 6, Blocks.venusBrick.blockID);
		world.setBlock(i + 4, j + 11, k + 7, Blocks.venusBrick.blockID);
		world.setBlock(i + 4, j + 11, k + 8, Blocks.venusBrick.blockID);
		world.setBlock(i + 4, j + 11, k + 9, Blocks.venusBrick.blockID);
		world.setBlock(i + 4, j + 11, k + 30, Blocks.venusBrick.blockID);
		world.setBlock(i + 4, j + 11, k + 31, Blocks.venusBrick.blockID);
		world.setBlock(i + 4, j + 11, k + 32, Blocks.venusBrick.blockID);
		world.setBlock(i + 4, j + 11, k + 33, Blocks.venusBrick.blockID);
		world.setBlock(i + 4, j + 11, k + 34, Blocks.venusBrick.blockID);
		world.setBlock(i + 5, j + 0, k + 0, Blocks.venusBrick.blockID);
		world.setBlock(i + 5, j + 0, k + 1, Blocks.venusBrick.blockID);
		world.setBlock(i + 5, j + 0, k + 2, Blocks.venusBrick.blockID);
		world.setBlock(i + 5, j + 0, k + 3, Blocks.venusBrick.blockID);
		world.setBlock(i + 5, j + 0, k + 4, Blocks.venusBrick.blockID);
		world.setBlock(i + 5, j + 0, k + 5, Blocks.venusBrick.blockID);
		world.setBlock(i + 5, j + 0, k + 6, Blocks.venusBrick.blockID);
		world.setBlock(i + 5, j + 0, k + 7, Blocks.venusBrick.blockID);
		world.setBlock(i + 5, j + 0, k + 8, Blocks.venusBrick.blockID);
		world.setBlock(i + 5, j + 0, k + 9, Blocks.venusBrick.blockID);
		world.setBlock(i + 5, j + 0, k + 10, Blocks.venusBrick.blockID);
		world.setBlock(i + 5, j + 0, k + 11, Blocks.venusBrick.blockID);
		world.setBlock(i + 5, j + 0, k + 12, Blocks.venusBrick.blockID);
		world.setBlock(i + 5, j + 0, k + 13, Blocks.venusBrick.blockID);
		world.setBlock(i + 5, j + 0, k + 14, Blocks.venusBrick.blockID);
		world.setBlock(i + 5, j + 0, k + 15, Blocks.venusBrick.blockID);
		world.setBlock(i + 5, j + 0, k + 16, Blocks.venusBrick.blockID);
		world.setBlock(i + 5, j + 0, k + 17, Blocks.venusBrick.blockID);
		world.setBlock(i + 5, j + 0, k + 18, Blocks.venusBrick.blockID);
		world.setBlock(i + 5, j + 0, k + 19, Blocks.venusBrick.blockID);
		world.setBlock(i + 5, j + 0, k + 20, Blocks.venusBrick.blockID);
		world.setBlock(i + 5, j + 0, k + 21, Blocks.venusBrick.blockID);
		world.setBlock(i + 5, j + 0, k + 22, Blocks.venusBrick.blockID);
		world.setBlock(i + 5, j + 0, k + 23, Blocks.venusBrick.blockID);
		world.setBlock(i + 5, j + 0, k + 24, Blocks.venusBrick.blockID);
		world.setBlock(i + 5, j + 0, k + 25, Blocks.venusBrick.blockID);
		world.setBlock(i + 5, j + 0, k + 26, Blocks.venusBrick.blockID);
		world.setBlock(i + 5, j + 0, k + 27, Blocks.venusBrick.blockID);
		world.setBlock(i + 5, j + 0, k + 28, Blocks.venusBrick.blockID);
		world.setBlock(i + 5, j + 0, k + 29, Blocks.venusBrick.blockID);
		world.setBlock(i + 5, j + 0, k + 30, Blocks.venusBrick.blockID);
		world.setBlock(i + 5, j + 0, k + 31, Blocks.venusBrick.blockID);
		world.setBlock(i + 5, j + 0, k + 32, Blocks.venusBrick.blockID);
		world.setBlock(i + 5, j + 0, k + 33, Blocks.venusBrick.blockID);
		world.setBlock(i + 5, j + 0, k + 34, Blocks.venusBrick.blockID);
		world.setBlock(i + 5, j + 1, k + 0, Blocks.venusBrick.blockID);
		world.setBlock(i + 5, j + 1, k + 1, Blocks.venusBrick.blockID);
		world.setBlock(i + 5, j + 1, k + 2, Blocks.venusBrick.blockID);
		world.setBlock(i + 5, j + 1, k + 3, Blocks.venusBrick.blockID);
		world.setBlock(i + 5, j + 1, k + 4, Blocks.venusBrick.blockID);
		world.setBlock(i + 5, j + 1, k + 5, Blocks.venusBrick.blockID);
		world.setBlock(i + 5, j + 1, k + 6, Blocks.venusBrick.blockID);
		world.setBlock(i + 5, j + 1, k + 7, Blocks.venusBrick.blockID);
		world.setBlock(i + 5, j + 1, k + 8, Blocks.venusBrick.blockID);
		world.setBlock(i + 5, j + 1, k + 9, Blocks.venusBrick.blockID);
		world.setBlock(i + 5, j + 1, k + 10, Blocks.venusBrick.blockID);
		world.setBlock(i + 5, j + 1, k + 11, Blocks.venusBrick.blockID);
		world.setBlock(i + 5, j + 1, k + 12, Blocks.venusBrick.blockID);
		world.setBlock(i + 5, j + 1, k + 13, Blocks.venusBrick.blockID);
		world.setBlock(i + 5, j + 1, k + 14, Blocks.venusBrick.blockID);
		world.setBlock(i + 5, j + 1, k + 15, Blocks.venusBrick.blockID);
		world.setBlock(i + 5, j + 1, k + 16, Blocks.venusBrick.blockID);
		world.setBlock(i + 5, j + 1, k + 17, Blocks.venusBrick.blockID);
		world.setBlock(i + 5, j + 1, k + 18, Blocks.venusBrick.blockID);
		world.setBlock(i + 5, j + 1, k + 19, Blocks.venusBrick.blockID);
		world.setBlock(i + 5, j + 1, k + 20, Blocks.venusBrick.blockID);
		world.setBlock(i + 5, j + 1, k + 21, Blocks.venusBrick.blockID);
		world.setBlock(i + 5, j + 1, k + 22, Blocks.venusBrick.blockID);
		world.setBlock(i + 5, j + 1, k + 23, Blocks.venusBrick.blockID);
		world.setBlock(i + 5, j + 1, k + 24, Blocks.venusBrick.blockID);
		world.setBlock(i + 5, j + 1, k + 25, Blocks.venusBrick.blockID);
		world.setBlock(i + 5, j + 1, k + 26, Blocks.venusBrick.blockID);
		world.setBlock(i + 5, j + 1, k + 27, Blocks.venusBrick.blockID);
		world.setBlock(i + 5, j + 1, k + 28, Blocks.venusBrick.blockID);
		world.setBlock(i + 5, j + 1, k + 29, Blocks.venusBrick.blockID);
		world.setBlock(i + 5, j + 1, k + 30, Blocks.venusBrick.blockID);
		world.setBlock(i + 5, j + 1, k + 31, Blocks.venusBrick.blockID);
		world.setBlock(i + 5, j + 1, k + 32, Blocks.venusBrick.blockID);
		world.setBlock(i + 5, j + 1, k + 33, Blocks.venusBrick.blockID);
		world.setBlock(i + 5, j + 1, k + 34, Blocks.venusBrick.blockID);
		world.setBlock(i + 5, j + 2, k + 0, Blocks.venusBrick.blockID);
		world.setBlock(i + 5, j + 2, k + 1, Blocks.venusBrick.blockID);
		world.setBlock(i + 5, j + 2, k + 2, Blocks.venusBrick.blockID);
		world.setBlock(i + 5, j + 2, k + 3, Blocks.venusBrick.blockID);
		world.setBlock(i + 5, j + 2, k + 4, Blocks.venusBrick.blockID);
		world.setBlock(i + 5, j + 2, k + 5, Blocks.venusBrick.blockID);
		world.setBlock(i + 5, j + 2, k + 6, Blocks.venusBrick.blockID);
		world.setBlock(i + 5, j + 2, k + 7, Blocks.venusBrick.blockID);
		world.setBlock(i + 5, j + 2, k + 8, Blocks.venusBrick.blockID);
		world.setBlock(i + 5, j + 2, k + 9, Blocks.venusBrick.blockID);
		world.setBlock(i + 5, j + 2, k + 10, Blocks.venusBrick.blockID);
		world.setBlock(i + 5, j + 2, k + 11, Blocks.venusBrick.blockID);
		world.setBlock(i + 5, j + 2, k + 12, Blocks.venusBrick.blockID);
		world.setBlock(i + 5, j + 2, k + 13, Blocks.venusBrick.blockID);
		world.setBlock(i + 5, j + 2, k + 14, Blocks.venusBrick.blockID);
		world.setBlock(i + 5, j + 2, k + 15, Blocks.venusBrick.blockID);
		world.setBlock(i + 5, j + 2, k + 16, Blocks.venusBrick.blockID);
		world.setBlock(i + 5, j + 2, k + 17, Blocks.venusBrick.blockID);
		world.setBlock(i + 5, j + 2, k + 18, Blocks.venusBrick.blockID);
		world.setBlock(i + 5, j + 2, k + 19, Blocks.venusBrick.blockID);
		world.setBlock(i + 5, j + 2, k + 20, Blocks.venusBrick.blockID);
		world.setBlock(i + 5, j + 2, k + 21, Blocks.venusBrick.blockID);
		world.setBlock(i + 5, j + 2, k + 22, Blocks.venusBrick.blockID);
		world.setBlock(i + 5, j + 2, k + 23, Blocks.venusBrick.blockID);
		world.setBlock(i + 5, j + 2, k + 24, Blocks.venusBrick.blockID);
		world.setBlock(i + 5, j + 2, k + 25, Blocks.venusBrick.blockID);
		world.setBlock(i + 5, j + 2, k + 26, Blocks.venusBrick.blockID);
		world.setBlock(i + 5, j + 2, k + 27, Blocks.venusBrick.blockID);
		world.setBlock(i + 5, j + 2, k + 28, Blocks.venusBrick.blockID);
		world.setBlock(i + 5, j + 2, k + 29, Blocks.venusBrick.blockID);
		world.setBlock(i + 5, j + 2, k + 30, Blocks.venusBrick.blockID);
		world.setBlock(i + 5, j + 2, k + 31, Blocks.venusBrick.blockID);
		world.setBlock(i + 5, j + 2, k + 32, Blocks.venusBrick.blockID);
		world.setBlock(i + 5, j + 2, k + 33, Blocks.venusBrick.blockID);
		world.setBlock(i + 5, j + 2, k + 34, Blocks.venusBrick.blockID);
		world.setBlock(i + 5, j + 3, k + 0, Blocks.venusBrick.blockID);
		world.setBlock(i + 5, j + 3, k + 1, Blocks.venusBrick.blockID);
		world.setBlock(i + 5, j + 3, k + 2, Blocks.venusBrick.blockID);
		world.setBlock(i + 5, j + 3, k + 3, Blocks.venusBrick.blockID);
		world.setBlock(i + 5, j + 3, k + 4, Blocks.venusBrick.blockID);
		world.setBlock(i + 5, j + 3, k + 5, Blocks.venusBrick.blockID);
		world.setBlock(i + 5, j + 3, k + 6, Blocks.venusBrick.blockID);
		world.setBlock(i + 5, j + 3, k + 7, Blocks.venusBrick.blockID);
		world.setBlock(i + 5, j + 3, k + 8, Blocks.venusBrick.blockID);
		world.setBlock(i + 5, j + 3, k + 9, Blocks.venusBrick.blockID);
		world.setBlock(i + 5, j + 3, k + 10, Blocks.venusBrick.blockID);
		world.setBlock(i + 5, j + 3, k + 11, Blocks.venusBrick.blockID);
		world.setBlock(i + 5, j + 3, k + 12, Blocks.venusBrick.blockID);
		world.setBlock(i + 5, j + 3, k + 13, Blocks.venusBrick.blockID);
		world.setBlock(i + 5, j + 3, k + 14, Blocks.venusBrick.blockID);
		world.setBlock(i + 5, j + 3, k + 15, Blocks.venusBrick.blockID);
		world.setBlock(i + 5, j + 3, k + 16, Blocks.venusBrick.blockID);
		world.setBlock(i + 5, j + 3, k + 17, Blocks.venusBrick.blockID);
		world.setBlock(i + 5, j + 3, k + 18, Blocks.venusBrick.blockID);
		world.setBlock(i + 5, j + 3, k + 19, Blocks.venusBrick.blockID);
		world.setBlock(i + 5, j + 3, k + 20, Blocks.venusBrick.blockID);
		world.setBlock(i + 5, j + 3, k + 21, Blocks.venusBrick.blockID);
		world.setBlock(i + 5, j + 3, k + 27, Blocks.venusBrick.blockID);
		world.setBlock(i + 5, j + 3, k + 28, Blocks.venusBrick.blockID);
		world.setBlock(i + 5, j + 3, k + 29, Blocks.venusBrick.blockID);
		world.setBlock(i + 5, j + 3, k + 30, Blocks.venusBrick.blockID);
		world.setBlock(i + 5, j + 3, k + 31, Blocks.venusBrick.blockID);
		world.setBlock(i + 5, j + 3, k + 32, Blocks.venusBrick.blockID);
		world.setBlock(i + 5, j + 3, k + 33, Blocks.venusBrick.blockID);
		world.setBlock(i + 5, j + 3, k + 34, Blocks.venusBrick.blockID);
		world.setBlock(i + 5, j + 4, k + 0, Blocks.venusBrick.blockID);
		world.setBlock(i + 5, j + 4, k + 1, Blocks.venusBrick.blockID);
		world.setBlock(i + 5, j + 4, k + 2, Blocks.venusBrick.blockID);
		world.setBlock(i + 5, j + 4, k + 3, Blocks.venusBrick.blockID);
		world.setBlock(i + 5, j + 4, k + 4, Blocks.venusBrick.blockID);
		world.setBlock(i + 5, j + 4, k + 5, Blocks.venusBrick.blockID);
		world.setBlock(i + 5, j + 4, k + 6, Blocks.venusBrick.blockID);
		world.setBlock(i + 5, j + 4, k + 7, Blocks.venusBrick.blockID);
		world.setBlock(i + 5, j + 4, k + 8, Blocks.venusBrick.blockID);
		world.setBlock(i + 5, j + 4, k + 9, Blocks.venusBrick.blockID);
		world.setBlock(i + 5, j + 4, k + 10, Blocks.venusBrick.blockID);
		world.setBlock(i + 5, j + 4, k + 11, Blocks.venusBrick.blockID);
		world.setBlock(i + 5, j + 4, k + 16, Blocks.venusBrick.blockID);
		world.setBlock(i + 5, j + 4, k + 17, Blocks.venusBrick.blockID);
		world.setBlock(i + 5, j + 4, k + 29, Blocks.venusBrick.blockID);
		world.setBlock(i + 5, j + 4, k + 30, Blocks.venusBrick.blockID);
		world.setBlock(i + 5, j + 4, k + 31, Blocks.venusBrick.blockID);
		world.setBlock(i + 5, j + 4, k + 32, Blocks.venusBrick.blockID);
		world.setBlock(i + 5, j + 4, k + 33, Blocks.venusBrick.blockID);
		world.setBlock(i + 5, j + 4, k + 34, Blocks.venusBrick.blockID);
		world.setBlock(i + 5, j + 8, k + 0, Blocks.venusBrick.blockID);
		world.setBlock(i + 5, j + 8, k + 1, Blocks.venusBrick.blockID);
		world.setBlock(i + 5, j + 8, k + 2, Blocks.venusBrick.blockID);
		world.setBlock(i + 5, j + 8, k + 3, Blocks.venusBrick.blockID);
		world.setBlock(i + 5, j + 8, k + 4, Blocks.venusBrick.blockID);
		world.setBlock(i + 5, j + 8, k + 5, Blocks.venusBrick.blockID);
		world.setBlock(i + 5, j + 8, k + 6, Blocks.venusBrick.blockID);
		world.setBlock(i + 5, j + 8, k + 7, Blocks.venusBrick.blockID);
		world.setBlock(i + 5, j + 8, k + 8, Blocks.venusBrick.blockID);
		world.setBlock(i + 5, j + 8, k + 32, Blocks.venusBrick.blockID);
		world.setBlock(i + 5, j + 8, k + 33, Blocks.venusBrick.blockID);
		world.setBlock(i + 5, j + 8, k + 34, Blocks.venusBrick.blockID);
		world.setBlock(i + 5, j + 9, k + 0, Blocks.venusBrick.blockID);
		world.setBlock(i + 5, j + 9, k + 1, Blocks.venusBrick.blockID);
		world.setBlock(i + 5, j + 9, k + 2, Blocks.venusBrick.blockID);
		world.setBlock(i + 5, j + 9, k + 3, Blocks.venusBrick.blockID);
		world.setBlock(i + 5, j + 9, k + 4, Blocks.venusBrick.blockID);
		world.setBlock(i + 5, j + 9, k + 5, Blocks.venusBrick.blockID);
		world.setBlock(i + 5, j + 9, k + 6, Blocks.venusBrick.blockID);
		world.setBlock(i + 5, j + 9, k + 7, Blocks.venusBrick.blockID);
		world.setBlock(i + 5, j + 9, k + 8, Blocks.venusBrick.blockID);
		world.setBlock(i + 5, j + 9, k + 32, Blocks.venusBrick.blockID);
		world.setBlock(i + 5, j + 9, k + 33, Blocks.venusBrick.blockID);
		world.setBlock(i + 5, j + 9, k + 34, Blocks.venusBrick.blockID);
		world.setBlock(i + 5, j + 10, k + 0, Blocks.venusBrick.blockID);
		world.setBlock(i + 5, j + 10, k + 1, Blocks.venusBrick.blockID);
		world.setBlock(i + 5, j + 10, k + 2, Blocks.venusBrick.blockID);
		world.setBlock(i + 5, j + 10, k + 3, Blocks.venusBrick.blockID);
		world.setBlock(i + 5, j + 10, k + 4, Blocks.venusBrick.blockID);
		world.setBlock(i + 5, j + 10, k + 5, Blocks.venusBrick.blockID);
		world.setBlock(i + 5, j + 10, k + 6, Blocks.venusBrick.blockID);
		world.setBlock(i + 5, j + 10, k + 7, Blocks.venusBrick.blockID);
		world.setBlock(i + 5, j + 10, k + 8, Blocks.venusBrick.blockID);
		world.setBlock(i + 5, j + 10, k + 31, Blocks.venusBrick.blockID);
		world.setBlock(i + 5, j + 10, k + 32, Blocks.venusBrick.blockID);
		world.setBlock(i + 5, j + 10, k + 33, Blocks.venusBrick.blockID);
		world.setBlock(i + 5, j + 10, k + 34, Blocks.venusBrick.blockID);
		world.setBlock(i + 5, j + 11, k + 0, Blocks.venusBrick.blockID);
		world.setBlock(i + 5, j + 11, k + 1, Blocks.venusBrick.blockID);
		world.setBlock(i + 5, j + 11, k + 2, Blocks.venusBrick.blockID);
		world.setBlock(i + 5, j + 11, k + 3, Blocks.venusBrick.blockID);
		world.setBlock(i + 5, j + 11, k + 4, Blocks.venusBrick.blockID);
		world.setBlock(i + 5, j + 11, k + 5, Blocks.venusBrick.blockID);
		world.setBlock(i + 5, j + 11, k + 6, Blocks.venusBrick.blockID);
		world.setBlock(i + 5, j + 11, k + 7, Blocks.venusBrick.blockID);
		world.setBlock(i + 5, j + 11, k + 30, Blocks.venusBrick.blockID);
		world.setBlock(i + 5, j + 11, k + 31, Blocks.venusBrick.blockID);
		world.setBlock(i + 5, j + 11, k + 32, Blocks.venusBrick.blockID);
		world.setBlock(i + 5, j + 11, k + 33, Blocks.venusBrick.blockID);
		world.setBlock(i + 5, j + 11, k + 34, Blocks.venusBrick.blockID);
		world.setBlock(i + 6, j + 0, k + 0, Blocks.venusBrick.blockID);
		world.setBlock(i + 6, j + 0, k + 1, Blocks.venusBrick.blockID);
		world.setBlock(i + 6, j + 0, k + 2, Blocks.venusBrick.blockID);
		world.setBlock(i + 6, j + 0, k + 3, Blocks.venusBrick.blockID);
		world.setBlock(i + 6, j + 0, k + 4, Blocks.venusBrick.blockID);
		world.setBlock(i + 6, j + 0, k + 5, Blocks.venusBrick.blockID);
		world.setBlock(i + 6, j + 0, k + 6, Blocks.venusBrick.blockID);
		world.setBlock(i + 6, j + 0, k + 7, Blocks.venusBrick.blockID);
		world.setBlock(i + 6, j + 0, k + 8, Blocks.venusBrick.blockID);
		world.setBlock(i + 6, j + 0, k + 9, Blocks.venusBrick.blockID);
		world.setBlock(i + 6, j + 0, k + 10, Blocks.venusBrick.blockID);
		world.setBlock(i + 6, j + 0, k + 11, Blocks.venusBrick.blockID);
		world.setBlock(i + 6, j + 0, k + 12, Blocks.venusBrick.blockID);
		world.setBlock(i + 6, j + 0, k + 13, Blocks.venusBrick.blockID);
		world.setBlock(i + 6, j + 0, k + 14, Blocks.venusBrick.blockID);
		world.setBlock(i + 6, j + 0, k + 15, Blocks.venusBrick.blockID);
		world.setBlock(i + 6, j + 0, k + 16, Blocks.venusBrick.blockID);
		world.setBlock(i + 6, j + 0, k + 17, Blocks.venusBrick.blockID);
		world.setBlock(i + 6, j + 0, k + 18, Blocks.venusBrick.blockID);
		world.setBlock(i + 6, j + 0, k + 19, Blocks.venusBrick.blockID);
		world.setBlock(i + 6, j + 0, k + 20, Blocks.venusBrick.blockID);
		world.setBlock(i + 6, j + 0, k + 21, Blocks.venusBrick.blockID);
		world.setBlock(i + 6, j + 0, k + 22, Blocks.venusBrick.blockID);
		world.setBlock(i + 6, j + 0, k + 23, Blocks.venusBrick.blockID);
		world.setBlock(i + 6, j + 0, k + 24, Blocks.venusBrick.blockID);
		world.setBlock(i + 6, j + 0, k + 25, Blocks.venusBrick.blockID);
		world.setBlock(i + 6, j + 0, k + 26, Blocks.venusBrick.blockID);
		world.setBlock(i + 6, j + 0, k + 27, Blocks.venusBrick.blockID);
		world.setBlock(i + 6, j + 0, k + 28, Blocks.venusBrick.blockID);
		world.setBlock(i + 6, j + 0, k + 29, Blocks.venusBrick.blockID);
		world.setBlock(i + 6, j + 0, k + 30, Blocks.venusBrick.blockID);
		world.setBlock(i + 6, j + 0, k + 31, Blocks.venusBrick.blockID);
		world.setBlock(i + 6, j + 0, k + 32, Blocks.venusBrick.blockID);
		world.setBlock(i + 6, j + 0, k + 33, Blocks.venusBrick.blockID);
		world.setBlock(i + 6, j + 0, k + 34, Blocks.venusBrick.blockID);
		world.setBlock(i + 6, j + 1, k + 0, Blocks.venusBrick.blockID);
		world.setBlock(i + 6, j + 1, k + 1, Blocks.venusBrick.blockID);
		world.setBlock(i + 6, j + 1, k + 2, Blocks.venusBrick.blockID);
